2023-09-17 20:46:46,649:WARNING:
'cuml' is a soft dependency and not included in the pycaret installation. Please run: `pip install cuml` to install.
2023-09-17 20:46:46,649:WARNING:
'cuml' is a soft dependency and not included in the pycaret installation. Please run: `pip install cuml` to install.
2023-09-17 20:46:46,649:WARNING:
'cuml' is a soft dependency and not included in the pycaret installation. Please run: `pip install cuml` to install.
2023-09-17 20:46:46,649:WARNING:
'cuml' is a soft dependency and not included in the pycaret installation. Please run: `pip install cuml` to install.
2023-09-17 20:46:48,683:INFO:PyCaret ClassificationExperiment
2023-09-17 20:46:48,683:INFO:Logging name: clf-default-name
2023-09-17 20:46:48,683:INFO:ML Usecase: MLUsecase.CLASSIFICATION
2023-09-17 20:46:48,683:INFO:version 3.1.0
2023-09-17 20:46:48,683:INFO:Initializing setup()
2023-09-17 20:46:48,683:INFO:self.USI: dc5c
2023-09-17 20:46:48,683:INFO:self._variable_keys: {'_available_plots', 'memory', 'y', 'X_train', 'seed', 'USI', 'X_test', 'data', 'log_plots_param', 'pipeline', 'exp_id', 'X', 'fix_imbalance', 'n_jobs_param', 'target_param', '_ml_usecase', 'fold_groups_param', 'is_multiclass', 'fold_generator', 'y_test', 'gpu_param', 'exp_name_log', 'fold_shuffle_param', 'html_param', 'idx', 'gpu_n_jobs_param', 'y_train', 'logging_param'}
2023-09-17 20:46:48,683:INFO:Checking environment
2023-09-17 20:46:48,683:INFO:python_version: 3.10.12
2023-09-17 20:46:48,684:INFO:python_build: ('main', 'Jun 11 2023 05:26:28')
2023-09-17 20:46:48,684:INFO:machine: x86_64
2023-09-17 20:46:48,684:INFO:platform: Linux-5.15.109+-x86_64-with-glibc2.35
2023-09-17 20:46:48,684:INFO:Memory: svmem(total=13613314048, available=12562784256, percent=7.7, used=709943296, free=896851968, active=1184632832, inactive=10945081344, buffers=111022080, cached=11895496704, shared=7168000, slab=511356928)
2023-09-17 20:46:48,687:INFO:Physical Core: 1
2023-09-17 20:46:48,687:INFO:Logical Core: 2
2023-09-17 20:46:48,687:INFO:Checking libraries
2023-09-17 20:46:48,687:INFO:System:
2023-09-17 20:46:48,687:INFO:    python: 3.10.12 (main, Jun 11 2023, 05:26:28) [GCC 11.4.0]
2023-09-17 20:46:48,687:INFO:executable: /usr/bin/python3
2023-09-17 20:46:48,687:INFO:   machine: Linux-5.15.109+-x86_64-with-glibc2.35
2023-09-17 20:46:48,687:INFO:PyCaret required dependencies:
2023-09-17 20:46:50,310:INFO:                 pip: 23.1.2
2023-09-17 20:46:50,311:INFO:          setuptools: 67.7.2
2023-09-17 20:46:50,311:INFO:             pycaret: 3.1.0
2023-09-17 20:46:50,311:INFO:             IPython: 7.34.0
2023-09-17 20:46:50,311:INFO:          ipywidgets: 7.7.1
2023-09-17 20:46:50,311:INFO:                tqdm: 4.66.1
2023-09-17 20:46:50,311:INFO:               numpy: 1.23.5
2023-09-17 20:46:50,311:INFO:              pandas: 1.5.3
2023-09-17 20:46:50,311:INFO:              jinja2: 3.1.2
2023-09-17 20:46:50,311:INFO:               scipy: 1.10.1
2023-09-17 20:46:50,311:INFO:              joblib: 1.3.2
2023-09-17 20:46:50,311:INFO:             sklearn: 1.2.2
2023-09-17 20:46:50,311:INFO:                pyod: 1.1.0
2023-09-17 20:46:50,311:INFO:            imblearn: 0.10.1
2023-09-17 20:46:50,311:INFO:   category_encoders: 2.6.2
2023-09-17 20:46:50,311:INFO:            lightgbm: 4.0.0
2023-09-17 20:46:50,311:INFO:               numba: 0.56.4
2023-09-17 20:46:50,311:INFO:            requests: 2.31.0
2023-09-17 20:46:50,311:INFO:          matplotlib: 3.7.1
2023-09-17 20:46:50,311:INFO:          scikitplot: 0.3.7
2023-09-17 20:46:50,311:INFO:         yellowbrick: 1.5
2023-09-17 20:46:50,311:INFO:              plotly: 5.15.0
2023-09-17 20:46:50,312:INFO:    plotly-resampler: Not installed
2023-09-17 20:46:50,312:INFO:             kaleido: 0.2.1
2023-09-17 20:46:50,312:INFO:           schemdraw: 0.15
2023-09-17 20:46:50,312:INFO:         statsmodels: 0.14.0
2023-09-17 20:46:50,312:INFO:              sktime: 0.21.1
2023-09-17 20:46:50,312:INFO:               tbats: 1.1.3
2023-09-17 20:46:50,312:INFO:            pmdarima: 2.0.3
2023-09-17 20:46:50,312:INFO:              psutil: 5.9.5
2023-09-17 20:46:50,312:INFO:          markupsafe: 2.1.3
2023-09-17 20:46:50,312:INFO:             pickle5: Not installed
2023-09-17 20:46:50,312:INFO:         cloudpickle: 2.2.1
2023-09-17 20:46:50,312:INFO:         deprecation: 2.1.0
2023-09-17 20:46:50,312:INFO:              xxhash: 3.3.0
2023-09-17 20:46:50,312:INFO:           wurlitzer: 3.0.3
2023-09-17 20:46:50,312:INFO:PyCaret optional dependencies:
2023-09-17 20:46:50,684:WARNING:/usr/local/lib/python3.10/dist-packages/trio/_core/_multierror.py:412: RuntimeWarning: IPython detected, but you already have a custom exception handler installed. I'll skip installing Trio's custom handler, but this means exception groups will not show full tracebacks.
  warnings.warn(

2023-09-17 20:46:53,767:INFO:                shap: 0.42.1
2023-09-17 20:46:53,784:INFO:           interpret: 0.4.4
2023-09-17 20:46:53,784:INFO:                umap: 0.5.4
2023-09-17 20:46:53,784:INFO:     ydata_profiling: 4.5.1
2023-09-17 20:46:53,784:INFO:  explainerdashboard: 0.4.3
2023-09-17 20:46:53,784:INFO:             autoviz: Not installed
2023-09-17 20:46:53,784:INFO:           fairlearn: 0.7.0
2023-09-17 20:46:53,784:INFO:          deepchecks: Not installed
2023-09-17 20:46:53,784:INFO:             xgboost: 1.7.6
2023-09-17 20:46:53,784:INFO:            catboost: 1.2.1.1
2023-09-17 20:46:53,785:INFO:              kmodes: 0.12.2
2023-09-17 20:46:53,785:INFO:             mlxtend: 0.22.0
2023-09-17 20:46:53,785:INFO:       statsforecast: 1.5.0
2023-09-17 20:46:53,785:INFO:        tune_sklearn: 0.4.6
2023-09-17 20:46:53,785:INFO:                 ray: 2.7.0
2023-09-17 20:46:53,785:INFO:            hyperopt: 0.2.7
2023-09-17 20:46:53,785:INFO:              optuna: 3.3.0
2023-09-17 20:46:53,785:INFO:               skopt: 0.9.0
2023-09-17 20:46:53,785:INFO:              mlflow: 1.30.1
2023-09-17 20:46:53,785:INFO:              gradio: 3.44.3
2023-09-17 20:46:53,785:INFO:             fastapi: 0.103.1
2023-09-17 20:46:53,785:INFO:             uvicorn: 0.23.2
2023-09-17 20:46:53,785:INFO:              m2cgen: 0.10.0
2023-09-17 20:46:53,785:INFO:           evidently: 0.2.8
2023-09-17 20:46:53,785:INFO:               fugue: 0.8.6
2023-09-17 20:46:53,785:INFO:           streamlit: Not installed
2023-09-17 20:46:53,785:INFO:             prophet: 1.1.4
2023-09-17 20:46:53,785:INFO:None
2023-09-17 20:46:53,785:INFO:Set up GPU usage.
2023-09-17 20:46:53,785:WARNING:
'cuml' is a soft dependency and not included in the pycaret installation. Please run: `pip install cuml` to install.
2023-09-17 20:46:53,785:WARNING:cuML is outdated or not found. Required version is >=23.08.
                Please visit https://rapids.ai/install for installation instructions.
2023-09-17 20:46:53,785:INFO:Set up data.
2023-09-17 20:46:53,877:INFO:Set up folding strategy.
2023-09-17 20:46:53,877:INFO:Set up train/test split.
2023-09-17 20:46:53,917:INFO:Set up index.
2023-09-17 20:46:53,924:INFO:Assigning column types.
2023-09-17 20:46:53,944:INFO:Engine successfully changes for model 'lr' to 'sklearn'.
2023-09-17 20:46:53,945:WARNING:
'cuml' is a soft dependency and not included in the pycaret installation. Please run: `pip install cuml` to install.
2023-09-17 20:46:54,106:INFO:Engine for model 'knn' has not been set explicitly, hence returning None.
2023-09-17 20:46:54,106:WARNING:
'cuml' is a soft dependency and not included in the pycaret installation. Please run: `pip install cuml` to install.
2023-09-17 20:46:54,110:WARNING:
'cuml' is a soft dependency and not included in the pycaret installation. Please run: `pip install cuml` to install.
2023-09-17 20:46:54,111:INFO:Engine for model 'rbfsvm' has not been set explicitly, hence returning None.
2023-09-17 20:46:54,111:WARNING:
'cuml' is a soft dependency and not included in the pycaret installation. Please run: `pip install cuml` to install.
2023-09-17 20:46:54,218:WARNING:
'cuml' is a soft dependency and not included in the pycaret installation. Please run: `pip install cuml` to install.
2023-09-17 20:46:54,232:WARNING:
'cuml' is a soft dependency and not included in the pycaret installation. Please run: `pip install cuml` to install.
2023-09-17 20:46:54,248:INFO:Soft dependency imported: xgboost: 1.7.6
2023-09-17 20:46:54,685:INFO:Soft dependency imported: catboost: 1.2.1.1
2023-09-17 20:46:54,796:WARNING:
'cuml' is a soft dependency and not included in the pycaret installation. Please run: `pip install cuml` to install.
2023-09-17 20:46:55,005:INFO:Engine for model 'knn' has not been set explicitly, hence returning None.
2023-09-17 20:46:55,005:WARNING:
'cuml' is a soft dependency and not included in the pycaret installation. Please run: `pip install cuml` to install.
2023-09-17 20:46:55,005:WARNING:
'cuml' is a soft dependency and not included in the pycaret installation. Please run: `pip install cuml` to install.
2023-09-17 20:46:55,007:INFO:Engine for model 'rbfsvm' has not been set explicitly, hence returning None.
2023-09-17 20:46:55,007:WARNING:
'cuml' is a soft dependency and not included in the pycaret installation. Please run: `pip install cuml` to install.
2023-09-17 20:46:55,056:WARNING:
'cuml' is a soft dependency and not included in the pycaret installation. Please run: `pip install cuml` to install.
2023-09-17 20:46:55,077:WARNING:
'cuml' is a soft dependency and not included in the pycaret installation. Please run: `pip install cuml` to install.
2023-09-17 20:46:55,080:INFO:Soft dependency imported: xgboost: 1.7.6
2023-09-17 20:46:55,122:INFO:Soft dependency imported: catboost: 1.2.1.1
2023-09-17 20:46:55,127:INFO:Engine successfully changes for model 'knn' to 'sklearn'.
2023-09-17 20:46:55,128:WARNING:
'cuml' is a soft dependency and not included in the pycaret installation. Please run: `pip install cuml` to install.
2023-09-17 20:46:55,289:WARNING:
'cuml' is a soft dependency and not included in the pycaret installation. Please run: `pip install cuml` to install.
2023-09-17 20:46:55,289:WARNING:
'cuml' is a soft dependency and not included in the pycaret installation. Please run: `pip install cuml` to install.
2023-09-17 20:46:55,291:INFO:Engine for model 'rbfsvm' has not been set explicitly, hence returning None.
2023-09-17 20:46:55,291:WARNING:
'cuml' is a soft dependency and not included in the pycaret installation. Please run: `pip install cuml` to install.
2023-09-17 20:46:55,372:WARNING:
'cuml' is a soft dependency and not included in the pycaret installation. Please run: `pip install cuml` to install.
2023-09-17 20:46:55,381:WARNING:
'cuml' is a soft dependency and not included in the pycaret installation. Please run: `pip install cuml` to install.
2023-09-17 20:46:55,389:INFO:Soft dependency imported: xgboost: 1.7.6
2023-09-17 20:46:55,415:INFO:Soft dependency imported: catboost: 1.2.1.1
2023-09-17 20:46:55,416:WARNING:
'cuml' is a soft dependency and not included in the pycaret installation. Please run: `pip install cuml` to install.
2023-09-17 20:46:55,555:WARNING:
'cuml' is a soft dependency and not included in the pycaret installation. Please run: `pip install cuml` to install.
2023-09-17 20:46:55,555:WARNING:
'cuml' is a soft dependency and not included in the pycaret installation. Please run: `pip install cuml` to install.
2023-09-17 20:46:55,556:INFO:Engine for model 'rbfsvm' has not been set explicitly, hence returning None.
2023-09-17 20:46:55,557:WARNING:
'cuml' is a soft dependency and not included in the pycaret installation. Please run: `pip install cuml` to install.
2023-09-17 20:46:55,676:WARNING:
'cuml' is a soft dependency and not included in the pycaret installation. Please run: `pip install cuml` to install.
2023-09-17 20:46:55,697:WARNING:
'cuml' is a soft dependency and not included in the pycaret installation. Please run: `pip install cuml` to install.
2023-09-17 20:46:55,699:INFO:Soft dependency imported: xgboost: 1.7.6
2023-09-17 20:46:55,762:INFO:Soft dependency imported: catboost: 1.2.1.1
2023-09-17 20:46:55,763:INFO:Engine successfully changes for model 'rbfsvm' to 'sklearn'.
2023-09-17 20:46:55,764:WARNING:
'cuml' is a soft dependency and not included in the pycaret installation. Please run: `pip install cuml` to install.
2023-09-17 20:46:55,914:WARNING:
'cuml' is a soft dependency and not included in the pycaret installation. Please run: `pip install cuml` to install.
2023-09-17 20:46:55,915:WARNING:
'cuml' is a soft dependency and not included in the pycaret installation. Please run: `pip install cuml` to install.
2023-09-17 20:46:55,916:WARNING:
'cuml' is a soft dependency and not included in the pycaret installation. Please run: `pip install cuml` to install.
2023-09-17 20:46:56,000:WARNING:
'cuml' is a soft dependency and not included in the pycaret installation. Please run: `pip install cuml` to install.
2023-09-17 20:46:56,021:WARNING:
'cuml' is a soft dependency and not included in the pycaret installation. Please run: `pip install cuml` to install.
2023-09-17 20:46:56,023:INFO:Soft dependency imported: xgboost: 1.7.6
2023-09-17 20:46:56,047:INFO:Soft dependency imported: catboost: 1.2.1.1
2023-09-17 20:46:56,052:WARNING:
'cuml' is a soft dependency and not included in the pycaret installation. Please run: `pip install cuml` to install.
2023-09-17 20:46:56,227:WARNING:
'cuml' is a soft dependency and not included in the pycaret installation. Please run: `pip install cuml` to install.
2023-09-17 20:46:56,227:WARNING:
'cuml' is a soft dependency and not included in the pycaret installation. Please run: `pip install cuml` to install.
2023-09-17 20:46:56,228:WARNING:
'cuml' is a soft dependency and not included in the pycaret installation. Please run: `pip install cuml` to install.
2023-09-17 20:46:56,321:WARNING:
'cuml' is a soft dependency and not included in the pycaret installation. Please run: `pip install cuml` to install.
2023-09-17 20:46:56,335:WARNING:
'cuml' is a soft dependency and not included in the pycaret installation. Please run: `pip install cuml` to install.
2023-09-17 20:46:56,337:INFO:Soft dependency imported: xgboost: 1.7.6
2023-09-17 20:46:56,373:INFO:Soft dependency imported: catboost: 1.2.1.1
2023-09-17 20:46:56,384:INFO:Preparing preprocessing pipeline...
2023-09-17 20:46:56,393:INFO:Set up simple imputation.
2023-09-17 20:46:56,410:INFO:Set up encoding of categorical features.
2023-09-17 20:46:56,414:INFO:Set up column name cleaning.
2023-09-17 20:46:58,734:INFO:Finished creating preprocessing pipeline.
2023-09-17 20:46:58,782:INFO:Pipeline: Pipeline(memory=FastMemory(location=/tmp/joblib),
         steps=[('numerical_imputer',
                 TransformerWrapper(exclude=None,
                                    include=['Unnamed: 0',
                                             'Currently Hospitalized',
                                             'Currently in ICU',
                                             'Currently Intubated',
                                             'Ever Hospitalized', 'Ever in ICU',
                                             'Ever Intubated'],
                                    transformer=SimpleImputer(add_indicator=False,
                                                              copy=True,
                                                              fill_value=None,
                                                              keep_empty_features=False,
                                                              missing_valu...
                                    transformer=TargetEncoder(cols=['Neighbourhood '
                                                                    'Name',
                                                                    'FSA',
                                                                    'Episode '
                                                                    'Date'],
                                                              drop_invariant=False,
                                                              handle_missing='return_nan',
                                                              handle_unknown='value',
                                                              hierarchy=None,
                                                              min_samples_leaf=20,
                                                              return_df=True,
                                                              smoothing=10,
                                                              verbose=0))),
                ('clean_column_names',
                 TransformerWrapper(exclude=None, include=None,
                                    transformer=CleanColumnNames(match='[\\]\\[\\,\\{\\}\\"\\:]+')))],
         verbose=False)
2023-09-17 20:46:58,782:INFO:Creating final display dataframe.
2023-09-17 20:47:00,584:INFO:Setup _display_container:                     Description             Value
0                    Session id              2858
1                        Target    Classification
2                   Target type            Binary
3           Original data shape       (14275, 15)
4        Transformed data shape       (14275, 27)
5   Transformed train set shape        (9992, 27)
6    Transformed test set shape        (4283, 27)
7               Ignore features                 2
8              Numeric features                 7
9          Categorical features                 6
10                   Preprocess              True
11              Imputation type            simple
12           Numeric imputation              mean
13       Categorical imputation              mode
14     Maximum one-hot encoding                25
15              Encoding method              None
16               Fold Generator   StratifiedKFold
17                  Fold Number                10
18                     CPU Jobs                -1
19                      Use GPU              True
20               Log Experiment             False
21              Experiment Name  clf-default-name
22                          USI              dc5c
2023-09-17 20:47:00,639:WARNING:
'cuml' is a soft dependency and not included in the pycaret installation. Please run: `pip install cuml` to install.
2023-09-17 20:47:00,888:WARNING:
'cuml' is a soft dependency and not included in the pycaret installation. Please run: `pip install cuml` to install.
2023-09-17 20:47:00,889:WARNING:
'cuml' is a soft dependency and not included in the pycaret installation. Please run: `pip install cuml` to install.
2023-09-17 20:47:00,890:WARNING:
'cuml' is a soft dependency and not included in the pycaret installation. Please run: `pip install cuml` to install.
2023-09-17 20:47:01,002:WARNING:
'cuml' is a soft dependency and not included in the pycaret installation. Please run: `pip install cuml` to install.
2023-09-17 20:47:01,019:WARNING:
'cuml' is a soft dependency and not included in the pycaret installation. Please run: `pip install cuml` to install.
2023-09-17 20:47:01,030:INFO:Soft dependency imported: xgboost: 1.7.6
2023-09-17 20:47:01,066:INFO:Soft dependency imported: catboost: 1.2.1.1
2023-09-17 20:47:01,068:WARNING:
'cuml' is a soft dependency and not included in the pycaret installation. Please run: `pip install cuml` to install.
2023-09-17 20:47:01,288:WARNING:
'cuml' is a soft dependency and not included in the pycaret installation. Please run: `pip install cuml` to install.
2023-09-17 20:47:01,288:WARNING:
'cuml' is a soft dependency and not included in the pycaret installation. Please run: `pip install cuml` to install.
2023-09-17 20:47:01,304:WARNING:
'cuml' is a soft dependency and not included in the pycaret installation. Please run: `pip install cuml` to install.
2023-09-17 20:47:01,354:WARNING:
'cuml' is a soft dependency and not included in the pycaret installation. Please run: `pip install cuml` to install.
2023-09-17 20:47:01,363:WARNING:
'cuml' is a soft dependency and not included in the pycaret installation. Please run: `pip install cuml` to install.
2023-09-17 20:47:01,365:INFO:Soft dependency imported: xgboost: 1.7.6
2023-09-17 20:47:01,384:INFO:Soft dependency imported: catboost: 1.2.1.1
2023-09-17 20:47:01,386:INFO:setup() successfully completed in 12.7s...............
2023-09-17 20:47:01,414:INFO:Initializing compare_models()
2023-09-17 20:47:01,419:INFO:compare_models(self=<pycaret.classification.oop.ClassificationExperiment object at 0x7f76ad0a8370>, include=None, fold=None, round=4, cross_validation=True, sort=Accuracy, n_select=1, budget_time=None, turbo=True, errors=ignore, fit_kwargs=None, groups=None, experiment_custom_tags=None, probability_threshold=None, verbose=True, parallel=None, caller_params={'self': <pycaret.classification.oop.ClassificationExperiment object at 0x7f76ad0a8370>, 'include': None, 'exclude': None, 'fold': None, 'round': 4, 'cross_validation': True, 'sort': 'Accuracy', 'n_select': 1, 'budget_time': None, 'turbo': True, 'errors': 'ignore', 'fit_kwargs': None, 'groups': None, 'experiment_custom_tags': None, 'probability_threshold': None, 'engine': None, 'verbose': True, 'parallel': None, '__class__': <class 'pycaret.classification.oop.ClassificationExperiment'>}, exclude=None)
2023-09-17 20:47:01,419:INFO:Checking exceptions
2023-09-17 20:47:01,444:INFO:Preparing display monitor
2023-09-17 20:47:01,638:INFO:Initializing Logistic Regression
2023-09-17 20:47:01,638:INFO:Total runtime is 6.389617919921875e-06 minutes
2023-09-17 20:47:01,653:INFO:SubProcess create_model() called ==================================
2023-09-17 20:47:01,654:INFO:Initializing create_model()
2023-09-17 20:47:01,654:INFO:create_model(self=<pycaret.classification.oop.ClassificationExperiment object at 0x7f76ad0a8370>, estimator=lr, fold=StratifiedKFold(n_splits=10, random_state=None, shuffle=False), round=4, cross_validation=True, predict=True, fit_kwargs={}, groups=None, refit=False, probability_threshold=None, experiment_custom_tags=None, verbose=False, system=False, add_to_model_list=True, metrics=None, display=<pycaret.internal.display.display.CommonDisplay object at 0x7f76a9411e10>, model_only=True, return_train_score=False, kwargs={})
2023-09-17 20:47:01,654:INFO:Checking exceptions
2023-09-17 20:47:01,654:INFO:Importing libraries
2023-09-17 20:47:01,654:INFO:Copying training dataset
2023-09-17 20:47:01,693:INFO:Defining folds
2023-09-17 20:47:01,693:INFO:Declaring metric variables
2023-09-17 20:47:01,712:INFO:Importing untrained model
2023-09-17 20:47:01,739:INFO:Logistic Regression Imported successfully
2023-09-17 20:47:01,766:INFO:Starting cross validation
2023-09-17 20:47:01,770:INFO:Cross validating with StratifiedKFold(n_splits=10, random_state=None, shuffle=False), n_jobs=1
2023-09-17 20:47:16,778:INFO:Calculating mean and std
2023-09-17 20:47:16,780:INFO:Creating metrics dataframe
2023-09-17 20:47:16,808:INFO:Uploading results into container
2023-09-17 20:47:16,816:INFO:Uploading model into container now
2023-09-17 20:47:16,823:INFO:_master_model_container: 1
2023-09-17 20:47:16,823:INFO:_display_container: 2
2023-09-17 20:47:16,823:INFO:LogisticRegression(C=1.0, class_weight=None, dual=False, fit_intercept=True,
                   intercept_scaling=1, l1_ratio=None, max_iter=1000,
                   multi_class='auto', n_jobs=None, penalty='l2',
                   random_state=2858, solver='lbfgs', tol=0.0001, verbose=0,
                   warm_start=False)
2023-09-17 20:47:16,824:INFO:create_model() successfully completed......................................
2023-09-17 20:47:17,590:INFO:SubProcess create_model() end ==================================
2023-09-17 20:47:17,591:INFO:Creating metrics dataframe
2023-09-17 20:47:17,662:INFO:Initializing K Neighbors Classifier
2023-09-17 20:47:17,662:INFO:Total runtime is 0.26707306305567424 minutes
2023-09-17 20:47:17,681:INFO:SubProcess create_model() called ==================================
2023-09-17 20:47:17,682:INFO:Initializing create_model()
2023-09-17 20:47:17,682:INFO:create_model(self=<pycaret.classification.oop.ClassificationExperiment object at 0x7f76ad0a8370>, estimator=knn, fold=StratifiedKFold(n_splits=10, random_state=None, shuffle=False), round=4, cross_validation=True, predict=True, fit_kwargs={}, groups=None, refit=False, probability_threshold=None, experiment_custom_tags=None, verbose=False, system=False, add_to_model_list=True, metrics=None, display=<pycaret.internal.display.display.CommonDisplay object at 0x7f76a9411e10>, model_only=True, return_train_score=False, kwargs={})
2023-09-17 20:47:17,682:INFO:Checking exceptions
2023-09-17 20:47:17,682:INFO:Importing libraries
2023-09-17 20:47:17,682:INFO:Copying training dataset
2023-09-17 20:47:17,719:INFO:Defining folds
2023-09-17 20:47:17,719:INFO:Declaring metric variables
2023-09-17 20:47:17,754:INFO:Importing untrained model
2023-09-17 20:47:17,791:INFO:K Neighbors Classifier Imported successfully
2023-09-17 20:47:17,833:INFO:Starting cross validation
2023-09-17 20:47:17,849:INFO:Cross validating with StratifiedKFold(n_splits=10, random_state=None, shuffle=False), n_jobs=1
2023-09-17 20:47:29,886:INFO:Calculating mean and std
2023-09-17 20:47:29,887:INFO:Creating metrics dataframe
2023-09-17 20:47:29,896:INFO:Uploading results into container
2023-09-17 20:47:29,896:INFO:Uploading model into container now
2023-09-17 20:47:29,897:INFO:_master_model_container: 2
2023-09-17 20:47:29,897:INFO:_display_container: 2
2023-09-17 20:47:29,898:INFO:KNeighborsClassifier(algorithm='auto', leaf_size=30, metric='minkowski',
                     metric_params=None, n_jobs=-1, n_neighbors=5, p=2,
                     weights='uniform')
2023-09-17 20:47:29,898:INFO:create_model() successfully completed......................................
2023-09-17 20:47:30,063:INFO:SubProcess create_model() end ==================================
2023-09-17 20:47:30,063:INFO:Creating metrics dataframe
2023-09-17 20:47:30,080:INFO:Initializing Naive Bayes
2023-09-17 20:47:30,081:INFO:Total runtime is 0.4740573207537333 minutes
2023-09-17 20:47:30,088:INFO:SubProcess create_model() called ==================================
2023-09-17 20:47:30,089:INFO:Initializing create_model()
2023-09-17 20:47:30,089:INFO:create_model(self=<pycaret.classification.oop.ClassificationExperiment object at 0x7f76ad0a8370>, estimator=nb, fold=StratifiedKFold(n_splits=10, random_state=None, shuffle=False), round=4, cross_validation=True, predict=True, fit_kwargs={}, groups=None, refit=False, probability_threshold=None, experiment_custom_tags=None, verbose=False, system=False, add_to_model_list=True, metrics=None, display=<pycaret.internal.display.display.CommonDisplay object at 0x7f76a9411e10>, model_only=True, return_train_score=False, kwargs={})
2023-09-17 20:47:30,089:INFO:Checking exceptions
2023-09-17 20:47:30,089:INFO:Importing libraries
2023-09-17 20:47:30,089:INFO:Copying training dataset
2023-09-17 20:47:30,101:INFO:Defining folds
2023-09-17 20:47:30,101:INFO:Declaring metric variables
2023-09-17 20:47:30,110:INFO:Importing untrained model
2023-09-17 20:47:30,118:INFO:Naive Bayes Imported successfully
2023-09-17 20:47:30,135:INFO:Starting cross validation
2023-09-17 20:47:30,138:INFO:Cross validating with StratifiedKFold(n_splits=10, random_state=None, shuffle=False), n_jobs=1
2023-09-17 20:47:32,677:INFO:Calculating mean and std
2023-09-17 20:47:32,682:INFO:Creating metrics dataframe
2023-09-17 20:47:32,692:INFO:Uploading results into container
2023-09-17 20:47:32,693:INFO:Uploading model into container now
2023-09-17 20:47:32,694:INFO:_master_model_container: 3
2023-09-17 20:47:32,694:INFO:_display_container: 2
2023-09-17 20:47:32,694:INFO:GaussianNB(priors=None, var_smoothing=1e-09)
2023-09-17 20:47:32,694:INFO:create_model() successfully completed......................................
2023-09-17 20:47:32,900:INFO:SubProcess create_model() end ==================================
2023-09-17 20:47:32,900:INFO:Creating metrics dataframe
2023-09-17 20:47:32,918:INFO:Initializing Decision Tree Classifier
2023-09-17 20:47:32,919:INFO:Total runtime is 0.5213520924250284 minutes
2023-09-17 20:47:32,927:INFO:SubProcess create_model() called ==================================
2023-09-17 20:47:32,928:INFO:Initializing create_model()
2023-09-17 20:47:32,928:INFO:create_model(self=<pycaret.classification.oop.ClassificationExperiment object at 0x7f76ad0a8370>, estimator=dt, fold=StratifiedKFold(n_splits=10, random_state=None, shuffle=False), round=4, cross_validation=True, predict=True, fit_kwargs={}, groups=None, refit=False, probability_threshold=None, experiment_custom_tags=None, verbose=False, system=False, add_to_model_list=True, metrics=None, display=<pycaret.internal.display.display.CommonDisplay object at 0x7f76a9411e10>, model_only=True, return_train_score=False, kwargs={})
2023-09-17 20:47:32,928:INFO:Checking exceptions
2023-09-17 20:47:32,928:INFO:Importing libraries
2023-09-17 20:47:32,928:INFO:Copying training dataset
2023-09-17 20:47:32,946:INFO:Defining folds
2023-09-17 20:47:32,946:INFO:Declaring metric variables
2023-09-17 20:47:32,955:INFO:Importing untrained model
2023-09-17 20:47:32,962:INFO:Decision Tree Classifier Imported successfully
2023-09-17 20:47:32,981:INFO:Starting cross validation
2023-09-17 20:47:32,984:INFO:Cross validating with StratifiedKFold(n_splits=10, random_state=None, shuffle=False), n_jobs=1
2023-09-17 20:47:37,357:INFO:Calculating mean and std
2023-09-17 20:47:37,364:INFO:Creating metrics dataframe
2023-09-17 20:47:37,375:INFO:Uploading results into container
2023-09-17 20:47:37,376:INFO:Uploading model into container now
2023-09-17 20:47:37,376:INFO:_master_model_container: 4
2023-09-17 20:47:37,376:INFO:_display_container: 2
2023-09-17 20:47:37,377:INFO:DecisionTreeClassifier(ccp_alpha=0.0, class_weight=None, criterion='gini',
                       max_depth=None, max_features=None, max_leaf_nodes=None,
                       min_impurity_decrease=0.0, min_samples_leaf=1,
                       min_samples_split=2, min_weight_fraction_leaf=0.0,
                       random_state=2858, splitter='best')
2023-09-17 20:47:37,377:INFO:create_model() successfully completed......................................
2023-09-17 20:47:37,590:INFO:SubProcess create_model() end ==================================
2023-09-17 20:47:37,590:INFO:Creating metrics dataframe
2023-09-17 20:47:37,611:INFO:Initializing SVM - Linear Kernel
2023-09-17 20:47:37,612:INFO:Total runtime is 0.599568780263265 minutes
2023-09-17 20:47:37,622:INFO:SubProcess create_model() called ==================================
2023-09-17 20:47:37,622:INFO:Initializing create_model()
2023-09-17 20:47:37,622:INFO:create_model(self=<pycaret.classification.oop.ClassificationExperiment object at 0x7f76ad0a8370>, estimator=svm, fold=StratifiedKFold(n_splits=10, random_state=None, shuffle=False), round=4, cross_validation=True, predict=True, fit_kwargs={}, groups=None, refit=False, probability_threshold=None, experiment_custom_tags=None, verbose=False, system=False, add_to_model_list=True, metrics=None, display=<pycaret.internal.display.display.CommonDisplay object at 0x7f76a9411e10>, model_only=True, return_train_score=False, kwargs={})
2023-09-17 20:47:37,622:INFO:Checking exceptions
2023-09-17 20:47:37,622:INFO:Importing libraries
2023-09-17 20:47:37,622:INFO:Copying training dataset
2023-09-17 20:47:37,644:INFO:Defining folds
2023-09-17 20:47:37,644:INFO:Declaring metric variables
2023-09-17 20:47:37,654:INFO:Importing untrained model
2023-09-17 20:47:37,663:INFO:SVM - Linear Kernel Imported successfully
2023-09-17 20:47:37,680:INFO:Starting cross validation
2023-09-17 20:47:37,684:INFO:Cross validating with StratifiedKFold(n_splits=10, random_state=None, shuffle=False), n_jobs=1
2023-09-17 20:47:38,357:WARNING:/usr/local/lib/python3.10/dist-packages/pycaret/internal/metrics.py:190: FitFailedWarning: Metric 'make_scorer(roc_auc_score, needs_proba=True, error_score=0.0, average=weighted, multi_class=ovr)' failed and error score 0.0 has been returned instead. If this is a custom metric, this usually means that the error is in the metric code. Full exception below:
Traceback (most recent call last):
  File "/usr/local/lib/python3.10/dist-packages/sklearn/metrics/_scorer.py", line 76, in _cached_call
    return cache[method]
KeyError: 'predict_proba'

During handling of the above exception, another exception occurred:

Traceback (most recent call last):
  File "/usr/local/lib/python3.10/dist-packages/pycaret/internal/metrics.py", line 182, in _score
    return super()._score(
  File "/usr/local/lib/python3.10/dist-packages/sklearn/metrics/_scorer.py", line 316, in _score
    y_pred = method_caller(clf, "predict_proba", X)
  File "/usr/local/lib/python3.10/dist-packages/sklearn/metrics/_scorer.py", line 78, in _cached_call
    result = getattr(estimator, method)(*args, **kwargs)
  File "/usr/local/lib/python3.10/dist-packages/sklearn/utils/_available_if.py", line 32, in __get__
    if not self.check(obj):
  File "/usr/local/lib/python3.10/dist-packages/sklearn/linear_model/_stochastic_gradient.py", line 1235, in _check_proba
    raise AttributeError(
AttributeError: probability estimates are not available for loss='hinge'

  warnings.warn(

2023-09-17 20:47:38,957:WARNING:/usr/local/lib/python3.10/dist-packages/pycaret/internal/metrics.py:190: FitFailedWarning: Metric 'make_scorer(roc_auc_score, needs_proba=True, error_score=0.0, average=weighted, multi_class=ovr)' failed and error score 0.0 has been returned instead. If this is a custom metric, this usually means that the error is in the metric code. Full exception below:
Traceback (most recent call last):
  File "/usr/local/lib/python3.10/dist-packages/sklearn/metrics/_scorer.py", line 76, in _cached_call
    return cache[method]
KeyError: 'predict_proba'

During handling of the above exception, another exception occurred:

Traceback (most recent call last):
  File "/usr/local/lib/python3.10/dist-packages/pycaret/internal/metrics.py", line 182, in _score
    return super()._score(
  File "/usr/local/lib/python3.10/dist-packages/sklearn/metrics/_scorer.py", line 316, in _score
    y_pred = method_caller(clf, "predict_proba", X)
  File "/usr/local/lib/python3.10/dist-packages/sklearn/metrics/_scorer.py", line 78, in _cached_call
    result = getattr(estimator, method)(*args, **kwargs)
  File "/usr/local/lib/python3.10/dist-packages/sklearn/utils/_available_if.py", line 32, in __get__
    if not self.check(obj):
  File "/usr/local/lib/python3.10/dist-packages/sklearn/linear_model/_stochastic_gradient.py", line 1235, in _check_proba
    raise AttributeError(
AttributeError: probability estimates are not available for loss='hinge'

  warnings.warn(

2023-09-17 20:47:39,769:WARNING:/usr/local/lib/python3.10/dist-packages/pycaret/internal/metrics.py:190: FitFailedWarning: Metric 'make_scorer(roc_auc_score, needs_proba=True, error_score=0.0, average=weighted, multi_class=ovr)' failed and error score 0.0 has been returned instead. If this is a custom metric, this usually means that the error is in the metric code. Full exception below:
Traceback (most recent call last):
  File "/usr/local/lib/python3.10/dist-packages/sklearn/metrics/_scorer.py", line 76, in _cached_call
    return cache[method]
KeyError: 'predict_proba'

During handling of the above exception, another exception occurred:

Traceback (most recent call last):
  File "/usr/local/lib/python3.10/dist-packages/pycaret/internal/metrics.py", line 182, in _score
    return super()._score(
  File "/usr/local/lib/python3.10/dist-packages/sklearn/metrics/_scorer.py", line 316, in _score
    y_pred = method_caller(clf, "predict_proba", X)
  File "/usr/local/lib/python3.10/dist-packages/sklearn/metrics/_scorer.py", line 78, in _cached_call
    result = getattr(estimator, method)(*args, **kwargs)
  File "/usr/local/lib/python3.10/dist-packages/sklearn/utils/_available_if.py", line 32, in __get__
    if not self.check(obj):
  File "/usr/local/lib/python3.10/dist-packages/sklearn/linear_model/_stochastic_gradient.py", line 1235, in _check_proba
    raise AttributeError(
AttributeError: probability estimates are not available for loss='hinge'

  warnings.warn(

2023-09-17 20:47:40,486:WARNING:/usr/local/lib/python3.10/dist-packages/pycaret/internal/metrics.py:190: FitFailedWarning: Metric 'make_scorer(roc_auc_score, needs_proba=True, error_score=0.0, average=weighted, multi_class=ovr)' failed and error score 0.0 has been returned instead. If this is a custom metric, this usually means that the error is in the metric code. Full exception below:
Traceback (most recent call last):
  File "/usr/local/lib/python3.10/dist-packages/sklearn/metrics/_scorer.py", line 76, in _cached_call
    return cache[method]
KeyError: 'predict_proba'

During handling of the above exception, another exception occurred:

Traceback (most recent call last):
  File "/usr/local/lib/python3.10/dist-packages/pycaret/internal/metrics.py", line 182, in _score
    return super()._score(
  File "/usr/local/lib/python3.10/dist-packages/sklearn/metrics/_scorer.py", line 316, in _score
    y_pred = method_caller(clf, "predict_proba", X)
  File "/usr/local/lib/python3.10/dist-packages/sklearn/metrics/_scorer.py", line 78, in _cached_call
    result = getattr(estimator, method)(*args, **kwargs)
  File "/usr/local/lib/python3.10/dist-packages/sklearn/utils/_available_if.py", line 32, in __get__
    if not self.check(obj):
  File "/usr/local/lib/python3.10/dist-packages/sklearn/linear_model/_stochastic_gradient.py", line 1235, in _check_proba
    raise AttributeError(
AttributeError: probability estimates are not available for loss='hinge'

  warnings.warn(

2023-09-17 20:47:41,060:WARNING:/usr/local/lib/python3.10/dist-packages/pycaret/internal/metrics.py:190: FitFailedWarning: Metric 'make_scorer(roc_auc_score, needs_proba=True, error_score=0.0, average=weighted, multi_class=ovr)' failed and error score 0.0 has been returned instead. If this is a custom metric, this usually means that the error is in the metric code. Full exception below:
Traceback (most recent call last):
  File "/usr/local/lib/python3.10/dist-packages/sklearn/metrics/_scorer.py", line 76, in _cached_call
    return cache[method]
KeyError: 'predict_proba'

During handling of the above exception, another exception occurred:

Traceback (most recent call last):
  File "/usr/local/lib/python3.10/dist-packages/pycaret/internal/metrics.py", line 182, in _score
    return super()._score(
  File "/usr/local/lib/python3.10/dist-packages/sklearn/metrics/_scorer.py", line 316, in _score
    y_pred = method_caller(clf, "predict_proba", X)
  File "/usr/local/lib/python3.10/dist-packages/sklearn/metrics/_scorer.py", line 78, in _cached_call
    result = getattr(estimator, method)(*args, **kwargs)
  File "/usr/local/lib/python3.10/dist-packages/sklearn/utils/_available_if.py", line 32, in __get__
    if not self.check(obj):
  File "/usr/local/lib/python3.10/dist-packages/sklearn/linear_model/_stochastic_gradient.py", line 1235, in _check_proba
    raise AttributeError(
AttributeError: probability estimates are not available for loss='hinge'

  warnings.warn(

2023-09-17 20:47:41,662:WARNING:/usr/local/lib/python3.10/dist-packages/pycaret/internal/metrics.py:190: FitFailedWarning: Metric 'make_scorer(roc_auc_score, needs_proba=True, error_score=0.0, average=weighted, multi_class=ovr)' failed and error score 0.0 has been returned instead. If this is a custom metric, this usually means that the error is in the metric code. Full exception below:
Traceback (most recent call last):
  File "/usr/local/lib/python3.10/dist-packages/sklearn/metrics/_scorer.py", line 76, in _cached_call
    return cache[method]
KeyError: 'predict_proba'

During handling of the above exception, another exception occurred:

Traceback (most recent call last):
  File "/usr/local/lib/python3.10/dist-packages/pycaret/internal/metrics.py", line 182, in _score
    return super()._score(
  File "/usr/local/lib/python3.10/dist-packages/sklearn/metrics/_scorer.py", line 316, in _score
    y_pred = method_caller(clf, "predict_proba", X)
  File "/usr/local/lib/python3.10/dist-packages/sklearn/metrics/_scorer.py", line 78, in _cached_call
    result = getattr(estimator, method)(*args, **kwargs)
  File "/usr/local/lib/python3.10/dist-packages/sklearn/utils/_available_if.py", line 32, in __get__
    if not self.check(obj):
  File "/usr/local/lib/python3.10/dist-packages/sklearn/linear_model/_stochastic_gradient.py", line 1235, in _check_proba
    raise AttributeError(
AttributeError: probability estimates are not available for loss='hinge'

  warnings.warn(

2023-09-17 20:47:42,248:WARNING:/usr/local/lib/python3.10/dist-packages/pycaret/internal/metrics.py:190: FitFailedWarning: Metric 'make_scorer(roc_auc_score, needs_proba=True, error_score=0.0, average=weighted, multi_class=ovr)' failed and error score 0.0 has been returned instead. If this is a custom metric, this usually means that the error is in the metric code. Full exception below:
Traceback (most recent call last):
  File "/usr/local/lib/python3.10/dist-packages/sklearn/metrics/_scorer.py", line 76, in _cached_call
    return cache[method]
KeyError: 'predict_proba'

During handling of the above exception, another exception occurred:

Traceback (most recent call last):
  File "/usr/local/lib/python3.10/dist-packages/pycaret/internal/metrics.py", line 182, in _score
    return super()._score(
  File "/usr/local/lib/python3.10/dist-packages/sklearn/metrics/_scorer.py", line 316, in _score
    y_pred = method_caller(clf, "predict_proba", X)
  File "/usr/local/lib/python3.10/dist-packages/sklearn/metrics/_scorer.py", line 78, in _cached_call
    result = getattr(estimator, method)(*args, **kwargs)
  File "/usr/local/lib/python3.10/dist-packages/sklearn/utils/_available_if.py", line 32, in __get__
    if not self.check(obj):
  File "/usr/local/lib/python3.10/dist-packages/sklearn/linear_model/_stochastic_gradient.py", line 1235, in _check_proba
    raise AttributeError(
AttributeError: probability estimates are not available for loss='hinge'

  warnings.warn(

2023-09-17 20:47:42,855:WARNING:/usr/local/lib/python3.10/dist-packages/pycaret/internal/metrics.py:190: FitFailedWarning: Metric 'make_scorer(roc_auc_score, needs_proba=True, error_score=0.0, average=weighted, multi_class=ovr)' failed and error score 0.0 has been returned instead. If this is a custom metric, this usually means that the error is in the metric code. Full exception below:
Traceback (most recent call last):
  File "/usr/local/lib/python3.10/dist-packages/sklearn/metrics/_scorer.py", line 76, in _cached_call
    return cache[method]
KeyError: 'predict_proba'

During handling of the above exception, another exception occurred:

Traceback (most recent call last):
  File "/usr/local/lib/python3.10/dist-packages/pycaret/internal/metrics.py", line 182, in _score
    return super()._score(
  File "/usr/local/lib/python3.10/dist-packages/sklearn/metrics/_scorer.py", line 316, in _score
    y_pred = method_caller(clf, "predict_proba", X)
  File "/usr/local/lib/python3.10/dist-packages/sklearn/metrics/_scorer.py", line 78, in _cached_call
    result = getattr(estimator, method)(*args, **kwargs)
  File "/usr/local/lib/python3.10/dist-packages/sklearn/utils/_available_if.py", line 32, in __get__
    if not self.check(obj):
  File "/usr/local/lib/python3.10/dist-packages/sklearn/linear_model/_stochastic_gradient.py", line 1235, in _check_proba
    raise AttributeError(
AttributeError: probability estimates are not available for loss='hinge'

  warnings.warn(

2023-09-17 20:47:43,467:WARNING:/usr/local/lib/python3.10/dist-packages/pycaret/internal/metrics.py:190: FitFailedWarning: Metric 'make_scorer(roc_auc_score, needs_proba=True, error_score=0.0, average=weighted, multi_class=ovr)' failed and error score 0.0 has been returned instead. If this is a custom metric, this usually means that the error is in the metric code. Full exception below:
Traceback (most recent call last):
  File "/usr/local/lib/python3.10/dist-packages/sklearn/metrics/_scorer.py", line 76, in _cached_call
    return cache[method]
KeyError: 'predict_proba'

During handling of the above exception, another exception occurred:

Traceback (most recent call last):
  File "/usr/local/lib/python3.10/dist-packages/pycaret/internal/metrics.py", line 182, in _score
    return super()._score(
  File "/usr/local/lib/python3.10/dist-packages/sklearn/metrics/_scorer.py", line 316, in _score
    y_pred = method_caller(clf, "predict_proba", X)
  File "/usr/local/lib/python3.10/dist-packages/sklearn/metrics/_scorer.py", line 78, in _cached_call
    result = getattr(estimator, method)(*args, **kwargs)
  File "/usr/local/lib/python3.10/dist-packages/sklearn/utils/_available_if.py", line 32, in __get__
    if not self.check(obj):
  File "/usr/local/lib/python3.10/dist-packages/sklearn/linear_model/_stochastic_gradient.py", line 1235, in _check_proba
    raise AttributeError(
AttributeError: probability estimates are not available for loss='hinge'

  warnings.warn(

2023-09-17 20:47:44,058:WARNING:/usr/local/lib/python3.10/dist-packages/pycaret/internal/metrics.py:190: FitFailedWarning: Metric 'make_scorer(roc_auc_score, needs_proba=True, error_score=0.0, average=weighted, multi_class=ovr)' failed and error score 0.0 has been returned instead. If this is a custom metric, this usually means that the error is in the metric code. Full exception below:
Traceback (most recent call last):
  File "/usr/local/lib/python3.10/dist-packages/sklearn/metrics/_scorer.py", line 76, in _cached_call
    return cache[method]
KeyError: 'predict_proba'

During handling of the above exception, another exception occurred:

Traceback (most recent call last):
  File "/usr/local/lib/python3.10/dist-packages/pycaret/internal/metrics.py", line 182, in _score
    return super()._score(
  File "/usr/local/lib/python3.10/dist-packages/sklearn/metrics/_scorer.py", line 316, in _score
    y_pred = method_caller(clf, "predict_proba", X)
  File "/usr/local/lib/python3.10/dist-packages/sklearn/metrics/_scorer.py", line 78, in _cached_call
    result = getattr(estimator, method)(*args, **kwargs)
  File "/usr/local/lib/python3.10/dist-packages/sklearn/utils/_available_if.py", line 32, in __get__
    if not self.check(obj):
  File "/usr/local/lib/python3.10/dist-packages/sklearn/linear_model/_stochastic_gradient.py", line 1235, in _check_proba
    raise AttributeError(
AttributeError: probability estimates are not available for loss='hinge'

  warnings.warn(

2023-09-17 20:47:44,073:INFO:Calculating mean and std
2023-09-17 20:47:44,081:INFO:Creating metrics dataframe
2023-09-17 20:47:44,094:INFO:Uploading results into container
2023-09-17 20:47:44,095:INFO:Uploading model into container now
2023-09-17 20:47:44,095:INFO:_master_model_container: 5
2023-09-17 20:47:44,096:INFO:_display_container: 2
2023-09-17 20:47:44,096:INFO:SGDClassifier(alpha=0.0001, average=False, class_weight=None,
              early_stopping=False, epsilon=0.1, eta0=0.001, fit_intercept=True,
              l1_ratio=0.15, learning_rate='optimal', loss='hinge',
              max_iter=1000, n_iter_no_change=5, n_jobs=-1, penalty='l2',
              power_t=0.5, random_state=2858, shuffle=True, tol=0.001,
              validation_fraction=0.1, verbose=0, warm_start=False)
2023-09-17 20:47:44,097:INFO:create_model() successfully completed......................................
2023-09-17 20:47:44,337:INFO:SubProcess create_model() end ==================================
2023-09-17 20:47:44,337:INFO:Creating metrics dataframe
2023-09-17 20:47:44,362:INFO:Initializing Ridge Classifier
2023-09-17 20:47:44,363:INFO:Total runtime is 0.7120856205622356 minutes
2023-09-17 20:47:44,372:INFO:SubProcess create_model() called ==================================
2023-09-17 20:47:44,372:INFO:Initializing create_model()
2023-09-17 20:47:44,372:INFO:create_model(self=<pycaret.classification.oop.ClassificationExperiment object at 0x7f76ad0a8370>, estimator=ridge, fold=StratifiedKFold(n_splits=10, random_state=None, shuffle=False), round=4, cross_validation=True, predict=True, fit_kwargs={}, groups=None, refit=False, probability_threshold=None, experiment_custom_tags=None, verbose=False, system=False, add_to_model_list=True, metrics=None, display=<pycaret.internal.display.display.CommonDisplay object at 0x7f76a9411e10>, model_only=True, return_train_score=False, kwargs={})
2023-09-17 20:47:44,372:INFO:Checking exceptions
2023-09-17 20:47:44,372:INFO:Importing libraries
2023-09-17 20:47:44,372:INFO:Copying training dataset
2023-09-17 20:47:44,395:INFO:Defining folds
2023-09-17 20:47:44,395:INFO:Declaring metric variables
2023-09-17 20:47:44,403:INFO:Importing untrained model
2023-09-17 20:47:44,410:INFO:Ridge Classifier Imported successfully
2023-09-17 20:47:44,424:INFO:Starting cross validation
2023-09-17 20:47:44,427:INFO:Cross validating with StratifiedKFold(n_splits=10, random_state=None, shuffle=False), n_jobs=1
2023-09-17 20:47:44,838:WARNING:/usr/local/lib/python3.10/dist-packages/pycaret/internal/metrics.py:190: FitFailedWarning: Metric 'make_scorer(roc_auc_score, needs_proba=True, error_score=0.0, average=weighted, multi_class=ovr)' failed and error score 0.0 has been returned instead. If this is a custom metric, this usually means that the error is in the metric code. Full exception below:
Traceback (most recent call last):
  File "/usr/local/lib/python3.10/dist-packages/sklearn/metrics/_scorer.py", line 76, in _cached_call
    return cache[method]
KeyError: 'predict_proba'

During handling of the above exception, another exception occurred:

Traceback (most recent call last):
  File "/usr/local/lib/python3.10/dist-packages/pycaret/internal/metrics.py", line 182, in _score
    return super()._score(
  File "/usr/local/lib/python3.10/dist-packages/sklearn/metrics/_scorer.py", line 316, in _score
    y_pred = method_caller(clf, "predict_proba", X)
  File "/usr/local/lib/python3.10/dist-packages/sklearn/metrics/_scorer.py", line 78, in _cached_call
    result = getattr(estimator, method)(*args, **kwargs)
AttributeError: 'RidgeClassifier' object has no attribute 'predict_proba'

  warnings.warn(

2023-09-17 20:47:45,194:WARNING:/usr/local/lib/python3.10/dist-packages/pycaret/internal/metrics.py:190: FitFailedWarning: Metric 'make_scorer(roc_auc_score, needs_proba=True, error_score=0.0, average=weighted, multi_class=ovr)' failed and error score 0.0 has been returned instead. If this is a custom metric, this usually means that the error is in the metric code. Full exception below:
Traceback (most recent call last):
  File "/usr/local/lib/python3.10/dist-packages/sklearn/metrics/_scorer.py", line 76, in _cached_call
    return cache[method]
KeyError: 'predict_proba'

During handling of the above exception, another exception occurred:

Traceback (most recent call last):
  File "/usr/local/lib/python3.10/dist-packages/pycaret/internal/metrics.py", line 182, in _score
    return super()._score(
  File "/usr/local/lib/python3.10/dist-packages/sklearn/metrics/_scorer.py", line 316, in _score
    y_pred = method_caller(clf, "predict_proba", X)
  File "/usr/local/lib/python3.10/dist-packages/sklearn/metrics/_scorer.py", line 78, in _cached_call
    result = getattr(estimator, method)(*args, **kwargs)
AttributeError: 'RidgeClassifier' object has no attribute 'predict_proba'

  warnings.warn(

2023-09-17 20:47:45,500:WARNING:/usr/local/lib/python3.10/dist-packages/pycaret/internal/metrics.py:190: FitFailedWarning: Metric 'make_scorer(roc_auc_score, needs_proba=True, error_score=0.0, average=weighted, multi_class=ovr)' failed and error score 0.0 has been returned instead. If this is a custom metric, this usually means that the error is in the metric code. Full exception below:
Traceback (most recent call last):
  File "/usr/local/lib/python3.10/dist-packages/sklearn/metrics/_scorer.py", line 76, in _cached_call
    return cache[method]
KeyError: 'predict_proba'

During handling of the above exception, another exception occurred:

Traceback (most recent call last):
  File "/usr/local/lib/python3.10/dist-packages/pycaret/internal/metrics.py", line 182, in _score
    return super()._score(
  File "/usr/local/lib/python3.10/dist-packages/sklearn/metrics/_scorer.py", line 316, in _score
    y_pred = method_caller(clf, "predict_proba", X)
  File "/usr/local/lib/python3.10/dist-packages/sklearn/metrics/_scorer.py", line 78, in _cached_call
    result = getattr(estimator, method)(*args, **kwargs)
AttributeError: 'RidgeClassifier' object has no attribute 'predict_proba'

  warnings.warn(

2023-09-17 20:47:45,799:WARNING:/usr/local/lib/python3.10/dist-packages/pycaret/internal/metrics.py:190: FitFailedWarning: Metric 'make_scorer(roc_auc_score, needs_proba=True, error_score=0.0, average=weighted, multi_class=ovr)' failed and error score 0.0 has been returned instead. If this is a custom metric, this usually means that the error is in the metric code. Full exception below:
Traceback (most recent call last):
  File "/usr/local/lib/python3.10/dist-packages/sklearn/metrics/_scorer.py", line 76, in _cached_call
    return cache[method]
KeyError: 'predict_proba'

During handling of the above exception, another exception occurred:

Traceback (most recent call last):
  File "/usr/local/lib/python3.10/dist-packages/pycaret/internal/metrics.py", line 182, in _score
    return super()._score(
  File "/usr/local/lib/python3.10/dist-packages/sklearn/metrics/_scorer.py", line 316, in _score
    y_pred = method_caller(clf, "predict_proba", X)
  File "/usr/local/lib/python3.10/dist-packages/sklearn/metrics/_scorer.py", line 78, in _cached_call
    result = getattr(estimator, method)(*args, **kwargs)
AttributeError: 'RidgeClassifier' object has no attribute 'predict_proba'

  warnings.warn(

2023-09-17 20:47:46,099:WARNING:/usr/local/lib/python3.10/dist-packages/pycaret/internal/metrics.py:190: FitFailedWarning: Metric 'make_scorer(roc_auc_score, needs_proba=True, error_score=0.0, average=weighted, multi_class=ovr)' failed and error score 0.0 has been returned instead. If this is a custom metric, this usually means that the error is in the metric code. Full exception below:
Traceback (most recent call last):
  File "/usr/local/lib/python3.10/dist-packages/sklearn/metrics/_scorer.py", line 76, in _cached_call
    return cache[method]
KeyError: 'predict_proba'

During handling of the above exception, another exception occurred:

Traceback (most recent call last):
  File "/usr/local/lib/python3.10/dist-packages/pycaret/internal/metrics.py", line 182, in _score
    return super()._score(
  File "/usr/local/lib/python3.10/dist-packages/sklearn/metrics/_scorer.py", line 316, in _score
    y_pred = method_caller(clf, "predict_proba", X)
  File "/usr/local/lib/python3.10/dist-packages/sklearn/metrics/_scorer.py", line 78, in _cached_call
    result = getattr(estimator, method)(*args, **kwargs)
AttributeError: 'RidgeClassifier' object has no attribute 'predict_proba'

  warnings.warn(

2023-09-17 20:47:46,408:WARNING:/usr/local/lib/python3.10/dist-packages/pycaret/internal/metrics.py:190: FitFailedWarning: Metric 'make_scorer(roc_auc_score, needs_proba=True, error_score=0.0, average=weighted, multi_class=ovr)' failed and error score 0.0 has been returned instead. If this is a custom metric, this usually means that the error is in the metric code. Full exception below:
Traceback (most recent call last):
  File "/usr/local/lib/python3.10/dist-packages/sklearn/metrics/_scorer.py", line 76, in _cached_call
    return cache[method]
KeyError: 'predict_proba'

During handling of the above exception, another exception occurred:

Traceback (most recent call last):
  File "/usr/local/lib/python3.10/dist-packages/pycaret/internal/metrics.py", line 182, in _score
    return super()._score(
  File "/usr/local/lib/python3.10/dist-packages/sklearn/metrics/_scorer.py", line 316, in _score
    y_pred = method_caller(clf, "predict_proba", X)
  File "/usr/local/lib/python3.10/dist-packages/sklearn/metrics/_scorer.py", line 78, in _cached_call
    result = getattr(estimator, method)(*args, **kwargs)
AttributeError: 'RidgeClassifier' object has no attribute 'predict_proba'

  warnings.warn(

2023-09-17 20:47:46,708:WARNING:/usr/local/lib/python3.10/dist-packages/pycaret/internal/metrics.py:190: FitFailedWarning: Metric 'make_scorer(roc_auc_score, needs_proba=True, error_score=0.0, average=weighted, multi_class=ovr)' failed and error score 0.0 has been returned instead. If this is a custom metric, this usually means that the error is in the metric code. Full exception below:
Traceback (most recent call last):
  File "/usr/local/lib/python3.10/dist-packages/sklearn/metrics/_scorer.py", line 76, in _cached_call
    return cache[method]
KeyError: 'predict_proba'

During handling of the above exception, another exception occurred:

Traceback (most recent call last):
  File "/usr/local/lib/python3.10/dist-packages/pycaret/internal/metrics.py", line 182, in _score
    return super()._score(
  File "/usr/local/lib/python3.10/dist-packages/sklearn/metrics/_scorer.py", line 316, in _score
    y_pred = method_caller(clf, "predict_proba", X)
  File "/usr/local/lib/python3.10/dist-packages/sklearn/metrics/_scorer.py", line 78, in _cached_call
    result = getattr(estimator, method)(*args, **kwargs)
AttributeError: 'RidgeClassifier' object has no attribute 'predict_proba'

  warnings.warn(

2023-09-17 20:47:47,021:WARNING:/usr/local/lib/python3.10/dist-packages/pycaret/internal/metrics.py:190: FitFailedWarning: Metric 'make_scorer(roc_auc_score, needs_proba=True, error_score=0.0, average=weighted, multi_class=ovr)' failed and error score 0.0 has been returned instead. If this is a custom metric, this usually means that the error is in the metric code. Full exception below:
Traceback (most recent call last):
  File "/usr/local/lib/python3.10/dist-packages/sklearn/metrics/_scorer.py", line 76, in _cached_call
    return cache[method]
KeyError: 'predict_proba'

During handling of the above exception, another exception occurred:

Traceback (most recent call last):
  File "/usr/local/lib/python3.10/dist-packages/pycaret/internal/metrics.py", line 182, in _score
    return super()._score(
  File "/usr/local/lib/python3.10/dist-packages/sklearn/metrics/_scorer.py", line 316, in _score
    y_pred = method_caller(clf, "predict_proba", X)
  File "/usr/local/lib/python3.10/dist-packages/sklearn/metrics/_scorer.py", line 78, in _cached_call
    result = getattr(estimator, method)(*args, **kwargs)
AttributeError: 'RidgeClassifier' object has no attribute 'predict_proba'

  warnings.warn(

2023-09-17 20:47:47,342:WARNING:/usr/local/lib/python3.10/dist-packages/pycaret/internal/metrics.py:190: FitFailedWarning: Metric 'make_scorer(roc_auc_score, needs_proba=True, error_score=0.0, average=weighted, multi_class=ovr)' failed and error score 0.0 has been returned instead. If this is a custom metric, this usually means that the error is in the metric code. Full exception below:
Traceback (most recent call last):
  File "/usr/local/lib/python3.10/dist-packages/sklearn/metrics/_scorer.py", line 76, in _cached_call
    return cache[method]
KeyError: 'predict_proba'

During handling of the above exception, another exception occurred:

Traceback (most recent call last):
  File "/usr/local/lib/python3.10/dist-packages/pycaret/internal/metrics.py", line 182, in _score
    return super()._score(
  File "/usr/local/lib/python3.10/dist-packages/sklearn/metrics/_scorer.py", line 316, in _score
    y_pred = method_caller(clf, "predict_proba", X)
  File "/usr/local/lib/python3.10/dist-packages/sklearn/metrics/_scorer.py", line 78, in _cached_call
    result = getattr(estimator, method)(*args, **kwargs)
AttributeError: 'RidgeClassifier' object has no attribute 'predict_proba'

  warnings.warn(

2023-09-17 20:47:47,647:WARNING:/usr/local/lib/python3.10/dist-packages/pycaret/internal/metrics.py:190: FitFailedWarning: Metric 'make_scorer(roc_auc_score, needs_proba=True, error_score=0.0, average=weighted, multi_class=ovr)' failed and error score 0.0 has been returned instead. If this is a custom metric, this usually means that the error is in the metric code. Full exception below:
Traceback (most recent call last):
  File "/usr/local/lib/python3.10/dist-packages/sklearn/metrics/_scorer.py", line 76, in _cached_call
    return cache[method]
KeyError: 'predict_proba'

During handling of the above exception, another exception occurred:

Traceback (most recent call last):
  File "/usr/local/lib/python3.10/dist-packages/pycaret/internal/metrics.py", line 182, in _score
    return super()._score(
  File "/usr/local/lib/python3.10/dist-packages/sklearn/metrics/_scorer.py", line 316, in _score
    y_pred = method_caller(clf, "predict_proba", X)
  File "/usr/local/lib/python3.10/dist-packages/sklearn/metrics/_scorer.py", line 78, in _cached_call
    result = getattr(estimator, method)(*args, **kwargs)
AttributeError: 'RidgeClassifier' object has no attribute 'predict_proba'

  warnings.warn(

2023-09-17 20:47:47,663:INFO:Calculating mean and std
2023-09-17 20:47:47,666:INFO:Creating metrics dataframe
2023-09-17 20:47:47,674:INFO:Uploading results into container
2023-09-17 20:47:47,675:INFO:Uploading model into container now
2023-09-17 20:47:47,676:INFO:_master_model_container: 6
2023-09-17 20:47:47,676:INFO:_display_container: 2
2023-09-17 20:47:47,676:INFO:RidgeClassifier(alpha=1.0, class_weight=None, copy_X=True, fit_intercept=True,
                max_iter=None, positive=False, random_state=2858, solver='auto',
                tol=0.0001)
2023-09-17 20:47:47,677:INFO:create_model() successfully completed......................................
2023-09-17 20:47:47,858:INFO:SubProcess create_model() end ==================================
2023-09-17 20:47:47,859:INFO:Creating metrics dataframe
2023-09-17 20:47:47,876:INFO:Initializing Random Forest Classifier
2023-09-17 20:47:47,876:INFO:Total runtime is 0.7706424832344055 minutes
2023-09-17 20:47:47,886:INFO:SubProcess create_model() called ==================================
2023-09-17 20:47:47,887:INFO:Initializing create_model()
2023-09-17 20:47:47,887:INFO:create_model(self=<pycaret.classification.oop.ClassificationExperiment object at 0x7f76ad0a8370>, estimator=rf, fold=StratifiedKFold(n_splits=10, random_state=None, shuffle=False), round=4, cross_validation=True, predict=True, fit_kwargs={}, groups=None, refit=False, probability_threshold=None, experiment_custom_tags=None, verbose=False, system=False, add_to_model_list=True, metrics=None, display=<pycaret.internal.display.display.CommonDisplay object at 0x7f76a9411e10>, model_only=True, return_train_score=False, kwargs={})
2023-09-17 20:47:47,887:INFO:Checking exceptions
2023-09-17 20:47:47,887:INFO:Importing libraries
2023-09-17 20:47:47,888:INFO:Copying training dataset
2023-09-17 20:47:47,909:INFO:Defining folds
2023-09-17 20:47:47,909:INFO:Declaring metric variables
2023-09-17 20:47:47,919:INFO:Importing untrained model
2023-09-17 20:47:47,925:INFO:Random Forest Classifier Imported successfully
2023-09-17 20:47:47,938:INFO:Starting cross validation
2023-09-17 20:47:47,942:INFO:Cross validating with StratifiedKFold(n_splits=10, random_state=None, shuffle=False), n_jobs=1
2023-09-17 20:48:01,232:INFO:Calculating mean and std
2023-09-17 20:48:01,239:INFO:Creating metrics dataframe
2023-09-17 20:48:01,253:INFO:Uploading results into container
2023-09-17 20:48:01,254:INFO:Uploading model into container now
2023-09-17 20:48:01,254:INFO:_master_model_container: 7
2023-09-17 20:48:01,254:INFO:_display_container: 2
2023-09-17 20:48:01,255:INFO:RandomForestClassifier(bootstrap=True, ccp_alpha=0.0, class_weight=None,
                       criterion='gini', max_depth=None, max_features='sqrt',
                       max_leaf_nodes=None, max_samples=None,
                       min_impurity_decrease=0.0, min_samples_leaf=1,
                       min_samples_split=2, min_weight_fraction_leaf=0.0,
                       n_estimators=100, n_jobs=-1, oob_score=False,
                       random_state=2858, verbose=0, warm_start=False)
2023-09-17 20:48:01,255:INFO:create_model() successfully completed......................................
2023-09-17 20:48:01,474:INFO:SubProcess create_model() end ==================================
2023-09-17 20:48:01,475:INFO:Creating metrics dataframe
2023-09-17 20:48:01,501:INFO:Initializing Quadratic Discriminant Analysis
2023-09-17 20:48:01,501:INFO:Total runtime is 0.9977257966995239 minutes
2023-09-17 20:48:01,512:INFO:SubProcess create_model() called ==================================
2023-09-17 20:48:01,513:INFO:Initializing create_model()
2023-09-17 20:48:01,513:INFO:create_model(self=<pycaret.classification.oop.ClassificationExperiment object at 0x7f76ad0a8370>, estimator=qda, fold=StratifiedKFold(n_splits=10, random_state=None, shuffle=False), round=4, cross_validation=True, predict=True, fit_kwargs={}, groups=None, refit=False, probability_threshold=None, experiment_custom_tags=None, verbose=False, system=False, add_to_model_list=True, metrics=None, display=<pycaret.internal.display.display.CommonDisplay object at 0x7f76a9411e10>, model_only=True, return_train_score=False, kwargs={})
2023-09-17 20:48:01,513:INFO:Checking exceptions
2023-09-17 20:48:01,513:INFO:Importing libraries
2023-09-17 20:48:01,513:INFO:Copying training dataset
2023-09-17 20:48:01,535:INFO:Defining folds
2023-09-17 20:48:01,536:INFO:Declaring metric variables
2023-09-17 20:48:01,546:INFO:Importing untrained model
2023-09-17 20:48:01,554:INFO:Quadratic Discriminant Analysis Imported successfully
2023-09-17 20:48:01,575:INFO:Starting cross validation
2023-09-17 20:48:01,579:INFO:Cross validating with StratifiedKFold(n_splits=10, random_state=None, shuffle=False), n_jobs=1
2023-09-17 20:48:01,944:WARNING:/usr/local/lib/python3.10/dist-packages/sklearn/discriminant_analysis.py:926: UserWarning: Variables are collinear
  warnings.warn("Variables are collinear")

2023-09-17 20:48:02,451:WARNING:/usr/local/lib/python3.10/dist-packages/sklearn/discriminant_analysis.py:926: UserWarning: Variables are collinear
  warnings.warn("Variables are collinear")

2023-09-17 20:48:03,004:WARNING:/usr/local/lib/python3.10/dist-packages/sklearn/discriminant_analysis.py:926: UserWarning: Variables are collinear
  warnings.warn("Variables are collinear")

2023-09-17 20:48:03,466:WARNING:/usr/local/lib/python3.10/dist-packages/sklearn/discriminant_analysis.py:926: UserWarning: Variables are collinear
  warnings.warn("Variables are collinear")

2023-09-17 20:48:04,021:WARNING:/usr/local/lib/python3.10/dist-packages/sklearn/discriminant_analysis.py:926: UserWarning: Variables are collinear
  warnings.warn("Variables are collinear")

2023-09-17 20:48:04,503:WARNING:/usr/local/lib/python3.10/dist-packages/sklearn/discriminant_analysis.py:926: UserWarning: Variables are collinear
  warnings.warn("Variables are collinear")

2023-09-17 20:48:05,071:WARNING:/usr/local/lib/python3.10/dist-packages/sklearn/discriminant_analysis.py:926: UserWarning: Variables are collinear
  warnings.warn("Variables are collinear")

2023-09-17 20:48:05,576:WARNING:/usr/local/lib/python3.10/dist-packages/sklearn/discriminant_analysis.py:926: UserWarning: Variables are collinear
  warnings.warn("Variables are collinear")

2023-09-17 20:48:06,022:WARNING:/usr/local/lib/python3.10/dist-packages/sklearn/discriminant_analysis.py:926: UserWarning: Variables are collinear
  warnings.warn("Variables are collinear")

2023-09-17 20:48:06,467:WARNING:/usr/local/lib/python3.10/dist-packages/sklearn/discriminant_analysis.py:926: UserWarning: Variables are collinear
  warnings.warn("Variables are collinear")

2023-09-17 20:48:06,674:INFO:Calculating mean and std
2023-09-17 20:48:06,681:INFO:Creating metrics dataframe
2023-09-17 20:48:06,691:INFO:Uploading results into container
2023-09-17 20:48:06,692:INFO:Uploading model into container now
2023-09-17 20:48:06,697:INFO:_master_model_container: 8
2023-09-17 20:48:06,700:INFO:_display_container: 2
2023-09-17 20:48:06,701:INFO:QuadraticDiscriminantAnalysis(priors=None, reg_param=0.0,
                              store_covariance=False, tol=0.0001)
2023-09-17 20:48:06,701:INFO:create_model() successfully completed......................................
2023-09-17 20:48:06,919:INFO:SubProcess create_model() end ==================================
2023-09-17 20:48:06,920:INFO:Creating metrics dataframe
2023-09-17 20:48:06,948:INFO:Initializing Ada Boost Classifier
2023-09-17 20:48:06,948:INFO:Total runtime is 1.0885041991869608 minutes
2023-09-17 20:48:06,955:INFO:SubProcess create_model() called ==================================
2023-09-17 20:48:06,956:INFO:Initializing create_model()
2023-09-17 20:48:06,956:INFO:create_model(self=<pycaret.classification.oop.ClassificationExperiment object at 0x7f76ad0a8370>, estimator=ada, fold=StratifiedKFold(n_splits=10, random_state=None, shuffle=False), round=4, cross_validation=True, predict=True, fit_kwargs={}, groups=None, refit=False, probability_threshold=None, experiment_custom_tags=None, verbose=False, system=False, add_to_model_list=True, metrics=None, display=<pycaret.internal.display.display.CommonDisplay object at 0x7f76a9411e10>, model_only=True, return_train_score=False, kwargs={})
2023-09-17 20:48:06,956:INFO:Checking exceptions
2023-09-17 20:48:06,956:INFO:Importing libraries
2023-09-17 20:48:06,956:INFO:Copying training dataset
2023-09-17 20:48:06,977:INFO:Defining folds
2023-09-17 20:48:06,977:INFO:Declaring metric variables
2023-09-17 20:48:06,987:INFO:Importing untrained model
2023-09-17 20:48:06,997:INFO:Ada Boost Classifier Imported successfully
2023-09-17 20:48:07,017:INFO:Starting cross validation
2023-09-17 20:48:07,021:INFO:Cross validating with StratifiedKFold(n_splits=10, random_state=None, shuffle=False), n_jobs=1
2023-09-17 20:48:13,751:INFO:Calculating mean and std
2023-09-17 20:48:13,753:INFO:Creating metrics dataframe
2023-09-17 20:48:13,764:INFO:Uploading results into container
2023-09-17 20:48:13,764:INFO:Uploading model into container now
2023-09-17 20:48:13,765:INFO:_master_model_container: 9
2023-09-17 20:48:13,765:INFO:_display_container: 2
2023-09-17 20:48:13,766:INFO:AdaBoostClassifier(algorithm='SAMME.R', base_estimator='deprecated',
                   estimator=None, learning_rate=1.0, n_estimators=50,
                   random_state=2858)
2023-09-17 20:48:13,766:INFO:create_model() successfully completed......................................
2023-09-17 20:48:13,949:INFO:SubProcess create_model() end ==================================
2023-09-17 20:48:13,949:INFO:Creating metrics dataframe
2023-09-17 20:48:13,963:INFO:Initializing Gradient Boosting Classifier
2023-09-17 20:48:13,964:INFO:Total runtime is 1.2054394721984862 minutes
2023-09-17 20:48:13,971:INFO:SubProcess create_model() called ==================================
2023-09-17 20:48:13,971:INFO:Initializing create_model()
2023-09-17 20:48:13,971:INFO:create_model(self=<pycaret.classification.oop.ClassificationExperiment object at 0x7f76ad0a8370>, estimator=gbc, fold=StratifiedKFold(n_splits=10, random_state=None, shuffle=False), round=4, cross_validation=True, predict=True, fit_kwargs={}, groups=None, refit=False, probability_threshold=None, experiment_custom_tags=None, verbose=False, system=False, add_to_model_list=True, metrics=None, display=<pycaret.internal.display.display.CommonDisplay object at 0x7f76a9411e10>, model_only=True, return_train_score=False, kwargs={})
2023-09-17 20:48:13,972:INFO:Checking exceptions
2023-09-17 20:48:13,972:INFO:Importing libraries
2023-09-17 20:48:13,972:INFO:Copying training dataset
2023-09-17 20:48:13,984:INFO:Defining folds
2023-09-17 20:48:13,984:INFO:Declaring metric variables
2023-09-17 20:48:13,996:INFO:Importing untrained model
2023-09-17 20:48:14,004:INFO:Gradient Boosting Classifier Imported successfully
2023-09-17 20:48:14,017:INFO:Starting cross validation
2023-09-17 20:48:14,024:INFO:Cross validating with StratifiedKFold(n_splits=10, random_state=None, shuffle=False), n_jobs=1
2023-09-17 20:48:32,631:INFO:Calculating mean and std
2023-09-17 20:48:32,639:INFO:Creating metrics dataframe
2023-09-17 20:48:32,650:INFO:Uploading results into container
2023-09-17 20:48:32,651:INFO:Uploading model into container now
2023-09-17 20:48:32,652:INFO:_master_model_container: 10
2023-09-17 20:48:32,652:INFO:_display_container: 2
2023-09-17 20:48:32,653:INFO:GradientBoostingClassifier(ccp_alpha=0.0, criterion='friedman_mse', init=None,
                           learning_rate=0.1, loss='log_loss', max_depth=3,
                           max_features=None, max_leaf_nodes=None,
                           min_impurity_decrease=0.0, min_samples_leaf=1,
                           min_samples_split=2, min_weight_fraction_leaf=0.0,
                           n_estimators=100, n_iter_no_change=None,
                           random_state=2858, subsample=1.0, tol=0.0001,
                           validation_fraction=0.1, verbose=0,
                           warm_start=False)
2023-09-17 20:48:32,653:INFO:create_model() successfully completed......................................
2023-09-17 20:48:32,815:INFO:SubProcess create_model() end ==================================
2023-09-17 20:48:32,815:INFO:Creating metrics dataframe
2023-09-17 20:48:32,830:INFO:Initializing Linear Discriminant Analysis
2023-09-17 20:48:32,830:INFO:Total runtime is 1.5198765675226846 minutes
2023-09-17 20:48:32,837:INFO:SubProcess create_model() called ==================================
2023-09-17 20:48:32,839:INFO:Initializing create_model()
2023-09-17 20:48:32,839:INFO:create_model(self=<pycaret.classification.oop.ClassificationExperiment object at 0x7f76ad0a8370>, estimator=lda, fold=StratifiedKFold(n_splits=10, random_state=None, shuffle=False), round=4, cross_validation=True, predict=True, fit_kwargs={}, groups=None, refit=False, probability_threshold=None, experiment_custom_tags=None, verbose=False, system=False, add_to_model_list=True, metrics=None, display=<pycaret.internal.display.display.CommonDisplay object at 0x7f76a9411e10>, model_only=True, return_train_score=False, kwargs={})
2023-09-17 20:48:32,840:INFO:Checking exceptions
2023-09-17 20:48:32,840:INFO:Importing libraries
2023-09-17 20:48:32,840:INFO:Copying training dataset
2023-09-17 20:48:32,852:INFO:Defining folds
2023-09-17 20:48:32,853:INFO:Declaring metric variables
2023-09-17 20:48:32,862:INFO:Importing untrained model
2023-09-17 20:48:32,868:INFO:Linear Discriminant Analysis Imported successfully
2023-09-17 20:48:32,882:INFO:Starting cross validation
2023-09-17 20:48:32,885:INFO:Cross validating with StratifiedKFold(n_splits=10, random_state=None, shuffle=False), n_jobs=1
2023-09-17 20:48:36,313:INFO:Calculating mean and std
2023-09-17 20:48:36,315:INFO:Creating metrics dataframe
2023-09-17 20:48:36,324:INFO:Uploading results into container
2023-09-17 20:48:36,325:INFO:Uploading model into container now
2023-09-17 20:48:36,328:INFO:_master_model_container: 11
2023-09-17 20:48:36,329:INFO:_display_container: 2
2023-09-17 20:48:36,329:INFO:LinearDiscriminantAnalysis(covariance_estimator=None, n_components=None,
                           priors=None, shrinkage=None, solver='svd',
                           store_covariance=False, tol=0.0001)
2023-09-17 20:48:36,329:INFO:create_model() successfully completed......................................
2023-09-17 20:48:36,520:INFO:SubProcess create_model() end ==================================
2023-09-17 20:48:36,521:INFO:Creating metrics dataframe
2023-09-17 20:48:36,541:INFO:Initializing Extra Trees Classifier
2023-09-17 20:48:36,541:INFO:Total runtime is 1.5817309220631917 minutes
2023-09-17 20:48:36,548:INFO:SubProcess create_model() called ==================================
2023-09-17 20:48:36,549:INFO:Initializing create_model()
2023-09-17 20:48:36,549:INFO:create_model(self=<pycaret.classification.oop.ClassificationExperiment object at 0x7f76ad0a8370>, estimator=et, fold=StratifiedKFold(n_splits=10, random_state=None, shuffle=False), round=4, cross_validation=True, predict=True, fit_kwargs={}, groups=None, refit=False, probability_threshold=None, experiment_custom_tags=None, verbose=False, system=False, add_to_model_list=True, metrics=None, display=<pycaret.internal.display.display.CommonDisplay object at 0x7f76a9411e10>, model_only=True, return_train_score=False, kwargs={})
2023-09-17 20:48:36,549:INFO:Checking exceptions
2023-09-17 20:48:36,549:INFO:Importing libraries
2023-09-17 20:48:36,549:INFO:Copying training dataset
2023-09-17 20:48:36,561:INFO:Defining folds
2023-09-17 20:48:36,562:INFO:Declaring metric variables
2023-09-17 20:48:36,572:INFO:Importing untrained model
2023-09-17 20:48:36,581:INFO:Extra Trees Classifier Imported successfully
2023-09-17 20:48:36,593:INFO:Starting cross validation
2023-09-17 20:48:36,596:INFO:Cross validating with StratifiedKFold(n_splits=10, random_state=None, shuffle=False), n_jobs=1
2023-09-17 20:48:51,095:INFO:Calculating mean and std
2023-09-17 20:48:51,099:INFO:Creating metrics dataframe
2023-09-17 20:48:51,109:INFO:Uploading results into container
2023-09-17 20:48:51,110:INFO:Uploading model into container now
2023-09-17 20:48:51,110:INFO:_master_model_container: 12
2023-09-17 20:48:51,111:INFO:_display_container: 2
2023-09-17 20:48:51,111:INFO:ExtraTreesClassifier(bootstrap=False, ccp_alpha=0.0, class_weight=None,
                     criterion='gini', max_depth=None, max_features='sqrt',
                     max_leaf_nodes=None, max_samples=None,
                     min_impurity_decrease=0.0, min_samples_leaf=1,
                     min_samples_split=2, min_weight_fraction_leaf=0.0,
                     n_estimators=100, n_jobs=-1, oob_score=False,
                     random_state=2858, verbose=0, warm_start=False)
2023-09-17 20:48:51,112:INFO:create_model() successfully completed......................................
2023-09-17 20:48:51,327:INFO:SubProcess create_model() end ==================================
2023-09-17 20:48:51,328:INFO:Creating metrics dataframe
2023-09-17 20:48:51,356:INFO:Initializing Extreme Gradient Boosting
2023-09-17 20:48:51,356:INFO:Total runtime is 1.8286459287007648 minutes
2023-09-17 20:48:51,364:INFO:SubProcess create_model() called ==================================
2023-09-17 20:48:51,364:INFO:Initializing create_model()
2023-09-17 20:48:51,364:INFO:create_model(self=<pycaret.classification.oop.ClassificationExperiment object at 0x7f76ad0a8370>, estimator=xgboost, fold=StratifiedKFold(n_splits=10, random_state=None, shuffle=False), round=4, cross_validation=True, predict=True, fit_kwargs={}, groups=None, refit=False, probability_threshold=None, experiment_custom_tags=None, verbose=False, system=False, add_to_model_list=True, metrics=None, display=<pycaret.internal.display.display.CommonDisplay object at 0x7f76a9411e10>, model_only=True, return_train_score=False, kwargs={})
2023-09-17 20:48:51,364:INFO:Checking exceptions
2023-09-17 20:48:51,364:INFO:Importing libraries
2023-09-17 20:48:51,364:INFO:Copying training dataset
2023-09-17 20:48:51,380:INFO:Defining folds
2023-09-17 20:48:51,380:INFO:Declaring metric variables
2023-09-17 20:48:51,388:INFO:Importing untrained model
2023-09-17 20:48:51,396:INFO:Extreme Gradient Boosting Imported successfully
2023-09-17 20:48:51,482:INFO:Starting cross validation
2023-09-17 20:48:51,501:INFO:Cross validating with StratifiedKFold(n_splits=10, random_state=None, shuffle=False), n_jobs=1
2023-09-17 20:48:55,044:WARNING:create_model() for xgboost raised an exception or returned all 0.0, trying without fit_kwargs:
2023-09-17 20:48:55,045:WARNING:Traceback (most recent call last):
  File "/usr/local/lib/python3.10/dist-packages/pycaret/internal/pycaret_experiment/supervised_experiment.py", line 796, in compare_models
    model, model_fit_time = self._create_model(**create_model_args)
  File "/usr/local/lib/python3.10/dist-packages/pycaret/internal/pycaret_experiment/supervised_experiment.py", line 1527, in _create_model
    model, model_fit_time, model_results, _ = self._create_model_with_cv(
  File "/usr/local/lib/python3.10/dist-packages/pycaret/internal/pycaret_experiment/supervised_experiment.py", line 1121, in _create_model_with_cv
    scores = cross_validate(
  File "/usr/local/lib/python3.10/dist-packages/sklearn/model_selection/_validation.py", line 285, in cross_validate
    _warn_or_raise_about_fit_failures(results, error_score)
  File "/usr/local/lib/python3.10/dist-packages/sklearn/model_selection/_validation.py", line 367, in _warn_or_raise_about_fit_failures
    raise ValueError(all_fits_failed_message)
ValueError: 
All the 10 fits failed.
It is very likely that your model is misconfigured.
You can try to debug the error by setting error_score='raise'.

Below are more details about the failures:
--------------------------------------------------------------------------------
1 fits failed with the following error:
Traceback (most recent call last):
  File "/usr/local/lib/python3.10/dist-packages/sklearn/model_selection/_validation.py", line 686, in _fit_and_score
    estimator.fit(X_train, y_train, **fit_params)
  File "/usr/local/lib/python3.10/dist-packages/pycaret/internal/pipeline.py", line 267, in fit
    fitted_estimator = self._memory_fit(
  File "/usr/local/lib/python3.10/dist-packages/joblib/memory.py", line 353, in __call__
    return self.func(*args, **kwargs)
  File "/usr/local/lib/python3.10/dist-packages/pycaret/internal/pipeline.py", line 66, in _fit_one
    transformer.fit(*args, **fit_params)
  File "/usr/local/lib/python3.10/dist-packages/xgboost/core.py", line 620, in inner_f
    return func(**kwargs)
  File "/usr/local/lib/python3.10/dist-packages/xgboost/sklearn.py", line 1490, in fit
    self._Booster = train(
  File "/usr/local/lib/python3.10/dist-packages/xgboost/core.py", line 620, in inner_f
    return func(**kwargs)
  File "/usr/local/lib/python3.10/dist-packages/xgboost/training.py", line 185, in train
    bst.update(dtrain, i, obj)
  File "/usr/local/lib/python3.10/dist-packages/xgboost/core.py", line 1918, in update
    _check_call(_LIB.XGBoosterUpdateOneIter(self.handle,
  File "/usr/local/lib/python3.10/dist-packages/xgboost/core.py", line 279, in _check_call
    raise XGBoostError(py_str(_LIB.XGBGetLastError()))
xgboost.core.XGBoostError: [20:48:52] ../src/gbm/gbtree.cc:625: Check failed: common::AllVisibleGPUs() >= 1 (0 vs. 1) : No visible GPU is found for XGBoost.
Stack trace:
  [bt] (0) /usr/local/lib/python3.10/dist-packages/xgboost/lib/libxgboost.so(+0x2a7e13) [0x7f76936a7e13]
  [bt] (1) /usr/local/lib/python3.10/dist-packages/xgboost/lib/libxgboost.so(+0x2ab120) [0x7f76936ab120]
  [bt] (2) /usr/local/lib/python3.10/dist-packages/xgboost/lib/libxgboost.so(+0x2ab52a) [0x7f76936ab52a]
  [bt] (3) /usr/local/lib/python3.10/dist-packages/xgboost/lib/libxgboost.so(+0x2e03c7) [0x7f76936e03c7]
  [bt] (4) /usr/local/lib/python3.10/dist-packages/xgboost/lib/libxgboost.so(XGBoosterUpdateOneIter+0x70) [0x7f769353c5a0]
  [bt] (5) /lib/x86_64-linux-gnu/libffi.so.8(+0x7e2e) [0x7f7708341e2e]
  [bt] (6) /lib/x86_64-linux-gnu/libffi.so.8(+0x4493) [0x7f770833e493]
  [bt] (7) /usr/lib/python3.10/lib-dynload/_ctypes.cpython-310-x86_64-linux-gnu.so(+0xa3e9) [0x7f77083673e9]
  [bt] (8) /usr/lib/python3.10/lib-dynload/_ctypes.cpython-310-x86_64-linux-gnu.so(+0x9a00) [0x7f7708366a00]



--------------------------------------------------------------------------------
3 fits failed with the following error:
Traceback (most recent call last):
  File "/usr/local/lib/python3.10/dist-packages/sklearn/model_selection/_validation.py", line 686, in _fit_and_score
    estimator.fit(X_train, y_train, **fit_params)
  File "/usr/local/lib/python3.10/dist-packages/pycaret/internal/pipeline.py", line 267, in fit
    fitted_estimator = self._memory_fit(
  File "/usr/local/lib/python3.10/dist-packages/joblib/memory.py", line 353, in __call__
    return self.func(*args, **kwargs)
  File "/usr/local/lib/python3.10/dist-packages/pycaret/internal/pipeline.py", line 66, in _fit_one
    transformer.fit(*args, **fit_params)
  File "/usr/local/lib/python3.10/dist-packages/xgboost/core.py", line 620, in inner_f
    return func(**kwargs)
  File "/usr/local/lib/python3.10/dist-packages/xgboost/sklearn.py", line 1490, in fit
    self._Booster = train(
  File "/usr/local/lib/python3.10/dist-packages/xgboost/core.py", line 620, in inner_f
    return func(**kwargs)
  File "/usr/local/lib/python3.10/dist-packages/xgboost/training.py", line 185, in train
    bst.update(dtrain, i, obj)
  File "/usr/local/lib/python3.10/dist-packages/xgboost/core.py", line 1918, in update
    _check_call(_LIB.XGBoosterUpdateOneIter(self.handle,
  File "/usr/local/lib/python3.10/dist-packages/xgboost/core.py", line 279, in _check_call
    raise XGBoostError(py_str(_LIB.XGBGetLastError()))
xgboost.core.XGBoostError: [20:48:53] ../src/gbm/gbtree.cc:625: Check failed: common::AllVisibleGPUs() >= 1 (0 vs. 1) : No visible GPU is found for XGBoost.
Stack trace:
  [bt] (0) /usr/local/lib/python3.10/dist-packages/xgboost/lib/libxgboost.so(+0x2a7e13) [0x7f76936a7e13]
  [bt] (1) /usr/local/lib/python3.10/dist-packages/xgboost/lib/libxgboost.so(+0x2ab120) [0x7f76936ab120]
  [bt] (2) /usr/local/lib/python3.10/dist-packages/xgboost/lib/libxgboost.so(+0x2ab52a) [0x7f76936ab52a]
  [bt] (3) /usr/local/lib/python3.10/dist-packages/xgboost/lib/libxgboost.so(+0x2e03c7) [0x7f76936e03c7]
  [bt] (4) /usr/local/lib/python3.10/dist-packages/xgboost/lib/libxgboost.so(XGBoosterUpdateOneIter+0x70) [0x7f769353c5a0]
  [bt] (5) /lib/x86_64-linux-gnu/libffi.so.8(+0x7e2e) [0x7f7708341e2e]
  [bt] (6) /lib/x86_64-linux-gnu/libffi.so.8(+0x4493) [0x7f770833e493]
  [bt] (7) /usr/lib/python3.10/lib-dynload/_ctypes.cpython-310-x86_64-linux-gnu.so(+0xa3e9) [0x7f77083673e9]
  [bt] (8) /usr/lib/python3.10/lib-dynload/_ctypes.cpython-310-x86_64-linux-gnu.so(+0x9a00) [0x7f7708366a00]



--------------------------------------------------------------------------------
5 fits failed with the following error:
Traceback (most recent call last):
  File "/usr/local/lib/python3.10/dist-packages/sklearn/model_selection/_validation.py", line 686, in _fit_and_score
    estimator.fit(X_train, y_train, **fit_params)
  File "/usr/local/lib/python3.10/dist-packages/pycaret/internal/pipeline.py", line 267, in fit
    fitted_estimator = self._memory_fit(
  File "/usr/local/lib/python3.10/dist-packages/joblib/memory.py", line 353, in __call__
    return self.func(*args, **kwargs)
  File "/usr/local/lib/python3.10/dist-packages/pycaret/internal/pipeline.py", line 66, in _fit_one
    transformer.fit(*args, **fit_params)
  File "/usr/local/lib/python3.10/dist-packages/xgboost/core.py", line 620, in inner_f
    return func(**kwargs)
  File "/usr/local/lib/python3.10/dist-packages/xgboost/sklearn.py", line 1490, in fit
    self._Booster = train(
  File "/usr/local/lib/python3.10/dist-packages/xgboost/core.py", line 620, in inner_f
    return func(**kwargs)
  File "/usr/local/lib/python3.10/dist-packages/xgboost/training.py", line 185, in train
    bst.update(dtrain, i, obj)
  File "/usr/local/lib/python3.10/dist-packages/xgboost/core.py", line 1918, in update
    _check_call(_LIB.XGBoosterUpdateOneIter(self.handle,
  File "/usr/local/lib/python3.10/dist-packages/xgboost/core.py", line 279, in _check_call
    raise XGBoostError(py_str(_LIB.XGBGetLastError()))
xgboost.core.XGBoostError: [20:48:54] ../src/gbm/gbtree.cc:625: Check failed: common::AllVisibleGPUs() >= 1 (0 vs. 1) : No visible GPU is found for XGBoost.
Stack trace:
  [bt] (0) /usr/local/lib/python3.10/dist-packages/xgboost/lib/libxgboost.so(+0x2a7e13) [0x7f76936a7e13]
  [bt] (1) /usr/local/lib/python3.10/dist-packages/xgboost/lib/libxgboost.so(+0x2ab120) [0x7f76936ab120]
  [bt] (2) /usr/local/lib/python3.10/dist-packages/xgboost/lib/libxgboost.so(+0x2ab52a) [0x7f76936ab52a]
  [bt] (3) /usr/local/lib/python3.10/dist-packages/xgboost/lib/libxgboost.so(+0x2e03c7) [0x7f76936e03c7]
  [bt] (4) /usr/local/lib/python3.10/dist-packages/xgboost/lib/libxgboost.so(XGBoosterUpdateOneIter+0x70) [0x7f769353c5a0]
  [bt] (5) /lib/x86_64-linux-gnu/libffi.so.8(+0x7e2e) [0x7f7708341e2e]
  [bt] (6) /lib/x86_64-linux-gnu/libffi.so.8(+0x4493) [0x7f770833e493]
  [bt] (7) /usr/lib/python3.10/lib-dynload/_ctypes.cpython-310-x86_64-linux-gnu.so(+0xa3e9) [0x7f77083673e9]
  [bt] (8) /usr/lib/python3.10/lib-dynload/_ctypes.cpython-310-x86_64-linux-gnu.so(+0x9a00) [0x7f7708366a00]



--------------------------------------------------------------------------------
1 fits failed with the following error:
Traceback (most recent call last):
  File "/usr/local/lib/python3.10/dist-packages/sklearn/model_selection/_validation.py", line 686, in _fit_and_score
    estimator.fit(X_train, y_train, **fit_params)
  File "/usr/local/lib/python3.10/dist-packages/pycaret/internal/pipeline.py", line 267, in fit
    fitted_estimator = self._memory_fit(
  File "/usr/local/lib/python3.10/dist-packages/joblib/memory.py", line 353, in __call__
    return self.func(*args, **kwargs)
  File "/usr/local/lib/python3.10/dist-packages/pycaret/internal/pipeline.py", line 66, in _fit_one
    transformer.fit(*args, **fit_params)
  File "/usr/local/lib/python3.10/dist-packages/xgboost/core.py", line 620, in inner_f
    return func(**kwargs)
  File "/usr/local/lib/python3.10/dist-packages/xgboost/sklearn.py", line 1490, in fit
    self._Booster = train(
  File "/usr/local/lib/python3.10/dist-packages/xgboost/core.py", line 620, in inner_f
    return func(**kwargs)
  File "/usr/local/lib/python3.10/dist-packages/xgboost/training.py", line 185, in train
    bst.update(dtrain, i, obj)
  File "/usr/local/lib/python3.10/dist-packages/xgboost/core.py", line 1918, in update
    _check_call(_LIB.XGBoosterUpdateOneIter(self.handle,
  File "/usr/local/lib/python3.10/dist-packages/xgboost/core.py", line 279, in _check_call
    raise XGBoostError(py_str(_LIB.XGBGetLastError()))
xgboost.core.XGBoostError: [20:48:55] ../src/gbm/gbtree.cc:625: Check failed: common::AllVisibleGPUs() >= 1 (0 vs. 1) : No visible GPU is found for XGBoost.
Stack trace:
  [bt] (0) /usr/local/lib/python3.10/dist-packages/xgboost/lib/libxgboost.so(+0x2a7e13) [0x7f76936a7e13]
  [bt] (1) /usr/local/lib/python3.10/dist-packages/xgboost/lib/libxgboost.so(+0x2ab120) [0x7f76936ab120]
  [bt] (2) /usr/local/lib/python3.10/dist-packages/xgboost/lib/libxgboost.so(+0x2ab52a) [0x7f76936ab52a]
  [bt] (3) /usr/local/lib/python3.10/dist-packages/xgboost/lib/libxgboost.so(+0x2e03c7) [0x7f76936e03c7]
  [bt] (4) /usr/local/lib/python3.10/dist-packages/xgboost/lib/libxgboost.so(XGBoosterUpdateOneIter+0x70) [0x7f769353c5a0]
  [bt] (5) /lib/x86_64-linux-gnu/libffi.so.8(+0x7e2e) [0x7f7708341e2e]
  [bt] (6) /lib/x86_64-linux-gnu/libffi.so.8(+0x4493) [0x7f770833e493]
  [bt] (7) /usr/lib/python3.10/lib-dynload/_ctypes.cpython-310-x86_64-linux-gnu.so(+0xa3e9) [0x7f77083673e9]
  [bt] (8) /usr/lib/python3.10/lib-dynload/_ctypes.cpython-310-x86_64-linux-gnu.so(+0x9a00) [0x7f7708366a00]




2023-09-17 20:48:55,045:INFO:Initializing create_model()
2023-09-17 20:48:55,045:INFO:create_model(self=<pycaret.classification.oop.ClassificationExperiment object at 0x7f76ad0a8370>, estimator=xgboost, fold=StratifiedKFold(n_splits=10, random_state=None, shuffle=False), round=4, cross_validation=True, predict=True, fit_kwargs={}, groups=None, refit=False, probability_threshold=None, experiment_custom_tags=None, verbose=False, system=False, add_to_model_list=True, metrics=None, display=<pycaret.internal.display.display.CommonDisplay object at 0x7f76a9411e10>, model_only=True, return_train_score=False, kwargs={})
2023-09-17 20:48:55,045:INFO:Checking exceptions
2023-09-17 20:48:55,045:INFO:Importing libraries
2023-09-17 20:48:55,045:INFO:Copying training dataset
2023-09-17 20:48:55,062:INFO:Defining folds
2023-09-17 20:48:55,062:INFO:Declaring metric variables
2023-09-17 20:48:55,071:INFO:Importing untrained model
2023-09-17 20:48:55,079:INFO:Extreme Gradient Boosting Imported successfully
2023-09-17 20:48:55,091:INFO:Starting cross validation
2023-09-17 20:48:55,094:INFO:Cross validating with StratifiedKFold(n_splits=10, random_state=None, shuffle=False), n_jobs=1
2023-09-17 20:48:57,185:ERROR:create_model() for xgboost raised an exception or returned all 0.0:
2023-09-17 20:48:57,185:ERROR:Traceback (most recent call last):
  File "/usr/local/lib/python3.10/dist-packages/pycaret/internal/pycaret_experiment/supervised_experiment.py", line 796, in compare_models
    model, model_fit_time = self._create_model(**create_model_args)
  File "/usr/local/lib/python3.10/dist-packages/pycaret/internal/pycaret_experiment/supervised_experiment.py", line 1527, in _create_model
    model, model_fit_time, model_results, _ = self._create_model_with_cv(
  File "/usr/local/lib/python3.10/dist-packages/pycaret/internal/pycaret_experiment/supervised_experiment.py", line 1121, in _create_model_with_cv
    scores = cross_validate(
  File "/usr/local/lib/python3.10/dist-packages/sklearn/model_selection/_validation.py", line 285, in cross_validate
    _warn_or_raise_about_fit_failures(results, error_score)
  File "/usr/local/lib/python3.10/dist-packages/sklearn/model_selection/_validation.py", line 367, in _warn_or_raise_about_fit_failures
    raise ValueError(all_fits_failed_message)
ValueError: 
All the 10 fits failed.
It is very likely that your model is misconfigured.
You can try to debug the error by setting error_score='raise'.

Below are more details about the failures:
--------------------------------------------------------------------------------
1 fits failed with the following error:
Traceback (most recent call last):
  File "/usr/local/lib/python3.10/dist-packages/sklearn/model_selection/_validation.py", line 686, in _fit_and_score
    estimator.fit(X_train, y_train, **fit_params)
  File "/usr/local/lib/python3.10/dist-packages/pycaret/internal/pipeline.py", line 267, in fit
    fitted_estimator = self._memory_fit(
  File "/usr/local/lib/python3.10/dist-packages/joblib/memory.py", line 353, in __call__
    return self.func(*args, **kwargs)
  File "/usr/local/lib/python3.10/dist-packages/pycaret/internal/pipeline.py", line 66, in _fit_one
    transformer.fit(*args, **fit_params)
  File "/usr/local/lib/python3.10/dist-packages/xgboost/core.py", line 620, in inner_f
    return func(**kwargs)
  File "/usr/local/lib/python3.10/dist-packages/xgboost/sklearn.py", line 1490, in fit
    self._Booster = train(
  File "/usr/local/lib/python3.10/dist-packages/xgboost/core.py", line 620, in inner_f
    return func(**kwargs)
  File "/usr/local/lib/python3.10/dist-packages/xgboost/training.py", line 185, in train
    bst.update(dtrain, i, obj)
  File "/usr/local/lib/python3.10/dist-packages/xgboost/core.py", line 1918, in update
    _check_call(_LIB.XGBoosterUpdateOneIter(self.handle,
  File "/usr/local/lib/python3.10/dist-packages/xgboost/core.py", line 279, in _check_call
    raise XGBoostError(py_str(_LIB.XGBGetLastError()))
xgboost.core.XGBoostError: [20:48:52] ../src/gbm/gbtree.cc:625: Check failed: common::AllVisibleGPUs() >= 1 (0 vs. 1) : No visible GPU is found for XGBoost.
Stack trace:
  [bt] (0) /usr/local/lib/python3.10/dist-packages/xgboost/lib/libxgboost.so(+0x2a7e13) [0x7f76936a7e13]
  [bt] (1) /usr/local/lib/python3.10/dist-packages/xgboost/lib/libxgboost.so(+0x2ab120) [0x7f76936ab120]
  [bt] (2) /usr/local/lib/python3.10/dist-packages/xgboost/lib/libxgboost.so(+0x2ab52a) [0x7f76936ab52a]
  [bt] (3) /usr/local/lib/python3.10/dist-packages/xgboost/lib/libxgboost.so(+0x2e03c7) [0x7f76936e03c7]
  [bt] (4) /usr/local/lib/python3.10/dist-packages/xgboost/lib/libxgboost.so(XGBoosterUpdateOneIter+0x70) [0x7f769353c5a0]
  [bt] (5) /lib/x86_64-linux-gnu/libffi.so.8(+0x7e2e) [0x7f7708341e2e]
  [bt] (6) /lib/x86_64-linux-gnu/libffi.so.8(+0x4493) [0x7f770833e493]
  [bt] (7) /usr/lib/python3.10/lib-dynload/_ctypes.cpython-310-x86_64-linux-gnu.so(+0xa3e9) [0x7f77083673e9]
  [bt] (8) /usr/lib/python3.10/lib-dynload/_ctypes.cpython-310-x86_64-linux-gnu.so(+0x9a00) [0x7f7708366a00]



--------------------------------------------------------------------------------
3 fits failed with the following error:
Traceback (most recent call last):
  File "/usr/local/lib/python3.10/dist-packages/sklearn/model_selection/_validation.py", line 686, in _fit_and_score
    estimator.fit(X_train, y_train, **fit_params)
  File "/usr/local/lib/python3.10/dist-packages/pycaret/internal/pipeline.py", line 267, in fit
    fitted_estimator = self._memory_fit(
  File "/usr/local/lib/python3.10/dist-packages/joblib/memory.py", line 353, in __call__
    return self.func(*args, **kwargs)
  File "/usr/local/lib/python3.10/dist-packages/pycaret/internal/pipeline.py", line 66, in _fit_one
    transformer.fit(*args, **fit_params)
  File "/usr/local/lib/python3.10/dist-packages/xgboost/core.py", line 620, in inner_f
    return func(**kwargs)
  File "/usr/local/lib/python3.10/dist-packages/xgboost/sklearn.py", line 1490, in fit
    self._Booster = train(
  File "/usr/local/lib/python3.10/dist-packages/xgboost/core.py", line 620, in inner_f
    return func(**kwargs)
  File "/usr/local/lib/python3.10/dist-packages/xgboost/training.py", line 185, in train
    bst.update(dtrain, i, obj)
  File "/usr/local/lib/python3.10/dist-packages/xgboost/core.py", line 1918, in update
    _check_call(_LIB.XGBoosterUpdateOneIter(self.handle,
  File "/usr/local/lib/python3.10/dist-packages/xgboost/core.py", line 279, in _check_call
    raise XGBoostError(py_str(_LIB.XGBGetLastError()))
xgboost.core.XGBoostError: [20:48:53] ../src/gbm/gbtree.cc:625: Check failed: common::AllVisibleGPUs() >= 1 (0 vs. 1) : No visible GPU is found for XGBoost.
Stack trace:
  [bt] (0) /usr/local/lib/python3.10/dist-packages/xgboost/lib/libxgboost.so(+0x2a7e13) [0x7f76936a7e13]
  [bt] (1) /usr/local/lib/python3.10/dist-packages/xgboost/lib/libxgboost.so(+0x2ab120) [0x7f76936ab120]
  [bt] (2) /usr/local/lib/python3.10/dist-packages/xgboost/lib/libxgboost.so(+0x2ab52a) [0x7f76936ab52a]
  [bt] (3) /usr/local/lib/python3.10/dist-packages/xgboost/lib/libxgboost.so(+0x2e03c7) [0x7f76936e03c7]
  [bt] (4) /usr/local/lib/python3.10/dist-packages/xgboost/lib/libxgboost.so(XGBoosterUpdateOneIter+0x70) [0x7f769353c5a0]
  [bt] (5) /lib/x86_64-linux-gnu/libffi.so.8(+0x7e2e) [0x7f7708341e2e]
  [bt] (6) /lib/x86_64-linux-gnu/libffi.so.8(+0x4493) [0x7f770833e493]
  [bt] (7) /usr/lib/python3.10/lib-dynload/_ctypes.cpython-310-x86_64-linux-gnu.so(+0xa3e9) [0x7f77083673e9]
  [bt] (8) /usr/lib/python3.10/lib-dynload/_ctypes.cpython-310-x86_64-linux-gnu.so(+0x9a00) [0x7f7708366a00]



--------------------------------------------------------------------------------
5 fits failed with the following error:
Traceback (most recent call last):
  File "/usr/local/lib/python3.10/dist-packages/sklearn/model_selection/_validation.py", line 686, in _fit_and_score
    estimator.fit(X_train, y_train, **fit_params)
  File "/usr/local/lib/python3.10/dist-packages/pycaret/internal/pipeline.py", line 267, in fit
    fitted_estimator = self._memory_fit(
  File "/usr/local/lib/python3.10/dist-packages/joblib/memory.py", line 353, in __call__
    return self.func(*args, **kwargs)
  File "/usr/local/lib/python3.10/dist-packages/pycaret/internal/pipeline.py", line 66, in _fit_one
    transformer.fit(*args, **fit_params)
  File "/usr/local/lib/python3.10/dist-packages/xgboost/core.py", line 620, in inner_f
    return func(**kwargs)
  File "/usr/local/lib/python3.10/dist-packages/xgboost/sklearn.py", line 1490, in fit
    self._Booster = train(
  File "/usr/local/lib/python3.10/dist-packages/xgboost/core.py", line 620, in inner_f
    return func(**kwargs)
  File "/usr/local/lib/python3.10/dist-packages/xgboost/training.py", line 185, in train
    bst.update(dtrain, i, obj)
  File "/usr/local/lib/python3.10/dist-packages/xgboost/core.py", line 1918, in update
    _check_call(_LIB.XGBoosterUpdateOneIter(self.handle,
  File "/usr/local/lib/python3.10/dist-packages/xgboost/core.py", line 279, in _check_call
    raise XGBoostError(py_str(_LIB.XGBGetLastError()))
xgboost.core.XGBoostError: [20:48:54] ../src/gbm/gbtree.cc:625: Check failed: common::AllVisibleGPUs() >= 1 (0 vs. 1) : No visible GPU is found for XGBoost.
Stack trace:
  [bt] (0) /usr/local/lib/python3.10/dist-packages/xgboost/lib/libxgboost.so(+0x2a7e13) [0x7f76936a7e13]
  [bt] (1) /usr/local/lib/python3.10/dist-packages/xgboost/lib/libxgboost.so(+0x2ab120) [0x7f76936ab120]
  [bt] (2) /usr/local/lib/python3.10/dist-packages/xgboost/lib/libxgboost.so(+0x2ab52a) [0x7f76936ab52a]
  [bt] (3) /usr/local/lib/python3.10/dist-packages/xgboost/lib/libxgboost.so(+0x2e03c7) [0x7f76936e03c7]
  [bt] (4) /usr/local/lib/python3.10/dist-packages/xgboost/lib/libxgboost.so(XGBoosterUpdateOneIter+0x70) [0x7f769353c5a0]
  [bt] (5) /lib/x86_64-linux-gnu/libffi.so.8(+0x7e2e) [0x7f7708341e2e]
  [bt] (6) /lib/x86_64-linux-gnu/libffi.so.8(+0x4493) [0x7f770833e493]
  [bt] (7) /usr/lib/python3.10/lib-dynload/_ctypes.cpython-310-x86_64-linux-gnu.so(+0xa3e9) [0x7f77083673e9]
  [bt] (8) /usr/lib/python3.10/lib-dynload/_ctypes.cpython-310-x86_64-linux-gnu.so(+0x9a00) [0x7f7708366a00]



--------------------------------------------------------------------------------
1 fits failed with the following error:
Traceback (most recent call last):
  File "/usr/local/lib/python3.10/dist-packages/sklearn/model_selection/_validation.py", line 686, in _fit_and_score
    estimator.fit(X_train, y_train, **fit_params)
  File "/usr/local/lib/python3.10/dist-packages/pycaret/internal/pipeline.py", line 267, in fit
    fitted_estimator = self._memory_fit(
  File "/usr/local/lib/python3.10/dist-packages/joblib/memory.py", line 353, in __call__
    return self.func(*args, **kwargs)
  File "/usr/local/lib/python3.10/dist-packages/pycaret/internal/pipeline.py", line 66, in _fit_one
    transformer.fit(*args, **fit_params)
  File "/usr/local/lib/python3.10/dist-packages/xgboost/core.py", line 620, in inner_f
    return func(**kwargs)
  File "/usr/local/lib/python3.10/dist-packages/xgboost/sklearn.py", line 1490, in fit
    self._Booster = train(
  File "/usr/local/lib/python3.10/dist-packages/xgboost/core.py", line 620, in inner_f
    return func(**kwargs)
  File "/usr/local/lib/python3.10/dist-packages/xgboost/training.py", line 185, in train
    bst.update(dtrain, i, obj)
  File "/usr/local/lib/python3.10/dist-packages/xgboost/core.py", line 1918, in update
    _check_call(_LIB.XGBoosterUpdateOneIter(self.handle,
  File "/usr/local/lib/python3.10/dist-packages/xgboost/core.py", line 279, in _check_call
    raise XGBoostError(py_str(_LIB.XGBGetLastError()))
xgboost.core.XGBoostError: [20:48:55] ../src/gbm/gbtree.cc:625: Check failed: common::AllVisibleGPUs() >= 1 (0 vs. 1) : No visible GPU is found for XGBoost.
Stack trace:
  [bt] (0) /usr/local/lib/python3.10/dist-packages/xgboost/lib/libxgboost.so(+0x2a7e13) [0x7f76936a7e13]
  [bt] (1) /usr/local/lib/python3.10/dist-packages/xgboost/lib/libxgboost.so(+0x2ab120) [0x7f76936ab120]
  [bt] (2) /usr/local/lib/python3.10/dist-packages/xgboost/lib/libxgboost.so(+0x2ab52a) [0x7f76936ab52a]
  [bt] (3) /usr/local/lib/python3.10/dist-packages/xgboost/lib/libxgboost.so(+0x2e03c7) [0x7f76936e03c7]
  [bt] (4) /usr/local/lib/python3.10/dist-packages/xgboost/lib/libxgboost.so(XGBoosterUpdateOneIter+0x70) [0x7f769353c5a0]
  [bt] (5) /lib/x86_64-linux-gnu/libffi.so.8(+0x7e2e) [0x7f7708341e2e]
  [bt] (6) /lib/x86_64-linux-gnu/libffi.so.8(+0x4493) [0x7f770833e493]
  [bt] (7) /usr/lib/python3.10/lib-dynload/_ctypes.cpython-310-x86_64-linux-gnu.so(+0xa3e9) [0x7f77083673e9]
  [bt] (8) /usr/lib/python3.10/lib-dynload/_ctypes.cpython-310-x86_64-linux-gnu.so(+0x9a00) [0x7f7708366a00]




During handling of the above exception, another exception occurred:

Traceback (most recent call last):
  File "/usr/local/lib/python3.10/dist-packages/pycaret/internal/pycaret_experiment/supervised_experiment.py", line 812, in compare_models
    model, model_fit_time = self._create_model(**create_model_args)
  File "/usr/local/lib/python3.10/dist-packages/pycaret/internal/pycaret_experiment/supervised_experiment.py", line 1527, in _create_model
    model, model_fit_time, model_results, _ = self._create_model_with_cv(
  File "/usr/local/lib/python3.10/dist-packages/pycaret/internal/pycaret_experiment/supervised_experiment.py", line 1121, in _create_model_with_cv
    scores = cross_validate(
  File "/usr/local/lib/python3.10/dist-packages/sklearn/model_selection/_validation.py", line 285, in cross_validate
    _warn_or_raise_about_fit_failures(results, error_score)
  File "/usr/local/lib/python3.10/dist-packages/sklearn/model_selection/_validation.py", line 367, in _warn_or_raise_about_fit_failures
    raise ValueError(all_fits_failed_message)
ValueError: 
All the 10 fits failed.
It is very likely that your model is misconfigured.
You can try to debug the error by setting error_score='raise'.

Below are more details about the failures:
--------------------------------------------------------------------------------
4 fits failed with the following error:
Traceback (most recent call last):
  File "/usr/local/lib/python3.10/dist-packages/pycaret/internal/pycaret_experiment/supervised_experiment.py", line 796, in compare_models
    model, model_fit_time = self._create_model(**create_model_args)
  File "/usr/local/lib/python3.10/dist-packages/pycaret/internal/pycaret_experiment/supervised_experiment.py", line 1527, in _create_model
    model, model_fit_time, model_results, _ = self._create_model_with_cv(
  File "/usr/local/lib/python3.10/dist-packages/pycaret/internal/pycaret_experiment/supervised_experiment.py", line 1121, in _create_model_with_cv
    scores = cross_validate(
  File "/usr/local/lib/python3.10/dist-packages/sklearn/model_selection/_validation.py", line 285, in cross_validate
    _warn_or_raise_about_fit_failures(results, error_score)
  File "/usr/local/lib/python3.10/dist-packages/sklearn/model_selection/_validation.py", line 367, in _warn_or_raise_about_fit_failures
    raise ValueError(all_fits_failed_message)
ValueError: 
All the 10 fits failed.
It is very likely that your model is misconfigured.
You can try to debug the error by setting error_score='raise'.

Below are more details about the failures:
--------------------------------------------------------------------------------
1 fits failed with the following error:
Traceback (most recent call last):
  File "/usr/local/lib/python3.10/dist-packages/sklearn/model_selection/_validation.py", line 686, in _fit_and_score
    estimator.fit(X_train, y_train, **fit_params)
  File "/usr/local/lib/python3.10/dist-packages/pycaret/internal/pipeline.py", line 267, in fit
    fitted_estimator = self._memory_fit(
  File "/usr/local/lib/python3.10/dist-packages/joblib/memory.py", line 353, in __call__
    return self.func(*args, **kwargs)
  File "/usr/local/lib/python3.10/dist-packages/pycaret/internal/pipeline.py", line 66, in _fit_one
    transformer.fit(*args, **fit_params)
  File "/usr/local/lib/python3.10/dist-packages/xgboost/core.py", line 620, in inner_f
    return func(**kwargs)
  File "/usr/local/lib/python3.10/dist-packages/xgboost/sklearn.py", line 1490, in fit
    self._Booster = train(
  File "/usr/local/lib/python3.10/dist-packages/xgboost/core.py", line 620, in inner_f
    return func(**kwargs)
  File "/usr/local/lib/python3.10/dist-packages/xgboost/training.py", line 185, in train
    bst.update(dtrain, i, obj)
  File "/usr/local/lib/python3.10/dist-packages/xgboost/core.py", line 1918, in update
    _check_call(_LIB.XGBoosterUpdateOneIter(self.handle,
  File "/usr/local/lib/python3.10/dist-packages/xgboost/core.py", line 279, in _check_call
    raise XGBoostError(py_str(_LIB.XGBGetLastError()))
xgboost.core.XGBoostError: [20:48:52] ../src/gbm/gbtree.cc:625: Check failed: common::AllVisibleGPUs() >= 1 (0 vs. 1) : No visible GPU is found for XGBoost.
Stack trace:
  [bt] (0) /usr/local/lib/python3.10/dist-packages/xgboost/lib/libxgboost.so(+0x2a7e13) [0x7f76936a7e13]
  [bt] (1) /usr/local/lib/python3.10/dist-packages/xgboost/lib/libxgboost.so(+0x2ab120) [0x7f76936ab120]
  [bt] (2) /usr/local/lib/python3.10/dist-packages/xgboost/lib/libxgboost.so(+0x2ab52a) [0x7f76936ab52a]
  [bt] (3) /usr/local/lib/python3.10/dist-packages/xgboost/lib/libxgboost.so(+0x2e03c7) [0x7f76936e03c7]
  [bt] (4) /usr/local/lib/python3.10/dist-packages/xgboost/lib/libxgboost.so(XGBoosterUpdateOneIter+0x70) [0x7f769353c5a0]
  [bt] (5) /lib/x86_64-linux-gnu/libffi.so.8(+0x7e2e) [0x7f7708341e2e]
  [bt] (6) /lib/x86_64-linux-gnu/libffi.so.8(+0x4493) [0x7f770833e493]
  [bt] (7) /usr/lib/python3.10/lib-dynload/_ctypes.cpython-310-x86_64-linux-gnu.so(+0xa3e9) [0x7f77083673e9]
  [bt] (8) /usr/lib/python3.10/lib-dynload/_ctypes.cpython-310-x86_64-linux-gnu.so(+0x9a00) [0x7f7708366a00]



--------------------------------------------------------------------------------
3 fits failed with the following error:
Traceback (most recent call last):
  File "/usr/local/lib/python3.10/dist-packages/sklearn/model_selection/_validation.py", line 686, in _fit_and_score
    estimator.fit(X_train, y_train, **fit_params)
  File "/usr/local/lib/python3.10/dist-packages/pycaret/internal/pipeline.py", line 267, in fit
    fitted_estimator = self._memory_fit(
  File "/usr/local/lib/python3.10/dist-packages/joblib/memory.py", line 353, in __call__
    return self.func(*args, **kwargs)
  File "/usr/local/lib/python3.10/dist-packages/pycaret/internal/pipeline.py", line 66, in _fit_one
    transformer.fit(*args, **fit_params)
  File "/usr/local/lib/python3.10/dist-packages/xgboost/core.py", line 620, in inner_f
    return func(**kwargs)
  File "/usr/local/lib/python3.10/dist-packages/xgboost/sklearn.py", line 1490, in fit
    self._Booster = train(
  File "/usr/local/lib/python3.10/dist-packages/xgboost/core.py", line 620, in inner_f
    return func(**kwargs)
  File "/usr/local/lib/python3.10/dist-packages/xgboost/training.py", line 185, in train
    bst.update(dtrain, i, obj)
  File "/usr/local/lib/python3.10/dist-packages/xgboost/core.py", line 1918, in update
    _check_call(_LIB.XGBoosterUpdateOneIter(self.handle,
  File "/usr/local/lib/python3.10/dist-packages/xgboost/core.py", line 279, in _check_call
    raise XGBoostError(py_str(_LIB.XGBGetLastError()))
xgboost.core.XGBoostError: [20:48:53] ../src/gbm/gbtree.cc:625: Check failed: common::AllVisibleGPUs() >= 1 (0 vs. 1) : No visible GPU is found for XGBoost.
Stack trace:
  [bt] (0) /usr/local/lib/python3.10/dist-packages/xgboost/lib/libxgboost.so(+0x2a7e13) [0x7f76936a7e13]
  [bt] (1) /usr/local/lib/python3.10/dist-packages/xgboost/lib/libxgboost.so(+0x2ab120) [0x7f76936ab120]
  [bt] (2) /usr/local/lib/python3.10/dist-packages/xgboost/lib/libxgboost.so(+0x2ab52a) [0x7f76936ab52a]
  [bt] (3) /usr/local/lib/python3.10/dist-packages/xgboost/lib/libxgboost.so(+0x2e03c7) [0x7f76936e03c7]
  [bt] (4) /usr/local/lib/python3.10/dist-packages/xgboost/lib/libxgboost.so(XGBoosterUpdateOneIter+0x70) [0x7f769353c5a0]
  [bt] (5) /lib/x86_64-linux-gnu/libffi.so.8(+0x7e2e) [0x7f7708341e2e]
  [bt] (6) /lib/x86_64-linux-gnu/libffi.so.8(+0x4493) [0x7f770833e493]
  [bt] (7) /usr/lib/python3.10/lib-dynload/_ctypes.cpython-310-x86_64-linux-gnu.so(+0xa3e9) [0x7f77083673e9]
  [bt] (8) /usr/lib/python3.10/lib-dynload/_ctypes.cpython-310-x86_64-linux-gnu.so(+0x9a00) [0x7f7708366a00]



--------------------------------------------------------------------------------
5 fits failed with the following error:
Traceback (most recent call last):
  File "/usr/local/lib/python3.10/dist-packages/sklearn/model_selection/_validation.py", line 686, in _fit_and_score
    estimator.fit(X_train, y_train, **fit_params)
  File "/usr/local/lib/python3.10/dist-packages/pycaret/internal/pipeline.py", line 267, in fit
    fitted_estimator = self._memory_fit(
  File "/usr/local/lib/python3.10/dist-packages/joblib/memory.py", line 353, in __call__
    return self.func(*args, **kwargs)
  File "/usr/local/lib/python3.10/dist-packages/pycaret/internal/pipeline.py", line 66, in _fit_one
    transformer.fit(*args, **fit_params)
  File "/usr/local/lib/python3.10/dist-packages/xgboost/core.py", line 620, in inner_f
    return func(**kwargs)
  File "/usr/local/lib/python3.10/dist-packages/xgboost/sklearn.py", line 1490, in fit
    self._Booster = train(
  File "/usr/local/lib/python3.10/dist-packages/xgboost/core.py", line 620, in inner_f
    return func(**kwargs)
  File "/usr/local/lib/python3.10/dist-packages/xgboost/training.py", line 185, in train
    bst.update(dtrain, i, obj)
  File "/usr/local/lib/python3.10/dist-packages/xgboost/core.py", line 1918, in update
    _check_call(_LIB.XGBoosterUpdateOneIter(self.handle,
  File "/usr/local/lib/python3.10/dist-packages/xgboost/core.py", line 279, in _check_call
    raise XGBoostError(py_str(_LIB.XGBGetLastError()))
xgboost.core.XGBoostError: [20:48:54] ../src/gbm/gbtree.cc:625: Check failed: common::AllVisibleGPUs() >= 1 (0 vs. 1) : No visible GPU is found for XGBoost.
Stack trace:
  [bt] (0) /usr/local/lib/python3.10/dist-packages/xgboost/lib/libxgboost.so(+0x2a7e13) [0x7f76936a7e13]
  [bt] (1) /usr/local/lib/python3.10/dist-packages/xgboost/lib/libxgboost.so(+0x2ab120) [0x7f76936ab120]
  [bt] (2) /usr/local/lib/python3.10/dist-packages/xgboost/lib/libxgboost.so(+0x2ab52a) [0x7f76936ab52a]
  [bt] (3) /usr/local/lib/python3.10/dist-packages/xgboost/lib/libxgboost.so(+0x2e03c7) [0x7f76936e03c7]
  [bt] (4) /usr/local/lib/python3.10/dist-packages/xgboost/lib/libxgboost.so(XGBoosterUpdateOneIter+0x70) [0x7f769353c5a0]
  [bt] (5) /lib/x86_64-linux-gnu/libffi.so.8(+0x7e2e) [0x7f7708341e2e]
  [bt] (6) /lib/x86_64-linux-gnu/libffi.so.8(+0x4493) [0x7f770833e493]
  [bt] (7) /usr/lib/python3.10/lib-dynload/_ctypes.cpython-310-x86_64-linux-gnu.so(+0xa3e9) [0x7f77083673e9]
  [bt] (8) /usr/lib/python3.10/lib-dynload/_ctypes.cpython-310-x86_64-linux-gnu.so(+0x9a00) [0x7f7708366a00]



--------------------------------------------------------------------------------
1 fits failed with the following error:
Traceback (most recent call last):
  File "/usr/local/lib/python3.10/dist-packages/sklearn/model_selection/_validation.py", line 686, in _fit_and_score
    estimator.fit(X_train, y_train, **fit_params)
  File "/usr/local/lib/python3.10/dist-packages/pycaret/internal/pipeline.py", line 267, in fit
    fitted_estimator = self._memory_fit(
  File "/usr/local/lib/python3.10/dist-packages/joblib/memory.py", line 353, in __call__
    return self.func(*args, **kwargs)
  File "/usr/local/lib/python3.10/dist-packages/pycaret/internal/pipeline.py", line 66, in _fit_one
    transformer.fit(*args, **fit_params)
  File "/usr/local/lib/python3.10/dist-packages/xgboost/core.py", line 620, in inner_f
    return func(**kwargs)
  File "/usr/local/lib/python3.10/dist-packages/xgboost/sklearn.py", line 1490, in fit
    self._Booster = train(
  File "/usr/local/lib/python3.10/dist-packages/xgboost/core.py", line 620, in inner_f
    return func(**kwargs)
  File "/usr/local/lib/python3.10/dist-packages/xgboost/training.py", line 185, in train
    bst.update(dtrain, i, obj)
  File "/usr/local/lib/python3.10/dist-packages/xgboost/core.py", line 1918, in update
    _check_call(_LIB.XGBoosterUpdateOneIter(self.handle,
  File "/usr/local/lib/python3.10/dist-packages/xgboost/core.py", line 279, in _check_call
    raise XGBoostError(py_str(_LIB.XGBGetLastError()))
xgboost.core.XGBoostError: [20:48:55] ../src/gbm/gbtree.cc:625: Check failed: common::AllVisibleGPUs() >= 1 (0 vs. 1) : No visible GPU is found for XGBoost.
Stack trace:
  [bt] (0) /usr/local/lib/python3.10/dist-packages/xgboost/lib/libxgboost.so(+0x2a7e13) [0x7f76936a7e13]
  [bt] (1) /usr/local/lib/python3.10/dist-packages/xgboost/lib/libxgboost.so(+0x2ab120) [0x7f76936ab120]
  [bt] (2) /usr/local/lib/python3.10/dist-packages/xgboost/lib/libxgboost.so(+0x2ab52a) [0x7f76936ab52a]
  [bt] (3) /usr/local/lib/python3.10/dist-packages/xgboost/lib/libxgboost.so(+0x2e03c7) [0x7f76936e03c7]
  [bt] (4) /usr/local/lib/python3.10/dist-packages/xgboost/lib/libxgboost.so(XGBoosterUpdateOneIter+0x70) [0x7f769353c5a0]
  [bt] (5) /lib/x86_64-linux-gnu/libffi.so.8(+0x7e2e) [0x7f7708341e2e]
  [bt] (6) /lib/x86_64-linux-gnu/libffi.so.8(+0x4493) [0x7f770833e493]
  [bt] (7) /usr/lib/python3.10/lib-dynload/_ctypes.cpython-310-x86_64-linux-gnu.so(+0xa3e9) [0x7f77083673e9]
  [bt] (8) /usr/lib/python3.10/lib-dynload/_ctypes.cpython-310-x86_64-linux-gnu.so(+0x9a00) [0x7f7708366a00]




During handling of the above exception, another exception occurred:

Traceback (most recent call last):
  File "/usr/local/lib/python3.10/dist-packages/sklearn/model_selection/_validation.py", line 686, in _fit_and_score
    estimator.fit(X_train, y_train, **fit_params)
  File "/usr/local/lib/python3.10/dist-packages/pycaret/internal/pipeline.py", line 267, in fit
    fitted_estimator = self._memory_fit(
  File "/usr/local/lib/python3.10/dist-packages/joblib/memory.py", line 353, in __call__
    return self.func(*args, **kwargs)
  File "/usr/local/lib/python3.10/dist-packages/pycaret/internal/pipeline.py", line 66, in _fit_one
    transformer.fit(*args, **fit_params)
  File "/usr/local/lib/python3.10/dist-packages/xgboost/core.py", line 620, in inner_f
    return func(**kwargs)
  File "/usr/local/lib/python3.10/dist-packages/xgboost/sklearn.py", line 1490, in fit
    self._Booster = train(
  File "/usr/local/lib/python3.10/dist-packages/xgboost/core.py", line 620, in inner_f
    return func(**kwargs)
  File "/usr/local/lib/python3.10/dist-packages/xgboost/training.py", line 185, in train
    bst.update(dtrain, i, obj)
  File "/usr/local/lib/python3.10/dist-packages/xgboost/core.py", line 1918, in update
    _check_call(_LIB.XGBoosterUpdateOneIter(self.handle,
  File "/usr/local/lib/python3.10/dist-packages/xgboost/core.py", line 279, in _check_call
    raise XGBoostError(py_str(_LIB.XGBGetLastError()))
xgboost.core.XGBoostError: [20:48:55] ../src/gbm/gbtree.cc:625: Check failed: common::AllVisibleGPUs() >= 1 (0 vs. 1) : No visible GPU is found for XGBoost.
Stack trace:
  [bt] (0) /usr/local/lib/python3.10/dist-packages/xgboost/lib/libxgboost.so(+0x2a7e13) [0x7f76936a7e13]
  [bt] (1) /usr/local/lib/python3.10/dist-packages/xgboost/lib/libxgboost.so(+0x2ab120) [0x7f76936ab120]
  [bt] (2) /usr/local/lib/python3.10/dist-packages/xgboost/lib/libxgboost.so(+0x2ab52a) [0x7f76936ab52a]
  [bt] (3) /usr/local/lib/python3.10/dist-packages/xgboost/lib/libxgboost.so(+0x2e03c7) [0x7f76936e03c7]
  [bt] (4) /usr/local/lib/python3.10/dist-packages/xgboost/lib/libxgboost.so(XGBoosterUpdateOneIter+0x70) [0x7f769353c5a0]
  [bt] (5) /lib/x86_64-linux-gnu/libffi.so.8(+0x7e2e) [0x7f7708341e2e]
  [bt] (6) /lib/x86_64-linux-gnu/libffi.so.8(+0x4493) [0x7f770833e493]
  [bt] (7) /usr/lib/python3.10/lib-dynload/_ctypes.cpython-310-x86_64-linux-gnu.so(+0xa3e9) [0x7f77083673e9]
  [bt] (8) /usr/lib/python3.10/lib-dynload/_ctypes.cpython-310-x86_64-linux-gnu.so(+0x9a00) [0x7f7708366a00]



--------------------------------------------------------------------------------
5 fits failed with the following error:
Traceback (most recent call last):
  File "/usr/local/lib/python3.10/dist-packages/pycaret/internal/pycaret_experiment/supervised_experiment.py", line 796, in compare_models
    model, model_fit_time = self._create_model(**create_model_args)
  File "/usr/local/lib/python3.10/dist-packages/pycaret/internal/pycaret_experiment/supervised_experiment.py", line 1527, in _create_model
    model, model_fit_time, model_results, _ = self._create_model_with_cv(
  File "/usr/local/lib/python3.10/dist-packages/pycaret/internal/pycaret_experiment/supervised_experiment.py", line 1121, in _create_model_with_cv
    scores = cross_validate(
  File "/usr/local/lib/python3.10/dist-packages/sklearn/model_selection/_validation.py", line 285, in cross_validate
    _warn_or_raise_about_fit_failures(results, error_score)
  File "/usr/local/lib/python3.10/dist-packages/sklearn/model_selection/_validation.py", line 367, in _warn_or_raise_about_fit_failures
    raise ValueError(all_fits_failed_message)
ValueError: 
All the 10 fits failed.
It is very likely that your model is misconfigured.
You can try to debug the error by setting error_score='raise'.

Below are more details about the failures:
--------------------------------------------------------------------------------
1 fits failed with the following error:
Traceback (most recent call last):
  File "/usr/local/lib/python3.10/dist-packages/sklearn/model_selection/_validation.py", line 686, in _fit_and_score
    estimator.fit(X_train, y_train, **fit_params)
  File "/usr/local/lib/python3.10/dist-packages/pycaret/internal/pipeline.py", line 267, in fit
    fitted_estimator = self._memory_fit(
  File "/usr/local/lib/python3.10/dist-packages/joblib/memory.py", line 353, in __call__
    return self.func(*args, **kwargs)
  File "/usr/local/lib/python3.10/dist-packages/pycaret/internal/pipeline.py", line 66, in _fit_one
    transformer.fit(*args, **fit_params)
  File "/usr/local/lib/python3.10/dist-packages/xgboost/core.py", line 620, in inner_f
    return func(**kwargs)
  File "/usr/local/lib/python3.10/dist-packages/xgboost/sklearn.py", line 1490, in fit
    self._Booster = train(
  File "/usr/local/lib/python3.10/dist-packages/xgboost/core.py", line 620, in inner_f
    return func(**kwargs)
  File "/usr/local/lib/python3.10/dist-packages/xgboost/training.py", line 185, in train
    bst.update(dtrain, i, obj)
  File "/usr/local/lib/python3.10/dist-packages/xgboost/core.py", line 1918, in update
    _check_call(_LIB.XGBoosterUpdateOneIter(self.handle,
  File "/usr/local/lib/python3.10/dist-packages/xgboost/core.py", line 279, in _check_call
    raise XGBoostError(py_str(_LIB.XGBGetLastError()))
xgboost.core.XGBoostError: [20:48:52] ../src/gbm/gbtree.cc:625: Check failed: common::AllVisibleGPUs() >= 1 (0 vs. 1) : No visible GPU is found for XGBoost.
Stack trace:
  [bt] (0) /usr/local/lib/python3.10/dist-packages/xgboost/lib/libxgboost.so(+0x2a7e13) [0x7f76936a7e13]
  [bt] (1) /usr/local/lib/python3.10/dist-packages/xgboost/lib/libxgboost.so(+0x2ab120) [0x7f76936ab120]
  [bt] (2) /usr/local/lib/python3.10/dist-packages/xgboost/lib/libxgboost.so(+0x2ab52a) [0x7f76936ab52a]
  [bt] (3) /usr/local/lib/python3.10/dist-packages/xgboost/lib/libxgboost.so(+0x2e03c7) [0x7f76936e03c7]
  [bt] (4) /usr/local/lib/python3.10/dist-packages/xgboost/lib/libxgboost.so(XGBoosterUpdateOneIter+0x70) [0x7f769353c5a0]
  [bt] (5) /lib/x86_64-linux-gnu/libffi.so.8(+0x7e2e) [0x7f7708341e2e]
  [bt] (6) /lib/x86_64-linux-gnu/libffi.so.8(+0x4493) [0x7f770833e493]
  [bt] (7) /usr/lib/python3.10/lib-dynload/_ctypes.cpython-310-x86_64-linux-gnu.so(+0xa3e9) [0x7f77083673e9]
  [bt] (8) /usr/lib/python3.10/lib-dynload/_ctypes.cpython-310-x86_64-linux-gnu.so(+0x9a00) [0x7f7708366a00]



--------------------------------------------------------------------------------
3 fits failed with the following error:
Traceback (most recent call last):
  File "/usr/local/lib/python3.10/dist-packages/sklearn/model_selection/_validation.py", line 686, in _fit_and_score
    estimator.fit(X_train, y_train, **fit_params)
  File "/usr/local/lib/python3.10/dist-packages/pycaret/internal/pipeline.py", line 267, in fit
    fitted_estimator = self._memory_fit(
  File "/usr/local/lib/python3.10/dist-packages/joblib/memory.py", line 353, in __call__
    return self.func(*args, **kwargs)
  File "/usr/local/lib/python3.10/dist-packages/pycaret/internal/pipeline.py", line 66, in _fit_one
    transformer.fit(*args, **fit_params)
  File "/usr/local/lib/python3.10/dist-packages/xgboost/core.py", line 620, in inner_f
    return func(**kwargs)
  File "/usr/local/lib/python3.10/dist-packages/xgboost/sklearn.py", line 1490, in fit
    self._Booster = train(
  File "/usr/local/lib/python3.10/dist-packages/xgboost/core.py", line 620, in inner_f
    return func(**kwargs)
  File "/usr/local/lib/python3.10/dist-packages/xgboost/training.py", line 185, in train
    bst.update(dtrain, i, obj)
  File "/usr/local/lib/python3.10/dist-packages/xgboost/core.py", line 1918, in update
    _check_call(_LIB.XGBoosterUpdateOneIter(self.handle,
  File "/usr/local/lib/python3.10/dist-packages/xgboost/core.py", line 279, in _check_call
    raise XGBoostError(py_str(_LIB.XGBGetLastError()))
xgboost.core.XGBoostError: [20:48:53] ../src/gbm/gbtree.cc:625: Check failed: common::AllVisibleGPUs() >= 1 (0 vs. 1) : No visible GPU is found for XGBoost.
Stack trace:
  [bt] (0) /usr/local/lib/python3.10/dist-packages/xgboost/lib/libxgboost.so(+0x2a7e13) [0x7f76936a7e13]
  [bt] (1) /usr/local/lib/python3.10/dist-packages/xgboost/lib/libxgboost.so(+0x2ab120) [0x7f76936ab120]
  [bt] (2) /usr/local/lib/python3.10/dist-packages/xgboost/lib/libxgboost.so(+0x2ab52a) [0x7f76936ab52a]
  [bt] (3) /usr/local/lib/python3.10/dist-packages/xgboost/lib/libxgboost.so(+0x2e03c7) [0x7f76936e03c7]
  [bt] (4) /usr/local/lib/python3.10/dist-packages/xgboost/lib/libxgboost.so(XGBoosterUpdateOneIter+0x70) [0x7f769353c5a0]
  [bt] (5) /lib/x86_64-linux-gnu/libffi.so.8(+0x7e2e) [0x7f7708341e2e]
  [bt] (6) /lib/x86_64-linux-gnu/libffi.so.8(+0x4493) [0x7f770833e493]
  [bt] (7) /usr/lib/python3.10/lib-dynload/_ctypes.cpython-310-x86_64-linux-gnu.so(+0xa3e9) [0x7f77083673e9]
  [bt] (8) /usr/lib/python3.10/lib-dynload/_ctypes.cpython-310-x86_64-linux-gnu.so(+0x9a00) [0x7f7708366a00]



--------------------------------------------------------------------------------
5 fits failed with the following error:
Traceback (most recent call last):
  File "/usr/local/lib/python3.10/dist-packages/sklearn/model_selection/_validation.py", line 686, in _fit_and_score
    estimator.fit(X_train, y_train, **fit_params)
  File "/usr/local/lib/python3.10/dist-packages/pycaret/internal/pipeline.py", line 267, in fit
    fitted_estimator = self._memory_fit(
  File "/usr/local/lib/python3.10/dist-packages/joblib/memory.py", line 353, in __call__
    return self.func(*args, **kwargs)
  File "/usr/local/lib/python3.10/dist-packages/pycaret/internal/pipeline.py", line 66, in _fit_one
    transformer.fit(*args, **fit_params)
  File "/usr/local/lib/python3.10/dist-packages/xgboost/core.py", line 620, in inner_f
    return func(**kwargs)
  File "/usr/local/lib/python3.10/dist-packages/xgboost/sklearn.py", line 1490, in fit
    self._Booster = train(
  File "/usr/local/lib/python3.10/dist-packages/xgboost/core.py", line 620, in inner_f
    return func(**kwargs)
  File "/usr/local/lib/python3.10/dist-packages/xgboost/training.py", line 185, in train
    bst.update(dtrain, i, obj)
  File "/usr/local/lib/python3.10/dist-packages/xgboost/core.py", line 1918, in update
    _check_call(_LIB.XGBoosterUpdateOneIter(self.handle,
  File "/usr/local/lib/python3.10/dist-packages/xgboost/core.py", line 279, in _check_call
    raise XGBoostError(py_str(_LIB.XGBGetLastError()))
xgboost.core.XGBoostError: [20:48:54] ../src/gbm/gbtree.cc:625: Check failed: common::AllVisibleGPUs() >= 1 (0 vs. 1) : No visible GPU is found for XGBoost.
Stack trace:
  [bt] (0) /usr/local/lib/python3.10/dist-packages/xgboost/lib/libxgboost.so(+0x2a7e13) [0x7f76936a7e13]
  [bt] (1) /usr/local/lib/python3.10/dist-packages/xgboost/lib/libxgboost.so(+0x2ab120) [0x7f76936ab120]
  [bt] (2) /usr/local/lib/python3.10/dist-packages/xgboost/lib/libxgboost.so(+0x2ab52a) [0x7f76936ab52a]
  [bt] (3) /usr/local/lib/python3.10/dist-packages/xgboost/lib/libxgboost.so(+0x2e03c7) [0x7f76936e03c7]
  [bt] (4) /usr/local/lib/python3.10/dist-packages/xgboost/lib/libxgboost.so(XGBoosterUpdateOneIter+0x70) [0x7f769353c5a0]
  [bt] (5) /lib/x86_64-linux-gnu/libffi.so.8(+0x7e2e) [0x7f7708341e2e]
  [bt] (6) /lib/x86_64-linux-gnu/libffi.so.8(+0x4493) [0x7f770833e493]
  [bt] (7) /usr/lib/python3.10/lib-dynload/_ctypes.cpython-310-x86_64-linux-gnu.so(+0xa3e9) [0x7f77083673e9]
  [bt] (8) /usr/lib/python3.10/lib-dynload/_ctypes.cpython-310-x86_64-linux-gnu.so(+0x9a00) [0x7f7708366a00]



--------------------------------------------------------------------------------
1 fits failed with the following error:
Traceback (most recent call last):
  File "/usr/local/lib/python3.10/dist-packages/sklearn/model_selection/_validation.py", line 686, in _fit_and_score
    estimator.fit(X_train, y_train, **fit_params)
  File "/usr/local/lib/python3.10/dist-packages/pycaret/internal/pipeline.py", line 267, in fit
    fitted_estimator = self._memory_fit(
  File "/usr/local/lib/python3.10/dist-packages/joblib/memory.py", line 353, in __call__
    return self.func(*args, **kwargs)
  File "/usr/local/lib/python3.10/dist-packages/pycaret/internal/pipeline.py", line 66, in _fit_one
    transformer.fit(*args, **fit_params)
  File "/usr/local/lib/python3.10/dist-packages/xgboost/core.py", line 620, in inner_f
    return func(**kwargs)
  File "/usr/local/lib/python3.10/dist-packages/xgboost/sklearn.py", line 1490, in fit
    self._Booster = train(
  File "/usr/local/lib/python3.10/dist-packages/xgboost/core.py", line 620, in inner_f
    return func(**kwargs)
  File "/usr/local/lib/python3.10/dist-packages/xgboost/training.py", line 185, in train
    bst.update(dtrain, i, obj)
  File "/usr/local/lib/python3.10/dist-packages/xgboost/core.py", line 1918, in update
    _check_call(_LIB.XGBoosterUpdateOneIter(self.handle,
  File "/usr/local/lib/python3.10/dist-packages/xgboost/core.py", line 279, in _check_call
    raise XGBoostError(py_str(_LIB.XGBGetLastError()))
xgboost.core.XGBoostError: [20:48:55] ../src/gbm/gbtree.cc:625: Check failed: common::AllVisibleGPUs() >= 1 (0 vs. 1) : No visible GPU is found for XGBoost.
Stack trace:
  [bt] (0) /usr/local/lib/python3.10/dist-packages/xgboost/lib/libxgboost.so(+0x2a7e13) [0x7f76936a7e13]
  [bt] (1) /usr/local/lib/python3.10/dist-packages/xgboost/lib/libxgboost.so(+0x2ab120) [0x7f76936ab120]
  [bt] (2) /usr/local/lib/python3.10/dist-packages/xgboost/lib/libxgboost.so(+0x2ab52a) [0x7f76936ab52a]
  [bt] (3) /usr/local/lib/python3.10/dist-packages/xgboost/lib/libxgboost.so(+0x2e03c7) [0x7f76936e03c7]
  [bt] (4) /usr/local/lib/python3.10/dist-packages/xgboost/lib/libxgboost.so(XGBoosterUpdateOneIter+0x70) [0x7f769353c5a0]
  [bt] (5) /lib/x86_64-linux-gnu/libffi.so.8(+0x7e2e) [0x7f7708341e2e]
  [bt] (6) /lib/x86_64-linux-gnu/libffi.so.8(+0x4493) [0x7f770833e493]
  [bt] (7) /usr/lib/python3.10/lib-dynload/_ctypes.cpython-310-x86_64-linux-gnu.so(+0xa3e9) [0x7f77083673e9]
  [bt] (8) /usr/lib/python3.10/lib-dynload/_ctypes.cpython-310-x86_64-linux-gnu.so(+0x9a00) [0x7f7708366a00]




During handling of the above exception, another exception occurred:

Traceback (most recent call last):
  File "/usr/local/lib/python3.10/dist-packages/sklearn/model_selection/_validation.py", line 686, in _fit_and_score
    estimator.fit(X_train, y_train, **fit_params)
  File "/usr/local/lib/python3.10/dist-packages/pycaret/internal/pipeline.py", line 267, in fit
    fitted_estimator = self._memory_fit(
  File "/usr/local/lib/python3.10/dist-packages/joblib/memory.py", line 353, in __call__
    return self.func(*args, **kwargs)
  File "/usr/local/lib/python3.10/dist-packages/pycaret/internal/pipeline.py", line 66, in _fit_one
    transformer.fit(*args, **fit_params)
  File "/usr/local/lib/python3.10/dist-packages/xgboost/core.py", line 620, in inner_f
    return func(**kwargs)
  File "/usr/local/lib/python3.10/dist-packages/xgboost/sklearn.py", line 1490, in fit
    self._Booster = train(
  File "/usr/local/lib/python3.10/dist-packages/xgboost/core.py", line 620, in inner_f
    return func(**kwargs)
  File "/usr/local/lib/python3.10/dist-packages/xgboost/training.py", line 185, in train
    bst.update(dtrain, i, obj)
  File "/usr/local/lib/python3.10/dist-packages/xgboost/core.py", line 1918, in update
    _check_call(_LIB.XGBoosterUpdateOneIter(self.handle,
  File "/usr/local/lib/python3.10/dist-packages/xgboost/core.py", line 279, in _check_call
    raise XGBoostError(py_str(_LIB.XGBGetLastError()))
xgboost.core.XGBoostError: [20:48:56] ../src/gbm/gbtree.cc:625: Check failed: common::AllVisibleGPUs() >= 1 (0 vs. 1) : No visible GPU is found for XGBoost.
Stack trace:
  [bt] (0) /usr/local/lib/python3.10/dist-packages/xgboost/lib/libxgboost.so(+0x2a7e13) [0x7f76936a7e13]
  [bt] (1) /usr/local/lib/python3.10/dist-packages/xgboost/lib/libxgboost.so(+0x2ab120) [0x7f76936ab120]
  [bt] (2) /usr/local/lib/python3.10/dist-packages/xgboost/lib/libxgboost.so(+0x2ab52a) [0x7f76936ab52a]
  [bt] (3) /usr/local/lib/python3.10/dist-packages/xgboost/lib/libxgboost.so(+0x2e03c7) [0x7f76936e03c7]
  [bt] (4) /usr/local/lib/python3.10/dist-packages/xgboost/lib/libxgboost.so(XGBoosterUpdateOneIter+0x70) [0x7f769353c5a0]
  [bt] (5) /lib/x86_64-linux-gnu/libffi.so.8(+0x7e2e) [0x7f7708341e2e]
  [bt] (6) /lib/x86_64-linux-gnu/libffi.so.8(+0x4493) [0x7f770833e493]
  [bt] (7) /usr/lib/python3.10/lib-dynload/_ctypes.cpython-310-x86_64-linux-gnu.so(+0xa3e9) [0x7f77083673e9]
  [bt] (8) /usr/lib/python3.10/lib-dynload/_ctypes.cpython-310-x86_64-linux-gnu.so(+0x9a00) [0x7f7708366a00]



--------------------------------------------------------------------------------
1 fits failed with the following error:
Traceback (most recent call last):
  File "/usr/local/lib/python3.10/dist-packages/pycaret/internal/pycaret_experiment/supervised_experiment.py", line 796, in compare_models
    model, model_fit_time = self._create_model(**create_model_args)
  File "/usr/local/lib/python3.10/dist-packages/pycaret/internal/pycaret_experiment/supervised_experiment.py", line 1527, in _create_model
    model, model_fit_time, model_results, _ = self._create_model_with_cv(
  File "/usr/local/lib/python3.10/dist-packages/pycaret/internal/pycaret_experiment/supervised_experiment.py", line 1121, in _create_model_with_cv
    scores = cross_validate(
  File "/usr/local/lib/python3.10/dist-packages/sklearn/model_selection/_validation.py", line 285, in cross_validate
    _warn_or_raise_about_fit_failures(results, error_score)
  File "/usr/local/lib/python3.10/dist-packages/sklearn/model_selection/_validation.py", line 367, in _warn_or_raise_about_fit_failures
    raise ValueError(all_fits_failed_message)
ValueError: 
All the 10 fits failed.
It is very likely that your model is misconfigured.
You can try to debug the error by setting error_score='raise'.

Below are more details about the failures:
--------------------------------------------------------------------------------
1 fits failed with the following error:
Traceback (most recent call last):
  File "/usr/local/lib/python3.10/dist-packages/sklearn/model_selection/_validation.py", line 686, in _fit_and_score
    estimator.fit(X_train, y_train, **fit_params)
  File "/usr/local/lib/python3.10/dist-packages/pycaret/internal/pipeline.py", line 267, in fit
    fitted_estimator = self._memory_fit(
  File "/usr/local/lib/python3.10/dist-packages/joblib/memory.py", line 353, in __call__
    return self.func(*args, **kwargs)
  File "/usr/local/lib/python3.10/dist-packages/pycaret/internal/pipeline.py", line 66, in _fit_one
    transformer.fit(*args, **fit_params)
  File "/usr/local/lib/python3.10/dist-packages/xgboost/core.py", line 620, in inner_f
    return func(**kwargs)
  File "/usr/local/lib/python3.10/dist-packages/xgboost/sklearn.py", line 1490, in fit
    self._Booster = train(
  File "/usr/local/lib/python3.10/dist-packages/xgboost/core.py", line 620, in inner_f
    return func(**kwargs)
  File "/usr/local/lib/python3.10/dist-packages/xgboost/training.py", line 185, in train
    bst.update(dtrain, i, obj)
  File "/usr/local/lib/python3.10/dist-packages/xgboost/core.py", line 1918, in update
    _check_call(_LIB.XGBoosterUpdateOneIter(self.handle,
  File "/usr/local/lib/python3.10/dist-packages/xgboost/core.py", line 279, in _check_call
    raise XGBoostError(py_str(_LIB.XGBGetLastError()))
xgboost.core.XGBoostError: [20:48:52] ../src/gbm/gbtree.cc:625: Check failed: common::AllVisibleGPUs() >= 1 (0 vs. 1) : No visible GPU is found for XGBoost.
Stack trace:
  [bt] (0) /usr/local/lib/python3.10/dist-packages/xgboost/lib/libxgboost.so(+0x2a7e13) [0x7f76936a7e13]
  [bt] (1) /usr/local/lib/python3.10/dist-packages/xgboost/lib/libxgboost.so(+0x2ab120) [0x7f76936ab120]
  [bt] (2) /usr/local/lib/python3.10/dist-packages/xgboost/lib/libxgboost.so(+0x2ab52a) [0x7f76936ab52a]
  [bt] (3) /usr/local/lib/python3.10/dist-packages/xgboost/lib/libxgboost.so(+0x2e03c7) [0x7f76936e03c7]
  [bt] (4) /usr/local/lib/python3.10/dist-packages/xgboost/lib/libxgboost.so(XGBoosterUpdateOneIter+0x70) [0x7f769353c5a0]
  [bt] (5) /lib/x86_64-linux-gnu/libffi.so.8(+0x7e2e) [0x7f7708341e2e]
  [bt] (6) /lib/x86_64-linux-gnu/libffi.so.8(+0x4493) [0x7f770833e493]
  [bt] (7) /usr/lib/python3.10/lib-dynload/_ctypes.cpython-310-x86_64-linux-gnu.so(+0xa3e9) [0x7f77083673e9]
  [bt] (8) /usr/lib/python3.10/lib-dynload/_ctypes.cpython-310-x86_64-linux-gnu.so(+0x9a00) [0x7f7708366a00]



--------------------------------------------------------------------------------
3 fits failed with the following error:
Traceback (most recent call last):
  File "/usr/local/lib/python3.10/dist-packages/sklearn/model_selection/_validation.py", line 686, in _fit_and_score
    estimator.fit(X_train, y_train, **fit_params)
  File "/usr/local/lib/python3.10/dist-packages/pycaret/internal/pipeline.py", line 267, in fit
    fitted_estimator = self._memory_fit(
  File "/usr/local/lib/python3.10/dist-packages/joblib/memory.py", line 353, in __call__
    return self.func(*args, **kwargs)
  File "/usr/local/lib/python3.10/dist-packages/pycaret/internal/pipeline.py", line 66, in _fit_one
    transformer.fit(*args, **fit_params)
  File "/usr/local/lib/python3.10/dist-packages/xgboost/core.py", line 620, in inner_f
    return func(**kwargs)
  File "/usr/local/lib/python3.10/dist-packages/xgboost/sklearn.py", line 1490, in fit
    self._Booster = train(
  File "/usr/local/lib/python3.10/dist-packages/xgboost/core.py", line 620, in inner_f
    return func(**kwargs)
  File "/usr/local/lib/python3.10/dist-packages/xgboost/training.py", line 185, in train
    bst.update(dtrain, i, obj)
  File "/usr/local/lib/python3.10/dist-packages/xgboost/core.py", line 1918, in update
    _check_call(_LIB.XGBoosterUpdateOneIter(self.handle,
  File "/usr/local/lib/python3.10/dist-packages/xgboost/core.py", line 279, in _check_call
    raise XGBoostError(py_str(_LIB.XGBGetLastError()))
xgboost.core.XGBoostError: [20:48:53] ../src/gbm/gbtree.cc:625: Check failed: common::AllVisibleGPUs() >= 1 (0 vs. 1) : No visible GPU is found for XGBoost.
Stack trace:
  [bt] (0) /usr/local/lib/python3.10/dist-packages/xgboost/lib/libxgboost.so(+0x2a7e13) [0x7f76936a7e13]
  [bt] (1) /usr/local/lib/python3.10/dist-packages/xgboost/lib/libxgboost.so(+0x2ab120) [0x7f76936ab120]
  [bt] (2) /usr/local/lib/python3.10/dist-packages/xgboost/lib/libxgboost.so(+0x2ab52a) [0x7f76936ab52a]
  [bt] (3) /usr/local/lib/python3.10/dist-packages/xgboost/lib/libxgboost.so(+0x2e03c7) [0x7f76936e03c7]
  [bt] (4) /usr/local/lib/python3.10/dist-packages/xgboost/lib/libxgboost.so(XGBoosterUpdateOneIter+0x70) [0x7f769353c5a0]
  [bt] (5) /lib/x86_64-linux-gnu/libffi.so.8(+0x7e2e) [0x7f7708341e2e]
  [bt] (6) /lib/x86_64-linux-gnu/libffi.so.8(+0x4493) [0x7f770833e493]
  [bt] (7) /usr/lib/python3.10/lib-dynload/_ctypes.cpython-310-x86_64-linux-gnu.so(+0xa3e9) [0x7f77083673e9]
  [bt] (8) /usr/lib/python3.10/lib-dynload/_ctypes.cpython-310-x86_64-linux-gnu.so(+0x9a00) [0x7f7708366a00]



--------------------------------------------------------------------------------
5 fits failed with the following error:
Traceback (most recent call last):
  File "/usr/local/lib/python3.10/dist-packages/sklearn/model_selection/_validation.py", line 686, in _fit_and_score
    estimator.fit(X_train, y_train, **fit_params)
  File "/usr/local/lib/python3.10/dist-packages/pycaret/internal/pipeline.py", line 267, in fit
    fitted_estimator = self._memory_fit(
  File "/usr/local/lib/python3.10/dist-packages/joblib/memory.py", line 353, in __call__
    return self.func(*args, **kwargs)
  File "/usr/local/lib/python3.10/dist-packages/pycaret/internal/pipeline.py", line 66, in _fit_one
    transformer.fit(*args, **fit_params)
  File "/usr/local/lib/python3.10/dist-packages/xgboost/core.py", line 620, in inner_f
    return func(**kwargs)
  File "/usr/local/lib/python3.10/dist-packages/xgboost/sklearn.py", line 1490, in fit
    self._Booster = train(
  File "/usr/local/lib/python3.10/dist-packages/xgboost/core.py", line 620, in inner_f
    return func(**kwargs)
  File "/usr/local/lib/python3.10/dist-packages/xgboost/training.py", line 185, in train
    bst.update(dtrain, i, obj)
  File "/usr/local/lib/python3.10/dist-packages/xgboost/core.py", line 1918, in update
    _check_call(_LIB.XGBoosterUpdateOneIter(self.handle,
  File "/usr/local/lib/python3.10/dist-packages/xgboost/core.py", line 279, in _check_call
    raise XGBoostError(py_str(_LIB.XGBGetLastError()))
xgboost.core.XGBoostError: [20:48:54] ../src/gbm/gbtree.cc:625: Check failed: common::AllVisibleGPUs() >= 1 (0 vs. 1) : No visible GPU is found for XGBoost.
Stack trace:
  [bt] (0) /usr/local/lib/python3.10/dist-packages/xgboost/lib/libxgboost.so(+0x2a7e13) [0x7f76936a7e13]
  [bt] (1) /usr/local/lib/python3.10/dist-packages/xgboost/lib/libxgboost.so(+0x2ab120) [0x7f76936ab120]
  [bt] (2) /usr/local/lib/python3.10/dist-packages/xgboost/lib/libxgboost.so(+0x2ab52a) [0x7f76936ab52a]
  [bt] (3) /usr/local/lib/python3.10/dist-packages/xgboost/lib/libxgboost.so(+0x2e03c7) [0x7f76936e03c7]
  [bt] (4) /usr/local/lib/python3.10/dist-packages/xgboost/lib/libxgboost.so(XGBoosterUpdateOneIter+0x70) [0x7f769353c5a0]
  [bt] (5) /lib/x86_64-linux-gnu/libffi.so.8(+0x7e2e) [0x7f7708341e2e]
  [bt] (6) /lib/x86_64-linux-gnu/libffi.so.8(+0x4493) [0x7f770833e493]
  [bt] (7) /usr/lib/python3.10/lib-dynload/_ctypes.cpython-310-x86_64-linux-gnu.so(+0xa3e9) [0x7f77083673e9]
  [bt] (8) /usr/lib/python3.10/lib-dynload/_ctypes.cpython-310-x86_64-linux-gnu.so(+0x9a00) [0x7f7708366a00]



--------------------------------------------------------------------------------
1 fits failed with the following error:
Traceback (most recent call last):
  File "/usr/local/lib/python3.10/dist-packages/sklearn/model_selection/_validation.py", line 686, in _fit_and_score
    estimator.fit(X_train, y_train, **fit_params)
  File "/usr/local/lib/python3.10/dist-packages/pycaret/internal/pipeline.py", line 267, in fit
    fitted_estimator = self._memory_fit(
  File "/usr/local/lib/python3.10/dist-packages/joblib/memory.py", line 353, in __call__
    return self.func(*args, **kwargs)
  File "/usr/local/lib/python3.10/dist-packages/pycaret/internal/pipeline.py", line 66, in _fit_one
    transformer.fit(*args, **fit_params)
  File "/usr/local/lib/python3.10/dist-packages/xgboost/core.py", line 620, in inner_f
    return func(**kwargs)
  File "/usr/local/lib/python3.10/dist-packages/xgboost/sklearn.py", line 1490, in fit
    self._Booster = train(
  File "/usr/local/lib/python3.10/dist-packages/xgboost/core.py", line 620, in inner_f
    return func(**kwargs)
  File "/usr/local/lib/python3.10/dist-packages/xgboost/training.py", line 185, in train
    bst.update(dtrain, i, obj)
  File "/usr/local/lib/python3.10/dist-packages/xgboost/core.py", line 1918, in update
    _check_call(_LIB.XGBoosterUpdateOneIter(self.handle,
  File "/usr/local/lib/python3.10/dist-packages/xgboost/core.py", line 279, in _check_call
    raise XGBoostError(py_str(_LIB.XGBGetLastError()))
xgboost.core.XGBoostError: [20:48:55] ../src/gbm/gbtree.cc:625: Check failed: common::AllVisibleGPUs() >= 1 (0 vs. 1) : No visible GPU is found for XGBoost.
Stack trace:
  [bt] (0) /usr/local/lib/python3.10/dist-packages/xgboost/lib/libxgboost.so(+0x2a7e13) [0x7f76936a7e13]
  [bt] (1) /usr/local/lib/python3.10/dist-packages/xgboost/lib/libxgboost.so(+0x2ab120) [0x7f76936ab120]
  [bt] (2) /usr/local/lib/python3.10/dist-packages/xgboost/lib/libxgboost.so(+0x2ab52a) [0x7f76936ab52a]
  [bt] (3) /usr/local/lib/python3.10/dist-packages/xgboost/lib/libxgboost.so(+0x2e03c7) [0x7f76936e03c7]
  [bt] (4) /usr/local/lib/python3.10/dist-packages/xgboost/lib/libxgboost.so(XGBoosterUpdateOneIter+0x70) [0x7f769353c5a0]
  [bt] (5) /lib/x86_64-linux-gnu/libffi.so.8(+0x7e2e) [0x7f7708341e2e]
  [bt] (6) /lib/x86_64-linux-gnu/libffi.so.8(+0x4493) [0x7f770833e493]
  [bt] (7) /usr/lib/python3.10/lib-dynload/_ctypes.cpython-310-x86_64-linux-gnu.so(+0xa3e9) [0x7f77083673e9]
  [bt] (8) /usr/lib/python3.10/lib-dynload/_ctypes.cpython-310-x86_64-linux-gnu.so(+0x9a00) [0x7f7708366a00]




During handling of the above exception, another exception occurred:

Traceback (most recent call last):
  File "/usr/local/lib/python3.10/dist-packages/sklearn/model_selection/_validation.py", line 686, in _fit_and_score
    estimator.fit(X_train, y_train, **fit_params)
  File "/usr/local/lib/python3.10/dist-packages/pycaret/internal/pipeline.py", line 267, in fit
    fitted_estimator = self._memory_fit(
  File "/usr/local/lib/python3.10/dist-packages/joblib/memory.py", line 353, in __call__
    return self.func(*args, **kwargs)
  File "/usr/local/lib/python3.10/dist-packages/pycaret/internal/pipeline.py", line 66, in _fit_one
    transformer.fit(*args, **fit_params)
  File "/usr/local/lib/python3.10/dist-packages/xgboost/core.py", line 620, in inner_f
    return func(**kwargs)
  File "/usr/local/lib/python3.10/dist-packages/xgboost/sklearn.py", line 1490, in fit
    self._Booster = train(
  File "/usr/local/lib/python3.10/dist-packages/xgboost/core.py", line 620, in inner_f
    return func(**kwargs)
  File "/usr/local/lib/python3.10/dist-packages/xgboost/training.py", line 185, in train
    bst.update(dtrain, i, obj)
  File "/usr/local/lib/python3.10/dist-packages/xgboost/core.py", line 1918, in update
    _check_call(_LIB.XGBoosterUpdateOneIter(self.handle,
  File "/usr/local/lib/python3.10/dist-packages/xgboost/core.py", line 279, in _check_call
    raise XGBoostError(py_str(_LIB.XGBGetLastError()))
xgboost.core.XGBoostError: [20:48:57] ../src/gbm/gbtree.cc:625: Check failed: common::AllVisibleGPUs() >= 1 (0 vs. 1) : No visible GPU is found for XGBoost.
Stack trace:
  [bt] (0) /usr/local/lib/python3.10/dist-packages/xgboost/lib/libxgboost.so(+0x2a7e13) [0x7f76936a7e13]
  [bt] (1) /usr/local/lib/python3.10/dist-packages/xgboost/lib/libxgboost.so(+0x2ab120) [0x7f76936ab120]
  [bt] (2) /usr/local/lib/python3.10/dist-packages/xgboost/lib/libxgboost.so(+0x2ab52a) [0x7f76936ab52a]
  [bt] (3) /usr/local/lib/python3.10/dist-packages/xgboost/lib/libxgboost.so(+0x2e03c7) [0x7f76936e03c7]
  [bt] (4) /usr/local/lib/python3.10/dist-packages/xgboost/lib/libxgboost.so(XGBoosterUpdateOneIter+0x70) [0x7f769353c5a0]
  [bt] (5) /lib/x86_64-linux-gnu/libffi.so.8(+0x7e2e) [0x7f7708341e2e]
  [bt] (6) /lib/x86_64-linux-gnu/libffi.so.8(+0x4493) [0x7f770833e493]
  [bt] (7) /usr/lib/python3.10/lib-dynload/_ctypes.cpython-310-x86_64-linux-gnu.so(+0xa3e9) [0x7f77083673e9]
  [bt] (8) /usr/lib/python3.10/lib-dynload/_ctypes.cpython-310-x86_64-linux-gnu.so(+0x9a00) [0x7f7708366a00]




2023-09-17 20:48:57,186:INFO:Initializing Light Gradient Boosting Machine
2023-09-17 20:48:57,186:INFO:Total runtime is 1.9258045196533202 minutes
2023-09-17 20:48:57,192:INFO:SubProcess create_model() called ==================================
2023-09-17 20:48:57,192:INFO:Initializing create_model()
2023-09-17 20:48:57,192:INFO:create_model(self=<pycaret.classification.oop.ClassificationExperiment object at 0x7f76ad0a8370>, estimator=lightgbm, fold=StratifiedKFold(n_splits=10, random_state=None, shuffle=False), round=4, cross_validation=True, predict=True, fit_kwargs={}, groups=None, refit=False, probability_threshold=None, experiment_custom_tags=None, verbose=False, system=False, add_to_model_list=True, metrics=None, display=<pycaret.internal.display.display.CommonDisplay object at 0x7f76a9411e10>, model_only=True, return_train_score=False, kwargs={})
2023-09-17 20:48:57,192:INFO:Checking exceptions
2023-09-17 20:48:57,192:INFO:Importing libraries
2023-09-17 20:48:57,192:INFO:Copying training dataset
2023-09-17 20:48:57,212:INFO:Defining folds
2023-09-17 20:48:57,212:INFO:Declaring metric variables
2023-09-17 20:48:57,222:INFO:Importing untrained model
2023-09-17 20:48:57,229:INFO:Light Gradient Boosting Machine Imported successfully
2023-09-17 20:48:57,241:INFO:Starting cross validation
2023-09-17 20:48:57,245:INFO:Cross validating with StratifiedKFold(n_splits=10, random_state=None, shuffle=False), n_jobs=1
2023-09-17 20:48:57,436:INFO:[LightGBM] [Warning] Found whitespace in feature_names, replace with underlines
2023-09-17 20:48:57,436:INFO:[LightGBM] [Info] Number of positive: 8325, number of negative: 667
2023-09-17 20:48:57,448:INFO:[LightGBM] [Warning] Auto-choosing row-wise multi-threading, the overhead of testing was 0.010772 seconds.
2023-09-17 20:48:57,448:INFO:You can set `force_row_wise=true` to remove the overhead.
2023-09-17 20:48:57,449:INFO:And if memory is not enough, you can set `force_col_wise=true`.
2023-09-17 20:48:57,449:INFO:[LightGBM] [Info] Total Bins 643
2023-09-17 20:48:57,449:INFO:[LightGBM] [Info] Number of data points in the train set: 8992, number of used features: 22
2023-09-17 20:48:57,450:INFO:[LightGBM] [Info] [binary:BoostFromScore]: pavg=0.925823 -> initscore=2.524228
2023-09-17 20:48:57,450:INFO:[LightGBM] [Info] Start training from score 2.524228
2023-09-17 20:48:57,843:INFO:[LightGBM] [Warning] Found whitespace in feature_names, replace with underlines
2023-09-17 20:48:57,844:INFO:[LightGBM] [Info] Number of positive: 8326, number of negative: 666
2023-09-17 20:48:57,846:INFO:[LightGBM] [Warning] Auto-choosing row-wise multi-threading, the overhead of testing was 0.000713 seconds.
2023-09-17 20:48:57,846:INFO:You can set `force_row_wise=true` to remove the overhead.
2023-09-17 20:48:57,846:INFO:And if memory is not enough, you can set `force_col_wise=true`.
2023-09-17 20:48:57,846:INFO:[LightGBM] [Info] Total Bins 638
2023-09-17 20:48:57,846:INFO:[LightGBM] [Info] Number of data points in the train set: 8992, number of used features: 22
2023-09-17 20:48:57,846:INFO:[LightGBM] [Info] [binary:BoostFromScore]: pavg=0.925934 -> initscore=2.525849
2023-09-17 20:48:57,847:INFO:[LightGBM] [Info] Start training from score 2.525849
2023-09-17 20:48:58,205:INFO:[LightGBM] [Warning] Found whitespace in feature_names, replace with underlines
2023-09-17 20:48:58,206:INFO:[LightGBM] [Info] Number of positive: 8326, number of negative: 667
2023-09-17 20:48:58,208:INFO:[LightGBM] [Warning] Auto-choosing row-wise multi-threading, the overhead of testing was 0.000621 seconds.
2023-09-17 20:48:58,208:INFO:You can set `force_row_wise=true` to remove the overhead.
2023-09-17 20:48:58,208:INFO:And if memory is not enough, you can set `force_col_wise=true`.
2023-09-17 20:48:58,208:INFO:[LightGBM] [Info] Total Bins 637
2023-09-17 20:48:58,208:INFO:[LightGBM] [Info] Number of data points in the train set: 8993, number of used features: 22
2023-09-17 20:48:58,209:INFO:[LightGBM] [Info] [binary:BoostFromScore]: pavg=0.925831 -> initscore=2.524348
2023-09-17 20:48:58,209:INFO:[LightGBM] [Info] Start training from score 2.524348
2023-09-17 20:48:58,573:INFO:[LightGBM] [Warning] Found whitespace in feature_names, replace with underlines
2023-09-17 20:48:58,574:INFO:[LightGBM] [Info] Number of positive: 8326, number of negative: 667
2023-09-17 20:48:58,575:INFO:[LightGBM] [Warning] Auto-choosing row-wise multi-threading, the overhead of testing was 0.000702 seconds.
2023-09-17 20:48:58,576:INFO:You can set `force_row_wise=true` to remove the overhead.
2023-09-17 20:48:58,576:INFO:And if memory is not enough, you can set `force_col_wise=true`.
2023-09-17 20:48:58,576:INFO:[LightGBM] [Info] Total Bins 642
2023-09-17 20:48:58,576:INFO:[LightGBM] [Info] Number of data points in the train set: 8993, number of used features: 22
2023-09-17 20:48:58,576:INFO:[LightGBM] [Info] [binary:BoostFromScore]: pavg=0.925831 -> initscore=2.524348
2023-09-17 20:48:58,576:INFO:[LightGBM] [Info] Start training from score 2.524348
2023-09-17 20:48:58,933:INFO:[LightGBM] [Warning] Found whitespace in feature_names, replace with underlines
2023-09-17 20:48:58,934:INFO:[LightGBM] [Info] Number of positive: 8326, number of negative: 667
2023-09-17 20:48:58,935:INFO:[LightGBM] [Warning] Auto-choosing col-wise multi-threading, the overhead of testing was 0.001203 seconds.
2023-09-17 20:48:58,935:INFO:You can set `force_col_wise=true` to remove the overhead.
2023-09-17 20:48:58,936:INFO:[LightGBM] [Info] Total Bins 632
2023-09-17 20:48:58,936:INFO:[LightGBM] [Info] Number of data points in the train set: 8993, number of used features: 22
2023-09-17 20:48:58,936:INFO:[LightGBM] [Info] [binary:BoostFromScore]: pavg=0.925831 -> initscore=2.524348
2023-09-17 20:48:58,936:INFO:[LightGBM] [Info] Start training from score 2.524348
2023-09-17 20:48:59,323:INFO:[LightGBM] [Warning] Found whitespace in feature_names, replace with underlines
2023-09-17 20:48:59,324:INFO:[LightGBM] [Info] Number of positive: 8326, number of negative: 667
2023-09-17 20:48:59,325:INFO:[LightGBM] [Warning] Auto-choosing row-wise multi-threading, the overhead of testing was 0.000678 seconds.
2023-09-17 20:48:59,326:INFO:You can set `force_row_wise=true` to remove the overhead.
2023-09-17 20:48:59,326:INFO:And if memory is not enough, you can set `force_col_wise=true`.
2023-09-17 20:48:59,326:INFO:[LightGBM] [Info] Total Bins 642
2023-09-17 20:48:59,326:INFO:[LightGBM] [Info] Number of data points in the train set: 8993, number of used features: 22
2023-09-17 20:48:59,326:INFO:[LightGBM] [Info] [binary:BoostFromScore]: pavg=0.925831 -> initscore=2.524348
2023-09-17 20:48:59,326:INFO:[LightGBM] [Info] Start training from score 2.524348
2023-09-17 20:48:59,710:INFO:[LightGBM] [Warning] Found whitespace in feature_names, replace with underlines
2023-09-17 20:48:59,711:INFO:[LightGBM] [Info] Number of positive: 8326, number of negative: 667
2023-09-17 20:48:59,713:INFO:[LightGBM] [Warning] Auto-choosing row-wise multi-threading, the overhead of testing was 0.000674 seconds.
2023-09-17 20:48:59,713:INFO:You can set `force_row_wise=true` to remove the overhead.
2023-09-17 20:48:59,713:INFO:And if memory is not enough, you can set `force_col_wise=true`.
2023-09-17 20:48:59,713:INFO:[LightGBM] [Info] Total Bins 634
2023-09-17 20:48:59,713:INFO:[LightGBM] [Info] Number of data points in the train set: 8993, number of used features: 22
2023-09-17 20:48:59,714:INFO:[LightGBM] [Info] [binary:BoostFromScore]: pavg=0.925831 -> initscore=2.524348
2023-09-17 20:48:59,714:INFO:[LightGBM] [Info] Start training from score 2.524348
2023-09-17 20:49:00,086:INFO:[LightGBM] [Warning] Found whitespace in feature_names, replace with underlines
2023-09-17 20:49:00,087:INFO:[LightGBM] [Info] Number of positive: 8326, number of negative: 667
2023-09-17 20:49:00,089:INFO:[LightGBM] [Warning] Auto-choosing row-wise multi-threading, the overhead of testing was 0.000694 seconds.
2023-09-17 20:49:00,089:INFO:You can set `force_row_wise=true` to remove the overhead.
2023-09-17 20:49:00,089:INFO:And if memory is not enough, you can set `force_col_wise=true`.
2023-09-17 20:49:00,089:INFO:[LightGBM] [Info] Total Bins 637
2023-09-17 20:49:00,089:INFO:[LightGBM] [Info] Number of data points in the train set: 8993, number of used features: 22
2023-09-17 20:49:00,090:INFO:[LightGBM] [Info] [binary:BoostFromScore]: pavg=0.925831 -> initscore=2.524348
2023-09-17 20:49:00,090:INFO:[LightGBM] [Info] Start training from score 2.524348
2023-09-17 20:49:00,459:INFO:[LightGBM] [Warning] Found whitespace in feature_names, replace with underlines
2023-09-17 20:49:00,460:INFO:[LightGBM] [Info] Number of positive: 8326, number of negative: 667
2023-09-17 20:49:00,462:INFO:[LightGBM] [Warning] Auto-choosing row-wise multi-threading, the overhead of testing was 0.000695 seconds.
2023-09-17 20:49:00,462:INFO:You can set `force_row_wise=true` to remove the overhead.
2023-09-17 20:49:00,462:INFO:And if memory is not enough, you can set `force_col_wise=true`.
2023-09-17 20:49:00,462:INFO:[LightGBM] [Info] Total Bins 632
2023-09-17 20:49:00,462:INFO:[LightGBM] [Info] Number of data points in the train set: 8993, number of used features: 22
2023-09-17 20:49:00,463:INFO:[LightGBM] [Info] [binary:BoostFromScore]: pavg=0.925831 -> initscore=2.524348
2023-09-17 20:49:00,463:INFO:[LightGBM] [Info] Start training from score 2.524348
2023-09-17 20:49:00,850:INFO:[LightGBM] [Warning] Found whitespace in feature_names, replace with underlines
2023-09-17 20:49:00,854:INFO:[LightGBM] [Info] Number of positive: 8326, number of negative: 667
2023-09-17 20:49:00,857:INFO:[LightGBM] [Warning] Auto-choosing row-wise multi-threading, the overhead of testing was 0.000667 seconds.
2023-09-17 20:49:00,857:INFO:You can set `force_row_wise=true` to remove the overhead.
2023-09-17 20:49:00,857:INFO:And if memory is not enough, you can set `force_col_wise=true`.
2023-09-17 20:49:00,858:INFO:[LightGBM] [Info] Total Bins 640
2023-09-17 20:49:00,858:INFO:[LightGBM] [Info] Number of data points in the train set: 8993, number of used features: 22
2023-09-17 20:49:00,858:INFO:[LightGBM] [Info] [binary:BoostFromScore]: pavg=0.925831 -> initscore=2.524348
2023-09-17 20:49:00,858:INFO:[LightGBM] [Info] Start training from score 2.524348
2023-09-17 20:49:00,858:INFO:[LightGBM] [Info] Start training from score 2.524348

2023-09-17 20:49:01,035:INFO:Calculating mean and std
2023-09-17 20:49:01,039:INFO:Creating metrics dataframe
2023-09-17 20:49:01,047:INFO:Uploading results into container
2023-09-17 20:49:01,049:INFO:Uploading model into container now
2023-09-17 20:49:01,050:INFO:_master_model_container: 13
2023-09-17 20:49:01,050:INFO:_display_container: 2
2023-09-17 20:49:01,051:INFO:LGBMClassifier(boosting_type='gbdt', class_weight=None, colsample_bytree=1.0,
               importance_type='split', learning_rate=0.1, max_depth=-1,
               min_child_samples=20, min_child_weight=0.001, min_split_gain=0.0,
               n_estimators=100, n_jobs=-1, num_leaves=31, objective=None,
               random_state=2858, reg_alpha=0.0, reg_lambda=0.0, subsample=1.0,
               subsample_for_bin=200000, subsample_freq=0)
2023-09-17 20:49:01,051:INFO:create_model() successfully completed......................................
2023-09-17 20:49:01,221:INFO:SubProcess create_model() end ==================================
2023-09-17 20:49:01,221:INFO:Creating metrics dataframe
2023-09-17 20:49:01,238:INFO:Initializing CatBoost Classifier
2023-09-17 20:49:01,239:INFO:Total runtime is 1.993354860941569 minutes
2023-09-17 20:49:01,245:INFO:SubProcess create_model() called ==================================
2023-09-17 20:49:01,245:INFO:Initializing create_model()
2023-09-17 20:49:01,245:INFO:create_model(self=<pycaret.classification.oop.ClassificationExperiment object at 0x7f76ad0a8370>, estimator=catboost, fold=StratifiedKFold(n_splits=10, random_state=None, shuffle=False), round=4, cross_validation=True, predict=True, fit_kwargs={}, groups=None, refit=False, probability_threshold=None, experiment_custom_tags=None, verbose=False, system=False, add_to_model_list=True, metrics=None, display=<pycaret.internal.display.display.CommonDisplay object at 0x7f76a9411e10>, model_only=True, return_train_score=False, kwargs={})
2023-09-17 20:49:01,246:INFO:Checking exceptions
2023-09-17 20:49:01,246:INFO:Importing libraries
2023-09-17 20:49:01,246:INFO:Copying training dataset
2023-09-17 20:49:01,259:INFO:Defining folds
2023-09-17 20:49:01,259:INFO:Declaring metric variables
2023-09-17 20:49:01,272:INFO:Importing untrained model
2023-09-17 20:49:01,280:INFO:CatBoost Classifier Imported successfully
2023-09-17 20:49:01,293:INFO:Starting cross validation
2023-09-17 20:49:01,296:INFO:Cross validating with StratifiedKFold(n_splits=10, random_state=None, shuffle=False), n_jobs=1
2023-09-17 20:49:03,310:WARNING:create_model() for catboost raised an exception or returned all 0.0, trying without fit_kwargs:
2023-09-17 20:49:03,311:WARNING:Traceback (most recent call last):
  File "/usr/local/lib/python3.10/dist-packages/pycaret/internal/pycaret_experiment/supervised_experiment.py", line 796, in compare_models
    model, model_fit_time = self._create_model(**create_model_args)
  File "/usr/local/lib/python3.10/dist-packages/pycaret/internal/pycaret_experiment/supervised_experiment.py", line 1527, in _create_model
    model, model_fit_time, model_results, _ = self._create_model_with_cv(
  File "/usr/local/lib/python3.10/dist-packages/pycaret/internal/pycaret_experiment/supervised_experiment.py", line 1121, in _create_model_with_cv
    scores = cross_validate(
  File "/usr/local/lib/python3.10/dist-packages/sklearn/model_selection/_validation.py", line 285, in cross_validate
    _warn_or_raise_about_fit_failures(results, error_score)
  File "/usr/local/lib/python3.10/dist-packages/sklearn/model_selection/_validation.py", line 367, in _warn_or_raise_about_fit_failures
    raise ValueError(all_fits_failed_message)
ValueError: 
All the 10 fits failed.
It is very likely that your model is misconfigured.
You can try to debug the error by setting error_score='raise'.

Below are more details about the failures:
--------------------------------------------------------------------------------
1 fits failed with the following error:
Traceback (most recent call last):
  File "/usr/local/lib/python3.10/dist-packages/sklearn/model_selection/_validation.py", line 686, in _fit_and_score
    estimator.fit(X_train, y_train, **fit_params)
  File "/usr/local/lib/python3.10/dist-packages/pycaret/internal/pipeline.py", line 267, in fit
    fitted_estimator = self._memory_fit(
  File "/usr/local/lib/python3.10/dist-packages/joblib/memory.py", line 353, in __call__
    return self.func(*args, **kwargs)
  File "/usr/local/lib/python3.10/dist-packages/pycaret/internal/pipeline.py", line 66, in _fit_one
    transformer.fit(*args, **fit_params)
  File "/usr/local/lib/python3.10/dist-packages/catboost/core.py", line 5100, in fit
    self._fit(X, y, cat_features, text_features, embedding_features, None, sample_weight, None, None, None, None, baseline, use_best_model,
  File "/usr/local/lib/python3.10/dist-packages/catboost/core.py", line 2319, in _fit
    self._train(
  File "/usr/local/lib/python3.10/dist-packages/catboost/core.py", line 1723, in _train
    self._object._train(train_pool, test_pool, params, allow_clear_pool, init_model._object if init_model else None)
  File "_catboost.pyx", line 4645, in _catboost._CatBoost._train
  File "_catboost.pyx", line 4694, in _catboost._CatBoost._train
_catboost.CatBoostError: /src/catboost/catboost/cuda/cuda_lib/cuda_base.h:281: CUDA error 35: CUDA driver version is insufficient for CUDA runtime version

--------------------------------------------------------------------------------
9 fits failed with the following error:
Traceback (most recent call last):
  File "/usr/local/lib/python3.10/dist-packages/sklearn/model_selection/_validation.py", line 686, in _fit_and_score
    estimator.fit(X_train, y_train, **fit_params)
  File "/usr/local/lib/python3.10/dist-packages/pycaret/internal/pipeline.py", line 267, in fit
    fitted_estimator = self._memory_fit(
  File "/usr/local/lib/python3.10/dist-packages/joblib/memory.py", line 353, in __call__
    return self.func(*args, **kwargs)
  File "/usr/local/lib/python3.10/dist-packages/pycaret/internal/pipeline.py", line 66, in _fit_one
    transformer.fit(*args, **fit_params)
  File "/usr/local/lib/python3.10/dist-packages/catboost/core.py", line 5100, in fit
    self._fit(X, y, cat_features, text_features, embedding_features, None, sample_weight, None, None, None, None, baseline, use_best_model,
  File "/usr/local/lib/python3.10/dist-packages/catboost/core.py", line 2319, in _fit
    self._train(
  File "/usr/local/lib/python3.10/dist-packages/catboost/core.py", line 1723, in _train
    self._object._train(train_pool, test_pool, params, allow_clear_pool, init_model._object if init_model else None)
  File "_catboost.pyx", line 4645, in _catboost._CatBoost._train
  File "_catboost.pyx", line 4694, in _catboost._CatBoost._train
_catboost.CatBoostError: /src/catboost/catboost/cuda/cuda_lib/cuda_manager.cpp:201: Condition violated: `State == nullptr'


2023-09-17 20:49:03,311:INFO:Initializing create_model()
2023-09-17 20:49:03,311:INFO:create_model(self=<pycaret.classification.oop.ClassificationExperiment object at 0x7f76ad0a8370>, estimator=catboost, fold=StratifiedKFold(n_splits=10, random_state=None, shuffle=False), round=4, cross_validation=True, predict=True, fit_kwargs={}, groups=None, refit=False, probability_threshold=None, experiment_custom_tags=None, verbose=False, system=False, add_to_model_list=True, metrics=None, display=<pycaret.internal.display.display.CommonDisplay object at 0x7f76a9411e10>, model_only=True, return_train_score=False, kwargs={})
2023-09-17 20:49:03,311:INFO:Checking exceptions
2023-09-17 20:49:03,311:INFO:Importing libraries
2023-09-17 20:49:03,311:INFO:Copying training dataset
2023-09-17 20:49:03,323:INFO:Defining folds
2023-09-17 20:49:03,324:INFO:Declaring metric variables
2023-09-17 20:49:03,338:INFO:Importing untrained model
2023-09-17 20:49:03,347:INFO:CatBoost Classifier Imported successfully
2023-09-17 20:49:03,364:INFO:Starting cross validation
2023-09-17 20:49:03,367:INFO:Cross validating with StratifiedKFold(n_splits=10, random_state=None, shuffle=False), n_jobs=1
2023-09-17 20:49:06,171:ERROR:create_model() for catboost raised an exception or returned all 0.0:
2023-09-17 20:49:06,171:ERROR:Traceback (most recent call last):
  File "/usr/local/lib/python3.10/dist-packages/pycaret/internal/pycaret_experiment/supervised_experiment.py", line 796, in compare_models
    model, model_fit_time = self._create_model(**create_model_args)
  File "/usr/local/lib/python3.10/dist-packages/pycaret/internal/pycaret_experiment/supervised_experiment.py", line 1527, in _create_model
    model, model_fit_time, model_results, _ = self._create_model_with_cv(
  File "/usr/local/lib/python3.10/dist-packages/pycaret/internal/pycaret_experiment/supervised_experiment.py", line 1121, in _create_model_with_cv
    scores = cross_validate(
  File "/usr/local/lib/python3.10/dist-packages/sklearn/model_selection/_validation.py", line 285, in cross_validate
    _warn_or_raise_about_fit_failures(results, error_score)
  File "/usr/local/lib/python3.10/dist-packages/sklearn/model_selection/_validation.py", line 367, in _warn_or_raise_about_fit_failures
    raise ValueError(all_fits_failed_message)
ValueError: 
All the 10 fits failed.
It is very likely that your model is misconfigured.
You can try to debug the error by setting error_score='raise'.

Below are more details about the failures:
--------------------------------------------------------------------------------
1 fits failed with the following error:
Traceback (most recent call last):
  File "/usr/local/lib/python3.10/dist-packages/sklearn/model_selection/_validation.py", line 686, in _fit_and_score
    estimator.fit(X_train, y_train, **fit_params)
  File "/usr/local/lib/python3.10/dist-packages/pycaret/internal/pipeline.py", line 267, in fit
    fitted_estimator = self._memory_fit(
  File "/usr/local/lib/python3.10/dist-packages/joblib/memory.py", line 353, in __call__
    return self.func(*args, **kwargs)
  File "/usr/local/lib/python3.10/dist-packages/pycaret/internal/pipeline.py", line 66, in _fit_one
    transformer.fit(*args, **fit_params)
  File "/usr/local/lib/python3.10/dist-packages/catboost/core.py", line 5100, in fit
    self._fit(X, y, cat_features, text_features, embedding_features, None, sample_weight, None, None, None, None, baseline, use_best_model,
  File "/usr/local/lib/python3.10/dist-packages/catboost/core.py", line 2319, in _fit
    self._train(
  File "/usr/local/lib/python3.10/dist-packages/catboost/core.py", line 1723, in _train
    self._object._train(train_pool, test_pool, params, allow_clear_pool, init_model._object if init_model else None)
  File "_catboost.pyx", line 4645, in _catboost._CatBoost._train
  File "_catboost.pyx", line 4694, in _catboost._CatBoost._train
_catboost.CatBoostError: /src/catboost/catboost/cuda/cuda_lib/cuda_base.h:281: CUDA error 35: CUDA driver version is insufficient for CUDA runtime version

--------------------------------------------------------------------------------
9 fits failed with the following error:
Traceback (most recent call last):
  File "/usr/local/lib/python3.10/dist-packages/sklearn/model_selection/_validation.py", line 686, in _fit_and_score
    estimator.fit(X_train, y_train, **fit_params)
  File "/usr/local/lib/python3.10/dist-packages/pycaret/internal/pipeline.py", line 267, in fit
    fitted_estimator = self._memory_fit(
  File "/usr/local/lib/python3.10/dist-packages/joblib/memory.py", line 353, in __call__
    return self.func(*args, **kwargs)
  File "/usr/local/lib/python3.10/dist-packages/pycaret/internal/pipeline.py", line 66, in _fit_one
    transformer.fit(*args, **fit_params)
  File "/usr/local/lib/python3.10/dist-packages/catboost/core.py", line 5100, in fit
    self._fit(X, y, cat_features, text_features, embedding_features, None, sample_weight, None, None, None, None, baseline, use_best_model,
  File "/usr/local/lib/python3.10/dist-packages/catboost/core.py", line 2319, in _fit
    self._train(
  File "/usr/local/lib/python3.10/dist-packages/catboost/core.py", line 1723, in _train
    self._object._train(train_pool, test_pool, params, allow_clear_pool, init_model._object if init_model else None)
  File "_catboost.pyx", line 4645, in _catboost._CatBoost._train
  File "_catboost.pyx", line 4694, in _catboost._CatBoost._train
_catboost.CatBoostError: /src/catboost/catboost/cuda/cuda_lib/cuda_manager.cpp:201: Condition violated: `State == nullptr'


During handling of the above exception, another exception occurred:

Traceback (most recent call last):
  File "/usr/local/lib/python3.10/dist-packages/pycaret/internal/pycaret_experiment/supervised_experiment.py", line 812, in compare_models
    model, model_fit_time = self._create_model(**create_model_args)
  File "/usr/local/lib/python3.10/dist-packages/pycaret/internal/pycaret_experiment/supervised_experiment.py", line 1527, in _create_model
    model, model_fit_time, model_results, _ = self._create_model_with_cv(
  File "/usr/local/lib/python3.10/dist-packages/pycaret/internal/pycaret_experiment/supervised_experiment.py", line 1121, in _create_model_with_cv
    scores = cross_validate(
  File "/usr/local/lib/python3.10/dist-packages/sklearn/model_selection/_validation.py", line 285, in cross_validate
    _warn_or_raise_about_fit_failures(results, error_score)
  File "/usr/local/lib/python3.10/dist-packages/sklearn/model_selection/_validation.py", line 367, in _warn_or_raise_about_fit_failures
    raise ValueError(all_fits_failed_message)
ValueError: 
All the 10 fits failed.
It is very likely that your model is misconfigured.
You can try to debug the error by setting error_score='raise'.

Below are more details about the failures:
--------------------------------------------------------------------------------
10 fits failed with the following error:
Traceback (most recent call last):
  File "/usr/local/lib/python3.10/dist-packages/pycaret/internal/pycaret_experiment/supervised_experiment.py", line 796, in compare_models
    model, model_fit_time = self._create_model(**create_model_args)
  File "/usr/local/lib/python3.10/dist-packages/pycaret/internal/pycaret_experiment/supervised_experiment.py", line 1527, in _create_model
    model, model_fit_time, model_results, _ = self._create_model_with_cv(
  File "/usr/local/lib/python3.10/dist-packages/pycaret/internal/pycaret_experiment/supervised_experiment.py", line 1121, in _create_model_with_cv
    scores = cross_validate(
  File "/usr/local/lib/python3.10/dist-packages/sklearn/model_selection/_validation.py", line 285, in cross_validate
    _warn_or_raise_about_fit_failures(results, error_score)
  File "/usr/local/lib/python3.10/dist-packages/sklearn/model_selection/_validation.py", line 367, in _warn_or_raise_about_fit_failures
    raise ValueError(all_fits_failed_message)
ValueError: 
All the 10 fits failed.
It is very likely that your model is misconfigured.
You can try to debug the error by setting error_score='raise'.

Below are more details about the failures:
--------------------------------------------------------------------------------
1 fits failed with the following error:
Traceback (most recent call last):
  File "/usr/local/lib/python3.10/dist-packages/sklearn/model_selection/_validation.py", line 686, in _fit_and_score
    estimator.fit(X_train, y_train, **fit_params)
  File "/usr/local/lib/python3.10/dist-packages/pycaret/internal/pipeline.py", line 267, in fit
    fitted_estimator = self._memory_fit(
  File "/usr/local/lib/python3.10/dist-packages/joblib/memory.py", line 353, in __call__
    return self.func(*args, **kwargs)
  File "/usr/local/lib/python3.10/dist-packages/pycaret/internal/pipeline.py", line 66, in _fit_one
    transformer.fit(*args, **fit_params)
  File "/usr/local/lib/python3.10/dist-packages/catboost/core.py", line 5100, in fit
    self._fit(X, y, cat_features, text_features, embedding_features, None, sample_weight, None, None, None, None, baseline, use_best_model,
  File "/usr/local/lib/python3.10/dist-packages/catboost/core.py", line 2319, in _fit
    self._train(
  File "/usr/local/lib/python3.10/dist-packages/catboost/core.py", line 1723, in _train
    self._object._train(train_pool, test_pool, params, allow_clear_pool, init_model._object if init_model else None)
  File "_catboost.pyx", line 4645, in _catboost._CatBoost._train
  File "_catboost.pyx", line 4694, in _catboost._CatBoost._train
_catboost.CatBoostError: /src/catboost/catboost/cuda/cuda_lib/cuda_base.h:281: CUDA error 35: CUDA driver version is insufficient for CUDA runtime version

--------------------------------------------------------------------------------
9 fits failed with the following error:
Traceback (most recent call last):
  File "/usr/local/lib/python3.10/dist-packages/sklearn/model_selection/_validation.py", line 686, in _fit_and_score
    estimator.fit(X_train, y_train, **fit_params)
  File "/usr/local/lib/python3.10/dist-packages/pycaret/internal/pipeline.py", line 267, in fit
    fitted_estimator = self._memory_fit(
  File "/usr/local/lib/python3.10/dist-packages/joblib/memory.py", line 353, in __call__
    return self.func(*args, **kwargs)
  File "/usr/local/lib/python3.10/dist-packages/pycaret/internal/pipeline.py", line 66, in _fit_one
    transformer.fit(*args, **fit_params)
  File "/usr/local/lib/python3.10/dist-packages/catboost/core.py", line 5100, in fit
    self._fit(X, y, cat_features, text_features, embedding_features, None, sample_weight, None, None, None, None, baseline, use_best_model,
  File "/usr/local/lib/python3.10/dist-packages/catboost/core.py", line 2319, in _fit
    self._train(
  File "/usr/local/lib/python3.10/dist-packages/catboost/core.py", line 1723, in _train
    self._object._train(train_pool, test_pool, params, allow_clear_pool, init_model._object if init_model else None)
  File "_catboost.pyx", line 4645, in _catboost._CatBoost._train
  File "_catboost.pyx", line 4694, in _catboost._CatBoost._train
_catboost.CatBoostError: /src/catboost/catboost/cuda/cuda_lib/cuda_manager.cpp:201: Condition violated: `State == nullptr'


During handling of the above exception, another exception occurred:

Traceback (most recent call last):
  File "/usr/local/lib/python3.10/dist-packages/sklearn/model_selection/_validation.py", line 686, in _fit_and_score
    estimator.fit(X_train, y_train, **fit_params)
  File "/usr/local/lib/python3.10/dist-packages/pycaret/internal/pipeline.py", line 267, in fit
    fitted_estimator = self._memory_fit(
  File "/usr/local/lib/python3.10/dist-packages/joblib/memory.py", line 353, in __call__
    return self.func(*args, **kwargs)
  File "/usr/local/lib/python3.10/dist-packages/pycaret/internal/pipeline.py", line 66, in _fit_one
    transformer.fit(*args, **fit_params)
  File "/usr/local/lib/python3.10/dist-packages/catboost/core.py", line 5100, in fit
    self._fit(X, y, cat_features, text_features, embedding_features, None, sample_weight, None, None, None, None, baseline, use_best_model,
  File "/usr/local/lib/python3.10/dist-packages/catboost/core.py", line 2319, in _fit
    self._train(
  File "/usr/local/lib/python3.10/dist-packages/catboost/core.py", line 1723, in _train
    self._object._train(train_pool, test_pool, params, allow_clear_pool, init_model._object if init_model else None)
  File "_catboost.pyx", line 4645, in _catboost._CatBoost._train
  File "_catboost.pyx", line 4694, in _catboost._CatBoost._train
_catboost.CatBoostError: /src/catboost/catboost/cuda/cuda_lib/cuda_manager.cpp:201: Condition violated: `State == nullptr'


2023-09-17 20:49:06,172:INFO:Initializing Dummy Classifier
2023-09-17 20:49:06,172:INFO:Total runtime is 2.0755757371584576 minutes
2023-09-17 20:49:06,180:INFO:SubProcess create_model() called ==================================
2023-09-17 20:49:06,180:INFO:Initializing create_model()
2023-09-17 20:49:06,180:INFO:create_model(self=<pycaret.classification.oop.ClassificationExperiment object at 0x7f76ad0a8370>, estimator=dummy, fold=StratifiedKFold(n_splits=10, random_state=None, shuffle=False), round=4, cross_validation=True, predict=True, fit_kwargs={}, groups=None, refit=False, probability_threshold=None, experiment_custom_tags=None, verbose=False, system=False, add_to_model_list=True, metrics=None, display=<pycaret.internal.display.display.CommonDisplay object at 0x7f76a9411e10>, model_only=True, return_train_score=False, kwargs={})
2023-09-17 20:49:06,181:INFO:Checking exceptions
2023-09-17 20:49:06,181:INFO:Importing libraries
2023-09-17 20:49:06,181:INFO:Copying training dataset
2023-09-17 20:49:06,195:INFO:Defining folds
2023-09-17 20:49:06,195:INFO:Declaring metric variables
2023-09-17 20:49:06,206:INFO:Importing untrained model
2023-09-17 20:49:06,216:INFO:Dummy Classifier Imported successfully
2023-09-17 20:49:06,229:INFO:Starting cross validation
2023-09-17 20:49:06,233:INFO:Cross validating with StratifiedKFold(n_splits=10, random_state=None, shuffle=False), n_jobs=1
2023-09-17 20:49:09,948:INFO:Calculating mean and std
2023-09-17 20:49:09,950:INFO:Creating metrics dataframe
2023-09-17 20:49:09,960:INFO:Uploading results into container
2023-09-17 20:49:09,961:INFO:Uploading model into container now
2023-09-17 20:49:09,966:INFO:_master_model_container: 14
2023-09-17 20:49:09,966:INFO:_display_container: 2
2023-09-17 20:49:09,966:INFO:DummyClassifier(constant=None, random_state=2858, strategy='prior')
2023-09-17 20:49:09,967:INFO:create_model() successfully completed......................................
2023-09-17 20:49:10,194:INFO:SubProcess create_model() end ==================================
2023-09-17 20:49:10,194:INFO:Creating metrics dataframe
2023-09-17 20:49:10,248:INFO:Initializing create_model()
2023-09-17 20:49:10,248:INFO:create_model(self=<pycaret.classification.oop.ClassificationExperiment object at 0x7f76ad0a8370>, estimator=GradientBoostingClassifier(ccp_alpha=0.0, criterion='friedman_mse', init=None,
                           learning_rate=0.1, loss='log_loss', max_depth=3,
                           max_features=None, max_leaf_nodes=None,
                           min_impurity_decrease=0.0, min_samples_leaf=1,
                           min_samples_split=2, min_weight_fraction_leaf=0.0,
                           n_estimators=100, n_iter_no_change=None,
                           random_state=2858, subsample=1.0, tol=0.0001,
                           validation_fraction=0.1, verbose=0,
                           warm_start=False), fold=StratifiedKFold(n_splits=10, random_state=None, shuffle=False), round=4, cross_validation=False, predict=False, fit_kwargs={}, groups=None, refit=True, probability_threshold=None, experiment_custom_tags=None, verbose=False, system=False, add_to_model_list=True, metrics=None, display=None, model_only=True, return_train_score=False, kwargs={})
2023-09-17 20:49:10,248:INFO:Checking exceptions
2023-09-17 20:49:10,251:INFO:Importing libraries
2023-09-17 20:49:10,252:INFO:Copying training dataset
2023-09-17 20:49:10,267:INFO:Defining folds
2023-09-17 20:49:10,267:INFO:Declaring metric variables
2023-09-17 20:49:10,267:INFO:Importing untrained model
2023-09-17 20:49:10,267:INFO:Declaring custom model
2023-09-17 20:49:10,269:INFO:Gradient Boosting Classifier Imported successfully
2023-09-17 20:49:10,272:INFO:Cross validation set to False
2023-09-17 20:49:10,272:INFO:Fitting Model
2023-09-17 20:49:12,540:INFO:GradientBoostingClassifier(ccp_alpha=0.0, criterion='friedman_mse', init=None,
                           learning_rate=0.1, loss='log_loss', max_depth=3,
                           max_features=None, max_leaf_nodes=None,
                           min_impurity_decrease=0.0, min_samples_leaf=1,
                           min_samples_split=2, min_weight_fraction_leaf=0.0,
                           n_estimators=100, n_iter_no_change=None,
                           random_state=2858, subsample=1.0, tol=0.0001,
                           validation_fraction=0.1, verbose=0,
                           warm_start=False)
2023-09-17 20:49:12,540:INFO:create_model() successfully completed......................................
2023-09-17 20:49:12,827:INFO:_master_model_container: 14
2023-09-17 20:49:12,827:INFO:_display_container: 2
2023-09-17 20:49:12,828:INFO:GradientBoostingClassifier(ccp_alpha=0.0, criterion='friedman_mse', init=None,
                           learning_rate=0.1, loss='log_loss', max_depth=3,
                           max_features=None, max_leaf_nodes=None,
                           min_impurity_decrease=0.0, min_samples_leaf=1,
                           min_samples_split=2, min_weight_fraction_leaf=0.0,
                           n_estimators=100, n_iter_no_change=None,
                           random_state=2858, subsample=1.0, tol=0.0001,
                           validation_fraction=0.1, verbose=0,
                           warm_start=False)
2023-09-17 20:49:12,828:INFO:compare_models() successfully completed......................................
2023-09-17 20:49:12,855:INFO:Initializing evaluate_model()
2023-09-17 20:49:12,855:INFO:evaluate_model(self=<pycaret.classification.oop.ClassificationExperiment object at 0x7f76ad0a8370>, estimator=GradientBoostingClassifier(ccp_alpha=0.0, criterion='friedman_mse', init=None,
                           learning_rate=0.1, loss='log_loss', max_depth=3,
                           max_features=None, max_leaf_nodes=None,
                           min_impurity_decrease=0.0, min_samples_leaf=1,
                           min_samples_split=2, min_weight_fraction_leaf=0.0,
                           n_estimators=100, n_iter_no_change=None,
                           random_state=2858, subsample=1.0, tol=0.0001,
                           validation_fraction=0.1, verbose=0,
                           warm_start=False), fold=None, fit_kwargs=None, plot_kwargs=None, feature_name=None, groups=None)
2023-09-17 20:49:12,895:INFO:Initializing plot_model()
2023-09-17 20:49:12,895:INFO:plot_model(plot=pipeline, fold=StratifiedKFold(n_splits=10, random_state=None, shuffle=False), verbose=False, display=None, display_format=None, estimator=GradientBoostingClassifier(ccp_alpha=0.0, criterion='friedman_mse', init=None,
                           learning_rate=0.1, loss='log_loss', max_depth=3,
                           max_features=None, max_leaf_nodes=None,
                           min_impurity_decrease=0.0, min_samples_leaf=1,
                           min_samples_split=2, min_weight_fraction_leaf=0.0,
                           n_estimators=100, n_iter_no_change=None,
                           random_state=2858, subsample=1.0, tol=0.0001,
                           validation_fraction=0.1, verbose=0,
                           warm_start=False), feature_name=None, fit_kwargs={}, groups=None, label=False, plot_kwargs=None, save=False, scale=1, self=<pycaret.classification.oop.ClassificationExperiment object at 0x7f76ad0a8370>, system=True)
2023-09-17 20:49:12,895:INFO:Checking exceptions
2023-09-17 20:49:12,903:INFO:Preloading libraries
2023-09-17 20:49:12,918:INFO:Copying training dataset
2023-09-17 20:49:12,919:INFO:Plot type: pipeline
2023-09-17 20:49:13,314:INFO:Visual Rendered Successfully
2023-09-17 20:49:13,526:INFO:plot_model() successfully completed......................................
2023-09-17 20:49:13,554:INFO:Initializing save_model()
2023-09-17 20:49:13,555:INFO:save_model(model=GradientBoostingClassifier(ccp_alpha=0.0, criterion='friedman_mse', init=None,
                           learning_rate=0.1, loss='log_loss', max_depth=3,
                           max_features=None, max_leaf_nodes=None,
                           min_impurity_decrease=0.0, min_samples_leaf=1,
                           min_samples_split=2, min_weight_fraction_leaf=0.0,
                           n_estimators=100, n_iter_no_change=None,
                           random_state=2858, subsample=1.0, tol=0.0001,
                           validation_fraction=0.1, verbose=0,
                           warm_start=False), model_name=modelo_2, prep_pipe_=Pipeline(memory=FastMemory(location=/tmp/joblib),
         steps=[('numerical_imputer',
                 TransformerWrapper(exclude=None,
                                    include=['Unnamed: 0',
                                             'Currently Hospitalized',
                                             'Currently in ICU',
                                             'Currently Intubated',
                                             'Ever Hospitalized', 'Ever in ICU',
                                             'Ever Intubated'],
                                    transformer=SimpleImputer(add_indicator=False,
                                                              copy=True,
                                                              fill_value=None,
                                                              keep_empty_features=False,
                                                              missing_valu...
                                    transformer=TargetEncoder(cols=['Neighbourhood '
                                                                    'Name',
                                                                    'FSA',
                                                                    'Episode '
                                                                    'Date'],
                                                              drop_invariant=False,
                                                              handle_missing='return_nan',
                                                              handle_unknown='value',
                                                              hierarchy=None,
                                                              min_samples_leaf=20,
                                                              return_df=True,
                                                              smoothing=10,
                                                              verbose=0))),
                ('clean_column_names',
                 TransformerWrapper(exclude=None, include=None,
                                    transformer=CleanColumnNames(match='[\\]\\[\\,\\{\\}\\"\\:]+')))],
         verbose=False), verbose=True, use_case=MLUsecase.CLASSIFICATION, kwargs={})
2023-09-17 20:49:13,555:INFO:Adding model into prep_pipe
2023-09-17 20:49:13,582:INFO:modelo_2.pkl saved in current working directory
2023-09-17 20:49:13,601:INFO:Pipeline(memory=Memory(location=None),
         steps=[('numerical_imputer',
                 TransformerWrapper(exclude=None,
                                    include=['Unnamed: 0',
                                             'Currently Hospitalized',
                                             'Currently in ICU',
                                             'Currently Intubated',
                                             'Ever Hospitalized', 'Ever in ICU',
                                             'Ever Intubated'],
                                    transformer=SimpleImputer(add_indicator=False,
                                                              copy=True,
                                                              fill_value=None,
                                                              keep_empty_features=False,
                                                              missing_values=nan,
                                                              stra...
                                            criterion='friedman_mse', init=None,
                                            learning_rate=0.1, loss='log_loss',
                                            max_depth=3, max_features=None,
                                            max_leaf_nodes=None,
                                            min_impurity_decrease=0.0,
                                            min_samples_leaf=1,
                                            min_samples_split=2,
                                            min_weight_fraction_leaf=0.0,
                                            n_estimators=100,
                                            n_iter_no_change=None,
                                            random_state=2858, subsample=1.0,
                                            tol=0.0001, validation_fraction=0.1,
                                            verbose=0, warm_start=False))],
         verbose=False)
2023-09-17 20:49:13,602:INFO:save_model() successfully completed......................................
2023-09-17 20:49:13,851:INFO:Initializing create_model()
2023-09-17 20:49:13,851:INFO:create_model(self=<pycaret.classification.oop.ClassificationExperiment object at 0x7f76ad0a8370>, estimator=GradientBoostingClassifier(ccp_alpha=0.0, criterion='friedman_mse', init=None,
                           learning_rate=0.1, loss='log_loss', max_depth=3,
                           max_features=None, max_leaf_nodes=None,
                           min_impurity_decrease=0.0, min_samples_leaf=1,
                           min_samples_split=2, min_weight_fraction_leaf=0.0,
                           n_estimators=100, n_iter_no_change=None,
                           random_state=2858, subsample=1.0, tol=0.0001,
                           validation_fraction=0.1, verbose=0,
                           warm_start=False), fold=None, round=4, cross_validation=True, predict=True, fit_kwargs=None, groups=None, refit=True, probability_threshold=None, experiment_custom_tags=None, verbose=True, system=True, add_to_model_list=True, metrics=None, display=None, model_only=True, return_train_score=False, kwargs={})
2023-09-17 20:49:13,851:INFO:Checking exceptions
2023-09-17 20:49:13,903:INFO:Importing libraries
2023-09-17 20:49:13,904:INFO:Copying training dataset
2023-09-17 20:49:13,925:INFO:Defining folds
2023-09-17 20:49:13,925:INFO:Declaring metric variables
2023-09-17 20:49:13,935:INFO:Importing untrained model
2023-09-17 20:49:13,935:INFO:Declaring custom model
2023-09-17 20:49:13,948:INFO:Gradient Boosting Classifier Imported successfully
2023-09-17 20:49:13,969:INFO:Starting cross validation
2023-09-17 20:49:13,973:INFO:Cross validating with StratifiedKFold(n_splits=10, random_state=None, shuffle=False), n_jobs=1
2023-09-17 20:49:30,765:INFO:Calculating mean and std
2023-09-17 20:49:30,768:INFO:Creating metrics dataframe
2023-09-17 20:49:30,779:INFO:Finalizing model
2023-09-17 20:49:33,027:INFO:Uploading results into container
2023-09-17 20:49:33,028:INFO:Uploading model into container now
2023-09-17 20:49:33,052:INFO:_master_model_container: 15
2023-09-17 20:49:33,053:INFO:_display_container: 3
2023-09-17 20:49:33,054:INFO:GradientBoostingClassifier(ccp_alpha=0.0, criterion='friedman_mse', init=None,
                           learning_rate=0.1, loss='log_loss', max_depth=3,
                           max_features=None, max_leaf_nodes=None,
                           min_impurity_decrease=0.0, min_samples_leaf=1,
                           min_samples_split=2, min_weight_fraction_leaf=0.0,
                           n_estimators=100, n_iter_no_change=None,
                           random_state=2858, subsample=1.0, tol=0.0001,
                           validation_fraction=0.1, verbose=0,
                           warm_start=False)
2023-09-17 20:49:33,054:INFO:create_model() successfully completed......................................
2023-09-17 20:49:33,287:INFO:Initializing predict_model()
2023-09-17 20:49:33,287:INFO:predict_model(self=<pycaret.classification.oop.ClassificationExperiment object at 0x7f76ad0a8370>, estimator=GradientBoostingClassifier(ccp_alpha=0.0, criterion='friedman_mse', init=None,
                           learning_rate=0.1, loss='log_loss', max_depth=3,
                           max_features=None, max_leaf_nodes=None,
                           min_impurity_decrease=0.0, min_samples_leaf=1,
                           min_samples_split=2, min_weight_fraction_leaf=0.0,
                           n_estimators=100, n_iter_no_change=None,
                           random_state=2858, subsample=1.0, tol=0.0001,
                           validation_fraction=0.1, verbose=0,
                           warm_start=False), probability_threshold=None, encoded_labels=False, raw_score=False, round=4, verbose=True, ml_usecase=None, preprocess=True, encode_labels=<function _SupervisedExperiment.predict_model.<locals>.encode_labels at 0x7f76a92a67a0>)
2023-09-17 20:49:33,287:INFO:Checking exceptions
2023-09-17 20:49:33,287:INFO:Preloading libraries
2023-09-17 20:49:33,292:INFO:Set up data.
2023-09-17 20:49:33,324:INFO:Set up index.
2023-09-17 20:50:27,994:INFO:Initializing load_model()
2023-09-17 20:50:27,994:INFO:load_model(model_name=modelo_2, platform=None, authentication=None, verbose=True)
